File: PeakFitting/xrdData/ware_pzt/PZT for XRD - 59 - Batch 2_15-70 deg_0.004 step_4 sec per step_2.csv
[Measurement conditions]
Sample identification,
Comment - 1,"Configuration=MPSS New Configuration, Owner=User-1, Creation date=10/27/2010 9:00:11 AM"
Comment - 2,"Goniometer=PW3050/60 (Theta/Theta); Minimum step size 2Theta:0.001; Minimum step size Omega:0.001"
Comment - 3,"Sample stage=Multi purpose sample stage; Minimum step size Phi:2.5"
Comment - 4,"Diffractometer system=XPERT-PRO"
Comment - 5,"Measurement program=C:\PANalytical\Data Collector\Programs\JIvy\15-70 deg_0.004 step_4 sec per step.xrdmp, Identifier={D694021A-0495-4B56-AF4C-96A93E3EEBAF}"
Anode material,Cu
K-Alpha1 wavelength,1.5405980
K-Alpha2 wavelength,1.5444260
Ratio K-Alpha2/K-Alpha1,0.500
Divergence slit,Fixed,0.19mm
Monochromator used,NO
Generator voltage, 45
Tube current, 40
File date and time,20/Oct/2020 15:11
Unit cell,
h k l, 0 0 0
Scan axis,Gonio
Scan range,15.000000001,69.996786209
Scan step size,0.0041778
No. of points, 13164
Scan type,CONTINUOUS
Phi,0.0
Time per step,3.810
[Scan points]
Angle,Intensity
15.002088910,20.0
15.039689265,10.0
15.077289620,14.0
15.114889976,11.0
15.152490331,9.0
15.190090686,13.0
15.227691041,11.0
15.265291396,5.0
15.302891752,9.0
15.340492107,5.0
15.378092462,9.0
15.415692817,13.0
15.453293172,8.0
15.490893528,10.0
15.528493883,7.0
15.566094238,10.0
15.603694593,10.0
15.641294948,5.0
15.678895304,11.0
15.716495659,14.0
15.754096014,9.0
15.791696369,5.0
15.829296724,3.0
15.866897080,4.0
15.904497435,11.0
15.942097790,7.0
15.979698145,8.0
16.017298500,9.0
16.054898856,8.0
16.092499211,3.0
16.130099566,9.0
16.167699921,5.0
16.205300276,7.0
16.242900632,14.0
16.280500987,11.0
16.318101342,2.0
16.355701697,13.0
16.393302052,5.0
16.430902408,10.0
16.468502763,14.0
16.506103118,11.0
16.543703473,8.0
16.581303828,10.0
16.618904184,7.0
16.656504539,8.0
16.694104894,9.0
16.731705249,13.0
16.769305604,5.0
16.806905960,9.0
16.844506315,8.0
16.882106670,3.0
16.919707025,13.0
16.957307380,4.0
16.994907736,7.0
17.032508091,8.0
17.070108446,7.0
17.107708801,7.0
17.145309156,10.0
17.182909512,8.0
17.220509867,10.0
17.258110222,9.0
17.295710577,8.0
17.333310932,8.0
17.370911288,7.0
17.408511643,5.0
17.446111998,4.0
17.483712353,5.0
17.521312708,7.0
17.558913064,4.0
17.596513419,4.0
17.634113774,8.0
17.671714129,13.0
17.709314484,4.0
17.746914840,8.0
17.784515195,4.0
17.822115550,8.0
17.859715905,8.0
17.897316260,3.0
17.934916616,7.0
17.972516971,9.0
18.010117326,7.0
18.047717681,8.0
18.085318036,4.0
18.122918392,7.0
18.160518747,8.0
18.198119102,15.0
18.235719457,9.0
18.273319812,7.0
18.310920168,8.0
18.348520523,9.0
18.386120878,11.0
18.423721233,8.0
18.461321588,8.0
18.498921944,2.0
18.536522299,2.0
18.574122654,5.0
18.611723009,4.0
18.649323364,7.0
18.686923720,7.0
18.724524075,11.0
18.762124430,5.0
18.799724785,2.0
18.837325140,10.0
18.874925496,7.0
18.912525851,8.0
18.950126206,3.0
18.987726561,7.0
19.025326917,2.0
19.062927272,11.0
19.100527627,8.0
19.138127982,15.0
19.175728337,8.0
19.213328693,3.0
19.250929048,4.0
19.288529403,7.0
19.326129758,5.0
19.363730113,9.0
19.401330469,5.0
19.438930824,5.0
19.476531179,8.0
19.514131534,5.0
19.551731889,4.0
19.589332245,14.0
19.626932600,9.0
19.664532955,9.0
19.702133310,5.0
19.739733665,7.0
19.777334021,9.0
19.814934376,7.0
19.852534731,5.0
19.890135086,7.0
19.927735441,8.0
19.965335797,2.0
20.002936152,4.0
20.040536507,9.0
20.078136862,5.0
20.115737217,7.0
20.153337573,4.0
20.190937928,2.0
20.228538283,8.0
20.266138638,3.0
20.303738993,3.0
20.341339349,2.0
20.378939704,3.0
20.416540059,11.0
20.454140414,7.0
20.491740769,11.0
20.529341125,4.0
20.566941480,10.0
20.604541835,7.0
20.642142190,4.0
20.679742545,5.0
20.717342901,7.0
20.754943256,2.0
20.792543611,10.0
20.830143966,8.0
20.867744321,7.0
20.905344677,7.0
20.942945032,7.0
20.980545387,3.0
21.018145742,4.0
21.055746097,13.0
21.093346453,4.0
21.130946808,7.0
21.168547163,14.0
21.206147518,11.0
21.243747873,9.0
21.281348229,21.0
21.318948584,26.0
21.356548939,29.0
21.394149294,37.0
21.431749649,29.0
21.469350005,24.0
21.506950360,23.0
21.544550715,33.0
21.582151070,29.0
21.619751425,46.0
21.657351781,58.0
21.694952136,56.0
21.732552491,52.0
21.770152846,47.0
21.807753201,23.0
21.845353557,33.0
21.882953912,15.0
21.920554267,31.0
21.958154622,30.0
21.995754977,36.0
22.033355333,46.0
22.070955688,45.0
22.108556043,27.0
22.146156398,23.0
22.183756753,20.0
22.221357109,16.0
22.258957464,16.0
22.296557819,8.0
22.334158174,8.0
22.371758529,3.0
22.409358885,11.0
22.446959240,3.0
22.484559595,8.0
22.522159950,13.0
22.559760305,7.0
22.597360661,7.0
22.634961016,5.0
22.672561371,5.0
22.710161726,4.0
22.747762081,5.0
22.785362437,3.0
22.822962792,1.0
22.860563147,7.0
22.898163502,5.0
22.935763857,5.0
22.973364213,9.0
23.010964568,4.0
23.048564923,2.0
23.086165278,3.0
23.123765633,3.0
23.161365989,5.0
23.198966344,0.0
23.236566699,5.0
23.274167054,1.0
23.311767409,8.0
23.349367765,5.0
23.386968120,4.0
23.424568475,4.0
23.462168830,5.0
23.499769185,2.0
23.537369541,3.0
23.574969896,3.0
23.612570251,5.0
23.650170606,5.0
23.687770961,2.0
23.725371317,7.0
23.762971672,4.0
23.800572027,3.0
23.838172382,1.0
23.875772737,9.0
23.913373093,4.0
23.950973448,3.0
23.988573803,4.0
24.026174158,3.0
24.063774513,2.0
24.101374869,3.0
24.138975224,7.0
24.176575579,3.0
24.214175934,9.0
24.251776289,5.0
24.289376645,5.0
24.326977000,4.0
24.364577355,8.0
24.402177710,4.0
24.439778065,5.0
24.477378421,5.0
24.514978776,10.0
24.552579131,3.0
24.590179486,5.0
24.627779841,8.0
24.665380197,3.0
24.702980552,5.0
24.740580907,4.0
24.778181262,8.0
24.815781617,7.0
24.853381973,3.0
24.890982328,1.0
24.928582683,10.0
24.966183038,4.0
25.003783393,4.0
25.041383749,1.0
25.078984104,8.0
25.116584459,2.0
25.154184814,3.0
25.191785169,4.0
25.229385525,2.0
25.266985880,4.0
25.304586235,0.0
25.342186590,2.0
25.379786945,1.0
25.417387301,3.0
25.454987656,2.0
25.492588011,3.0
25.530188366,4.0
25.567788721,4.0
25.605389077,4.0
25.642989432,8.0
25.680589787,9.0
25.718190142,1.0
25.755790497,1.0
25.793390853,7.0
25.830991208,8.0
25.868591563,7.0
25.906191918,4.0
25.943792273,3.0
25.981392629,5.0
26.018992984,5.0
26.056593339,2.0
26.094193694,3.0
26.131794049,2.0
26.169394405,5.0
26.206994760,5.0
26.244595115,7.0
26.282195470,3.0
26.319795825,4.0
26.357396181,2.0
26.394996536,7.0
26.432596891,7.0
26.470197246,7.0
26.507797601,4.0
26.545397957,4.0
26.582998312,2.0
26.620598667,3.0
26.658199022,2.0
26.695799377,3.0
26.733399733,7.0
26.771000088,7.0
26.808600443,2.0
26.846200798,3.0
26.883801153,2.0
26.921401509,2.0
26.959001864,11.0
26.996602219,8.0
27.034202574,4.0
27.071802930,1.0
27.109403285,3.0
27.147003640,4.0
27.184603995,4.0
27.222204350,2.0
27.259804706,4.0
27.297405061,5.0
27.335005416,4.0
27.372605771,1.0
27.410206126,5.0
27.447806482,9.0
27.485406837,5.0
27.523007192,3.0
27.560607547,7.0
27.598207902,2.0
27.635808258,8.0
27.673408613,3.0
27.711008968,7.0
27.748609323,4.0
27.786209678,1.0
27.823810034,1.0
27.861410389,3.0
27.899010744,4.0
27.936611099,4.0
27.974211454,2.0
28.011811810,2.0
28.049412165,1.0
28.087012520,2.0
28.124612875,2.0
28.162213230,5.0
28.199813586,1.0
28.237413941,4.0
28.275014296,1.0
28.312614651,5.0
28.350215006,5.0
28.387815362,13.0
28.425415717,7.0
28.463016072,3.0
28.500616427,13.0
28.538216782,14.0
28.575817138,14.0
28.613417493,20.0
28.651017848,17.0
28.688618203,16.0
28.726218558,31.0
28.763818914,23.0
28.801419269,18.0
28.839019624,20.0
28.876619979,16.0
28.914220334,18.0
28.951820690,13.0
28.989421045,8.0
29.027021400,7.0
29.064621755,13.0
29.102222110,7.0
29.139822466,7.0
29.177422821,1.0
29.215023176,10.0
29.252623531,9.0
29.290223886,8.0
29.327824242,7.0
29.365424597,3.0
29.403024952,4.0
29.440625307,3.0
29.478225662,0.0
29.515826018,5.0
29.553426373,4.0
29.591026728,2.0
29.628627083,2.0
29.666227438,3.0
29.703827794,5.0
29.741428149,5.0
29.779028504,4.0
29.816628859,7.0
29.854229214,5.0
29.891829570,10.0
29.929429925,7.0
29.967030280,5.0
30.004630635,9.0
30.042230990,3.0
30.079831346,8.0
30.117431701,10.0
30.155032056,4.0
30.192632411,8.0
30.230232766,3.0
30.267833122,14.0
30.305433477,4.0
30.343033832,5.0
30.380634187,11.0
30.418234542,8.0
30.455834898,15.0
30.493435253,16.0
30.531035608,14.0
30.568635963,13.0
30.606236318,22.0
30.643836674,30.0
30.681437029,50.0
30.719037384,72.0
30.756637739,105.0
30.794238094,197.0
30.831838450,249.0
30.869438805,306.0
30.907039160,324.0
30.944639515,351.0
30.982239870,345.0
31.019840226,270.0
31.057440581,209.0
31.095040936,158.0
31.132641291,105.0
31.170241646,75.0
31.207842002,78.0
31.245442357,68.0
31.283042712,69.0
31.320643067,85.0
31.358243422,87.0
31.395843778,68.0
31.433444133,69.0
31.471044488,75.0
31.508644843,40.0
31.546245198,40.0
31.583845554,31.0
31.621445909,29.0
31.659046264,13.0
31.696646619,13.0
31.734246974,14.0
31.771847330,11.0
31.809447685,10.0
31.847048040,15.0
31.884648395,11.0
31.922248750,17.0
31.959849106,9.0
31.997449461,11.0
32.035049816,18.0
32.072650171,7.0
32.110250526,3.0
32.147850882,10.0
32.185451237,2.0
32.223051592,8.0
32.260651947,8.0
32.298252302,13.0
32.335852658,8.0
32.373453013,2.0
32.411053368,5.0
32.448653723,4.0
32.486254078,3.0
32.523854434,3.0
32.561454789,3.0
32.599055144,5.0
32.636655499,8.0
32.674255854,1.0
32.711856210,2.0
32.749456565,4.0
32.787056920,9.0
32.824657275,2.0
32.862257630,4.0
32.899857986,2.0
32.937458341,1.0
32.975058696,2.0
33.012659051,5.0
33.050259406,0.0
33.087859762,1.0
33.125460117,1.0
33.163060472,2.0
33.200660827,5.0
33.238261182,3.0
33.275861538,2.0
33.313461893,0.0
33.351062248,4.0
33.388662603,4.0
33.426262958,5.0
33.463863314,7.0
33.501463669,3.0
33.539064024,1.0
33.576664379,3.0
33.614264734,4.0
33.651865090,1.0
33.689465445,2.0
33.727065800,3.0
33.764666155,1.0
33.802266510,1.0
33.839866866,1.0
33.877467221,3.0
33.915067576,3.0
33.952667931,9.0
33.990268286,4.0
34.027868642,3.0
34.065468997,2.0
34.103069352,3.0
34.140669707,2.0
34.178270062,1.0
34.215870418,1.0
34.253470773,2.0
34.291071128,4.0
34.328671483,2.0
34.366271838,5.0
34.403872194,2.0
34.441472549,3.0
34.479072904,1.0
34.516673259,4.0
34.554273614,2.0
34.591873970,2.0
34.629474325,0.0
34.667074680,3.0
34.704675035,2.0
34.742275390,1.0
34.779875746,5.0
34.817476101,0.0
34.855076456,2.0
34.892676811,1.0
34.930277166,0.0
34.967877522,1.0
35.005477877,2.0
35.043078232,2.0
35.080678587,4.0
35.118278943,2.0
35.155879298,9.0
35.193479653,5.0
35.231080008,2.0
35.268680363,1.0
35.306280719,2.0
35.343881074,3.0
35.381481429,5.0
35.419081784,5.0
35.456682139,3.0
35.494282495,4.0
35.531882850,2.0
35.569483205,3.0
35.607083560,4.0
35.644683915,2.0
35.682284271,3.0
35.719884626,1.0
35.757484981,4.0
35.795085336,5.0
35.832685691,3.0
35.870286047,3.0
35.907886402,2.0
35.945486757,2.0
35.983087112,4.0
36.020687467,9.0
36.058287823,8.0
36.095888178,13.0
36.133488533,5.0
36.171088888,5.0
36.208689243,4.0
36.246289599,2.0
36.283889954,2.0
36.321490309,2.0
36.359090664,2.0
36.396691019,5.0
36.434291375,3.0
36.471891730,1.0
36.509492085,1.0
36.547092440,4.0
36.584692795,4.0
36.622293151,3.0
36.659893506,7.0
36.697493861,1.0
36.735094216,5.0
36.772694571,4.0
36.810294927,4.0
36.847895282,2.0
36.885495637,2.0
36.923095992,2.0
36.960696347,3.0
36.998296703,3.0
37.035897058,1.0
37.073497413,2.0
37.111097768,8.0
37.148698123,2.0
37.186298479,4.0
37.223898834,1.0
37.261499189,2.0
37.299099544,0.0
37.336699899,5.0
37.374300255,5.0
37.411900610,5.0
37.449500965,3.0
37.487101320,3.0
37.524701675,2.0
37.562302031,3.0
37.599902386,2.0
37.637502741,7.0
37.675103096,5.0
37.712703451,9.0
37.750303807,5.0
37.787904162,11.0
37.825504517,9.0
37.863104872,17.0
37.900705227,17.0
37.938305583,23.0
37.975905938,16.0
38.013506293,16.0
38.051106648,26.0
38.088707003,34.0
38.126307359,27.0
38.163907714,35.0
38.201508069,37.0
38.239108424,59.0
38.276708779,59.0
38.314309135,52.0
38.351909490,59.0
38.389509845,47.0
38.427110200,41.0
38.464710555,20.0
38.502310911,21.0
38.539911266,16.0
38.577511621,10.0
38.615111976,11.0
38.652712331,5.0
38.690312687,2.0
38.727913042,7.0
38.765513397,7.0
38.803113752,2.0
38.840714107,5.0
38.878314463,4.0
38.915914818,2.0
38.953515173,2.0
38.991115528,4.0
39.028715883,1.0
39.066316239,5.0
39.103916594,5.0
39.141516949,2.0
39.179117304,5.0
39.216717659,3.0
39.254318015,2.0
39.291918370,1.0
39.329518725,4.0
39.367119080,4.0
39.404719435,2.0
39.442319791,5.0
39.479920146,1.0
39.517520501,2.0
39.555120856,3.0
39.592721211,3.0
39.630321567,2.0
39.667921922,1.0
39.705522277,2.0
39.743122632,4.0
39.780722987,3.0
39.818323343,4.0
39.855923698,4.0
39.893524053,0.0
39.931124408,5.0
39.968724763,4.0
40.006325119,4.0
40.043925474,2.0
40.081525829,0.0
40.119126184,1.0
40.156726539,2.0
40.194326895,3.0
40.231927250,2.0
40.269527605,1.0
40.307127960,7.0
40.344728315,5.0
40.382328671,2.0
40.419929026,3.0
40.457529381,2.0
40.495129736,3.0
40.532730091,3.0
40.570330447,3.0
40.607930802,3.0
40.645531157,1.0
40.683131512,1.0
40.720731867,3.0
40.758332223,3.0
40.795932578,8.0
40.833532933,5.0
40.871133288,9.0
40.908733643,1.0
40.946333999,3.0
40.983934354,3.0
41.021534709,3.0
41.059135064,3.0
41.096735419,3.0
41.134335775,4.0
41.171936130,3.0
41.209536485,2.0
41.247136840,3.0
41.284737195,4.0
41.322337551,2.0
41.359937906,3.0
41.397538261,5.0
41.435138616,0.0
41.472738971,7.0
41.510339327,1.0
41.547939682,3.0
41.585540037,4.0
41.623140392,2.0
41.660740747,1.0
41.698341103,1.0
41.735941458,3.0
41.773541813,2.0
41.811142168,8.0
41.848742523,3.0
41.886342879,2.0
41.923943234,5.0
41.961543589,5.0
41.999143944,3.0
42.036744299,2.0
42.074344655,5.0
42.111945010,1.0
42.149545365,1.0
42.187145720,3.0
42.224746075,5.0
42.262346431,5.0
42.299946786,1.0
42.337547141,4.0
42.375147496,5.0
42.412747851,3.0
42.450348207,4.0
42.487948562,3.0
42.525548917,2.0
42.563149272,8.0
42.600749627,2.0
42.638349983,5.0
42.675950338,5.0
42.713550693,2.0
42.751151048,1.0
42.788751403,1.0
42.826351759,1.0
42.863952114,5.0
42.901552469,2.0
42.939152824,3.0
42.976753180,3.0
43.014353535,1.0
43.051953890,2.0
43.089554245,5.0
43.127154600,3.0
43.164754956,3.0
43.202355311,2.0
43.239955666,3.0
43.277556021,4.0
43.315156376,1.0
43.352756732,1.0
43.390357087,7.0
43.427957442,8.0
43.465557797,11.0
43.503158152,11.0
43.540758508,24.0
43.578358863,21.0
43.615959218,20.0
43.653559573,14.0
43.691159928,14.0
43.728760284,22.0
43.766360639,16.0
43.803960994,17.0
43.841561349,16.0
43.879161704,11.0
43.916762060,11.0
43.954362415,14.0
43.991962770,11.0
44.029563125,17.0
44.067163480,20.0
44.104763836,33.0
44.142364191,29.0
44.179964546,35.0
44.217564901,41.0
44.255165256,46.0
44.292765612,42.0
44.330365967,41.0
44.367966322,41.0
44.405566677,35.0
44.443167032,29.0
44.480767388,30.0
44.518367743,20.0
44.555968098,21.0
44.593568453,21.0
44.631168808,13.0
44.668769164,22.0
44.706369519,9.0
44.743969874,17.0
44.781570229,29.0
44.819170584,17.0
44.856770940,14.0
44.894371295,21.0
44.931971650,34.0
44.969572005,27.0
45.007172360,39.0
45.044772716,20.0
45.082373071,35.0
45.119973426,33.0
45.157573781,31.0
45.195174136,16.0
45.232774492,15.0
45.270374847,15.0
45.307975202,13.0
45.345575557,14.0
45.383175912,18.0
45.420776268,9.0
45.458376623,7.0
45.495976978,10.0
45.533577333,3.0
45.571177688,11.0
45.608778044,7.0
45.646378399,10.0
45.683978754,7.0
45.721579109,2.0
45.759179464,8.0
45.796779820,9.0
45.834380175,4.0
45.871980530,5.0
45.909580885,3.0
45.947181240,7.0
45.984781596,5.0
46.022381951,7.0
46.059982306,1.0
46.097582661,5.0
46.135183016,2.0
46.172783372,5.0
46.210383727,4.0
46.247984082,2.0
46.285584437,8.0
46.323184792,1.0
46.360785148,2.0
46.398385503,2.0
46.435985858,5.0
46.473586213,5.0
46.511186568,2.0
46.548786924,3.0
46.586387279,1.0
46.623987634,1.0
46.661587989,1.0
46.699188344,5.0
46.736788700,2.0
46.774389055,2.0
46.811989410,4.0
46.849589765,5.0
46.887190120,2.0
46.924790476,3.0
46.962390831,2.0
46.999991186,4.0
47.037591541,5.0
47.075191896,1.0
47.112792252,4.0
47.150392607,7.0
47.187992962,3.0
47.225593317,2.0
47.263193672,4.0
47.300794028,5.0
47.338394383,4.0
47.375994738,4.0
47.413595093,2.0
47.451195448,3.0
47.488795804,1.0
47.526396159,1.0
47.563996514,3.0
47.601596869,9.0
47.639197224,3.0
47.676797580,3.0
47.714397935,4.0
47.751998290,4.0
47.789598645,8.0
47.827199000,4.0
47.864799356,2.0
47.902399711,1.0
47.940000066,2.0
47.977600421,4.0
48.015200776,7.0
48.052801132,5.0
48.090401487,5.0
48.128001842,3.0
48.165602197,1.0
48.203202552,4.0
48.240802908,2.0
48.278403263,8.0
48.316003618,1.0
48.353603973,3.0
48.391204328,1.0
48.428804684,1.0
48.466405039,3.0
48.504005394,3.0
48.541605749,2.0
48.579206104,1.0
48.616806460,4.0
48.654406815,7.0
48.692007170,7.0
48.729607525,5.0
48.767207880,3.0
48.804808236,7.0
48.842408591,13.0
48.880008946,5.0
48.917609301,9.0
48.955209656,5.0
48.992810012,7.0
49.030410367,9.0
49.068010722,7.0
49.105611077,8.0
49.143211432,4.0
49.180811788,7.0
49.218412143,9.0
49.256012498,7.0
49.293612853,11.0
49.331213208,21.0
49.368813564,18.0
49.406413919,17.0
49.444014274,21.0
49.481614629,17.0
49.519214984,24.0
49.556815340,23.0
49.594415695,17.0
49.632016050,17.0
49.669616405,22.0
49.707216760,29.0
49.744817116,27.0
49.782417471,16.0
49.820017826,17.0
49.857618181,13.0
49.895218536,15.0
49.932818892,22.0
49.970419247,13.0
50.008019602,14.0
50.045619957,20.0
50.083220312,14.0
50.120820668,9.0
50.158421023,10.0
50.196021378,14.0
50.233621733,10.0
50.271222088,4.0
50.308822444,15.0
50.346422799,18.0
50.384023154,11.0
50.421623509,15.0
50.459223864,16.0
50.496824220,13.0
50.534424575,5.0
50.572024930,7.0
50.609625285,13.0
50.647225640,7.0
50.684825996,5.0
50.722426351,10.0
50.760026706,8.0
50.797627061,1.0
50.835227416,2.0
50.872827772,10.0
50.910428127,10.0
50.948028482,3.0
50.985628837,9.0
51.023229193,5.0
51.060829548,3.0
51.098429903,7.0
51.136030258,9.0
51.173630613,4.0
51.211230969,4.0
51.248831324,2.0
51.286431679,3.0
51.324032034,0.0
51.361632389,1.0
51.399232745,1.0
51.436833100,4.0
51.474433455,4.0
51.512033810,5.0
51.549634165,3.0
51.587234521,2.0
51.624834876,5.0
51.662435231,3.0
51.700035586,8.0
51.737635941,5.0
51.775236297,7.0
51.812836652,2.0
51.850437007,2.0
51.888037362,2.0
51.925637717,4.0
51.963238073,0.0
52.000838428,5.0
52.038438783,5.0
52.076039138,0.0
52.113639493,0.0
52.151239849,3.0
52.188840204,4.0
52.226440559,3.0
52.264040914,4.0
52.301641269,3.0
52.339241625,5.0
52.376841980,2.0
52.414442335,3.0
52.452042690,0.0
52.489643045,0.0
52.527243401,5.0
52.564843756,4.0
52.602444111,3.0
52.640044466,4.0
52.677644821,5.0
52.715245177,4.0
52.752845532,2.0
52.790445887,8.0
52.828046242,3.0
52.865646597,5.0
52.903246953,4.0
52.940847308,4.0
52.978447663,5.0
53.016048018,4.0
53.053648373,2.0
53.091248729,8.0
53.128849084,2.0
53.166449439,5.0
53.204049794,3.0
53.241650149,0.0
53.279250505,4.0
53.316850860,4.0
53.354451215,2.0
53.392051570,8.0
53.429651925,1.0
53.467252281,5.0
53.504852636,2.0
53.542452991,2.0
53.580053346,4.0
53.617653701,2.0
53.655254057,2.0
53.692854412,7.0
53.730454767,3.0
53.768055122,3.0
53.805655477,3.0
53.843255833,8.0
53.880856188,1.0
53.918456543,7.0
53.956056898,4.0
53.993657253,3.0
54.031257609,7.0
54.068857964,7.0
54.106458319,4.0
54.144058674,1.0
54.181659029,5.0
54.219259385,7.0
54.256859740,7.0
54.294460095,3.0
54.332060450,7.0
54.369660805,11.0
54.407261161,9.0
54.444861516,10.0
54.482461871,11.0
54.520062226,15.0
54.557662581,18.0
54.595262937,23.0
54.632863292,29.0
54.670463647,33.0
54.708064002,40.0
54.745664357,66.0
54.783264713,40.0
54.820865068,72.0
54.858465423,75.0
54.896065778,81.0
54.933666133,59.0
54.971266489,80.0
55.008866844,61.0
55.046467199,49.0
55.084067554,65.0
55.121667909,62.0
55.159268265,56.0
55.196868620,59.0
55.234468975,56.0
55.272069330,53.0
55.309669685,46.0
55.347270041,36.0
55.384870396,35.0
55.422470751,47.0
55.460071106,39.0
55.497671461,34.0
55.535271817,43.0
55.572872172,39.0
55.610472527,43.0
55.648072882,45.0
55.685673237,50.0
55.723273593,34.0
55.760873948,39.0
55.798474303,31.0
55.836074658,27.0
55.873675013,28.0
55.911275369,18.0
55.948875724,13.0
55.986476079,8.0
56.024076434,13.0
56.061676789,13.0
56.099277145,13.0
56.136877500,11.0
56.174477855,10.0
56.212078210,7.0
56.249678565,4.0
56.287278921,5.0
56.324879276,11.0
56.362479631,7.0
56.400079986,7.0
56.437680341,8.0
56.475280697,2.0
56.512881052,7.0
56.550481407,10.0
56.588081762,8.0
56.625682117,4.0
56.663282473,5.0
56.700882828,5.0
56.738483183,3.0
56.776083538,4.0
56.813683893,4.0
56.851284249,4.0
56.888884604,4.0
56.926484959,4.0
56.964085314,1.0
57.001685669,2.0
57.039286025,11.0
57.076886380,14.0
57.114486735,3.0
57.152087090,3.0
57.189687445,4.0
57.227287801,7.0
57.264888156,2.0
57.302488511,4.0
57.340088866,5.0
57.377689221,7.0
57.415289577,8.0
57.452889932,2.0
57.490490287,7.0
57.528090642,3.0
57.565690997,3.0
57.603291353,4.0
57.640891708,5.0
57.678492063,0.0
57.716092418,3.0
57.753692773,2.0
57.791293129,1.0
57.828893484,2.0
57.866493839,5.0
57.904094194,3.0
57.941694549,3.0
57.979294905,2.0
58.016895260,2.0
58.054495615,7.0
58.092095970,5.0
58.129696325,3.0
58.167296681,9.0
58.204897036,3.0
58.242497391,7.0
58.280097746,4.0
58.317698101,4.0
58.355298457,8.0
58.392898812,5.0
58.430499167,4.0
58.468099522,1.0
58.505699877,3.0
58.543300233,5.0
58.580900588,3.0
58.618500943,5.0
58.656101298,3.0
58.693701653,4.0
58.731302009,4.0
58.768902364,4.0
58.806502719,3.0
58.844103074,2.0
58.881703429,2.0
58.919303785,8.0
58.956904140,1.0
58.994504495,2.0
59.032104850,2.0
59.069705206,4.0
59.107305561,1.0
59.144905916,5.0
59.182506271,3.0
59.220106626,5.0
59.257706982,5.0
59.295307337,1.0
59.332907692,5.0
59.370508047,3.0
59.408108402,3.0
59.445708758,7.0
59.483309113,3.0
59.520909468,3.0
59.558509823,8.0
59.596110178,3.0
59.633710534,8.0
59.671310889,3.0
59.708911244,0.0
59.746511599,2.0
59.784111954,5.0
59.821712310,2.0
59.859312665,2.0
59.896913020,1.0
59.934513375,2.0
59.972113730,5.0
60.009714086,7.0
60.047314441,4.0
60.084914796,1.0
60.122515151,2.0
60.160115506,4.0
60.197715862,4.0
60.235316217,5.0
60.272916572,2.0
60.310516927,4.0
60.348117282,2.0
60.385717638,2.0
60.423317993,4.0
60.460918348,3.0
60.498518703,3.0
60.536119058,2.0
60.573719414,4.0
60.611319769,5.0
60.648920124,5.0
60.686520479,3.0
60.724120834,9.0
60.761721190,1.0
60.799321545,1.0
60.836921900,7.0
60.874522255,0.0
60.912122610,0.0
60.949722966,3.0
60.987323321,5.0
61.024923676,4.0
61.062524031,4.0
61.100124386,5.0
61.137724742,5.0
61.175325097,1.0
61.212925452,9.0
61.250525807,2.0
61.288126162,5.0
61.325726518,3.0
61.363326873,3.0
61.400927228,3.0
61.438527583,3.0
61.476127938,2.0
61.513728294,5.0
61.551328649,4.0
61.588929004,2.0
61.626529359,2.0
61.664129714,2.0
61.701730070,3.0
61.739330425,2.0
61.776930780,7.0
61.814531135,1.0
61.852131490,3.0
61.889731846,4.0
61.927332201,1.0
61.964932556,4.0
62.002532911,3.0
62.040133266,4.0
62.077733622,4.0
62.115333977,2.0
62.152934332,3.0
62.190534687,7.0
62.228135042,3.0
62.265735398,2.0
62.303335753,2.0
62.340936108,8.0
62.378536463,7.0
62.416136818,8.0
62.453737174,5.0
62.491337529,2.0
62.528937884,5.0
62.566538239,5.0
62.604138594,7.0
62.641738950,7.0
62.679339305,3.0
62.716939660,8.0
62.754540015,4.0
62.792140370,0.0
62.829740726,4.0
62.867341081,4.0
62.904941436,2.0
62.942541791,1.0
62.980142146,4.0
63.017742502,3.0
63.055342857,3.0
63.092943212,2.0
63.130543567,7.0
63.168143922,0.0
63.205744278,0.0
63.243344633,4.0
63.280944988,2.0
63.318545343,4.0
63.356145698,2.0
63.393746054,3.0
63.431346409,7.0
63.468946764,4.0
63.506547119,4.0
63.544147474,3.0
63.581747830,8.0
63.619348185,3.0
63.656948540,4.0
63.694548895,3.0
63.732149250,4.0
63.769749606,3.0
63.807349961,3.0
63.844950316,5.0
63.882550671,4.0
63.920151026,7.0
63.957751382,5.0
63.995351737,5.0
64.032952092,7.0
64.070552447,8.0
64.108152802,16.0
64.145753158,11.0
64.183353513,14.0
64.220953868,10.0
64.258554223,22.0
64.296154578,22.0
64.333754934,15.0
64.371355289,17.0
64.408955644,21.0
64.446555999,31.0
64.484156354,33.0
64.521756710,30.0
64.559357065,33.0
64.596957420,45.0
64.634557775,35.0
64.672158130,21.0
64.709758486,28.0
64.747358841,28.0
64.784959196,16.0
64.822559551,27.0
64.860159906,17.0
64.897760262,17.0
64.935360617,15.0
64.972960972,13.0
65.010561327,18.0
65.048161682,10.0
65.085762038,10.0
65.123362393,9.0
65.160962748,8.0
65.198563103,10.0
65.236163458,13.0
65.273763814,8.0
65.311364169,14.0
65.348964524,9.0
65.386564879,8.0
65.424165234,7.0
65.461765590,9.0
65.499365945,7.0
65.536966300,8.0
65.574566655,3.0
65.612167010,9.0
65.649767366,8.0
65.687367721,9.0
65.724968076,8.0
65.762568431,8.0
65.800168786,8.0
65.837769142,7.0
65.875369497,7.0
65.912969852,11.0
65.950570207,5.0
65.988170562,9.0
66.025770918,5.0
66.063371273,3.0
66.100971628,5.0
66.138571983,5.0
66.176172338,4.0
66.213772694,5.0
66.251373049,3.0
66.288973404,1.0
66.326573759,2.0
66.364174114,5.0
66.401774470,3.0
66.439374825,2.0
66.476975180,8.0
66.514575535,2.0
66.552175890,3.0
66.589776246,2.0
66.627376601,3.0
66.664976956,4.0
66.702577311,8.0
66.740177666,3.0
66.777778022,8.0
66.815378377,2.0
66.852978732,1.0
66.890579087,5.0
66.928179443,1.0
66.965779798,4.0
67.003380153,2.0
67.040980508,5.0
67.078580863,3.0
67.116181219,2.0
67.153781574,2.0
67.191381929,7.0
67.228982284,1.0
67.266582639,5.0
67.304182995,3.0
67.341783350,1.0
67.379383705,11.0
67.416984060,2.0
67.454584415,1.0
67.492184771,2.0
67.529785126,5.0
67.567385481,3.0
67.604985836,7.0
67.642586191,4.0
67.680186547,5.0
67.717786902,5.0
67.755387257,4.0
67.792987612,7.0
67.830587967,3.0
67.868188323,5.0
67.905788678,3.0
67.943389033,5.0
67.980989388,4.0
68.018589743,8.0
68.056190099,3.0
68.093790454,2.0
68.131390809,8.0
68.168991164,2.0
68.206591519,4.0
68.244191875,2.0
68.281792230,5.0
68.319392585,5.0
68.356992940,5.0
68.394593295,4.0
68.432193651,7.0
68.469794006,5.0
68.507394361,4.0
68.544994716,10.0
68.582595071,7.0
68.620195427,8.0
68.657795782,8.0
68.695396137,15.0
68.732996492,11.0
68.770596847,11.0
68.808197203,5.0
68.845797558,9.0
68.883397913,9.0
68.920998268,10.0
68.958598623,11.0
68.996198979,15.0
69.033799334,15.0
69.071399689,11.0
69.109000044,15.0
69.146600399,13.0
69.184200755,11.0
69.221801110,16.0
69.259401465,15.0
69.297001820,15.0
69.334602175,7.0
69.372202531,11.0
69.409802886,9.0
69.447403241,9.0
69.485003596,10.0
69.522603951,9.0
69.560204307,5.0
69.597804662,9.0
69.635405017,9.0
69.673005372,1.0
69.710605727,4.0
69.748206083,4.0
69.785806438,5.0
69.823406793,7.0
69.861007148,2.0
69.898607503,5.0
69.936207859,7.0
69.973808214,4.0
69.994697300,5.0