File: PeakFitting/xrdData/ware_pzt/PZTReactiveSinteringBatch2_10-28-2020.csv
[Measurement conditions]
Sample identification,PZTReactiveSinteringBatch2
Comment - 1,"Configuration=MPSS New Configuration, Owner=User-1, Creation date=10/27/2010 9:00:11 AM"
Comment - 2,"Goniometer=PW3050/60 (Theta/Theta); Minimum step size 2Theta:0.001; Minimum step size Omega:0.001"
Comment - 3,"Sample stage=Multi purpose sample stage; Minimum step size Phi:2.5"
Comment - 4,"Diffractometer system=XPERT-PRO"
Comment - 5,"Measurement program=C:\XRD Data\Aidan Ravnik\GeneralQuickScan10-100deg.xrdmp, Identifier={421A12CB-BC59-4E45-81EC-8D2024CB8EA2}"
Anode material,Cu
K-Alpha1 wavelength,1.5405980
K-Alpha2 wavelength,1.5444260
Ratio K-Alpha2/K-Alpha1,0.500
Divergence slit,Fixed,0.19mm
Monochromator used,NO
Generator voltage, 45
Tube current, 40
File date and time,28/Oct/2020 12:19
Unit cell,
h k l, 0 0 0
Scan axis,Gonio
Scan range,9.999999996,110.000233564
Scan step size,0.0167113
No. of points, 5984
Scan type,CONTINUOUS
Phi,0.0
Time per step,1.905
[Scan points]
Angle,Intensity
10.008355630,10.0
10.075200706,2.0
10.142045782,2.0
10.208890858,6.0
10.275735934,4.0
10.342581010,6.0
10.409426085,8.0
10.476271161,4.0
10.543116237,5.0
10.609961313,5.0
10.676806389,6.0
10.743651465,8.0
10.810496541,8.0
10.877341617,12.0
10.944186693,5.0
11.011031769,12.0
11.077876845,4.0
11.144721921,9.0
11.211566996,9.0
11.278412072,12.0
11.345257148,6.0
11.412102224,5.0
11.478947300,1.0
11.545792376,6.0
11.612637452,6.0
11.679482528,1.0
11.746327604,2.0
11.813172680,6.0
11.880017756,5.0
11.946862832,4.0
12.013707907,8.0
12.080552983,2.0
12.147398059,5.0
12.214243135,5.0
12.281088211,13.0
12.347933287,0.0
12.414778363,5.0
12.481623439,2.0
12.548468515,6.0
12.615313591,1.0
12.682158667,4.0
12.749003743,4.0
12.815848818,2.0
12.882693894,5.0
12.949538970,5.0
13.016384046,2.0
13.083229122,8.0
13.150074198,2.0
13.216919274,0.0
13.283764350,1.0
13.350609426,6.0
13.417454502,2.0
13.484299578,8.0
13.551144653,2.0
13.617989729,5.0
13.684834805,4.0
13.751679881,1.0
13.818524957,1.0
13.885370033,1.0
13.952215109,8.0
14.019060185,4.0
14.085905261,8.0
14.152750337,8.0
14.219595413,5.0
14.286440489,2.0
14.353285564,5.0
14.420130640,4.0
14.486975716,6.0
14.553820792,5.0
14.620665868,4.0
14.687510944,4.0
14.754356020,4.0
14.821201096,5.0
14.888046172,4.0
14.954891248,6.0
15.021736324,2.0
15.088581400,2.0
15.155426475,4.0
15.222271551,2.0
15.289116627,6.0
15.355961703,4.0
15.422806779,2.0
15.489651855,5.0
15.556496931,4.0
15.623342007,5.0
15.690187083,4.0
15.757032159,1.0
15.823877235,6.0
15.890722311,4.0
15.957567386,4.0
16.024412462,4.0
16.091257538,4.0
16.158102614,9.0
16.224947690,10.0
16.291792766,1.0
16.358637842,8.0
16.425482918,1.0
16.492327994,1.0
16.559173070,4.0
16.626018146,1.0
16.692863222,4.0
16.759708297,6.0
16.826553373,1.0
16.893398449,5.0
16.960243525,2.0
17.027088601,2.0
17.093933677,5.0
17.160778753,5.0
17.227623829,0.0
17.294468905,1.0
17.361313981,1.0
17.428159057,1.0
17.495004132,1.0
17.561849208,1.0
17.628694284,5.0
17.695539360,1.0
17.762384436,4.0
17.829229512,1.0
17.896074588,1.0
17.962919664,2.0
18.029764740,4.0
18.096609816,5.0
18.163454892,4.0
18.230299968,0.0
18.297145043,4.0
18.363990119,1.0
18.430835195,4.0
18.497680271,4.0
18.564525347,2.0
18.631370423,0.0
18.698215499,1.0
18.765060575,6.0
18.831905651,5.0
18.898750727,1.0
18.965595803,6.0
19.032440879,0.0
19.099285954,2.0
19.166131030,2.0
19.232976106,2.0
19.299821182,6.0
19.366666258,6.0
19.433511334,5.0
19.500356410,2.0
19.567201486,1.0
19.634046562,2.0
19.700891638,4.0
19.767736714,0.0
19.834581790,4.0
19.901426865,1.0
19.968271941,1.0
20.035117017,5.0
20.101962093,1.0
20.168807169,2.0
20.235652245,5.0
20.302497321,2.0
20.369342397,4.0
20.436187473,0.0
20.503032549,5.0
20.569877625,1.0
20.636722700,2.0
20.703567776,5.0
20.770412852,5.0
20.837257928,0.0
20.904103004,2.0
20.970948080,4.0
21.037793156,6.0
21.104638232,6.0
21.171483308,1.0
21.238328384,5.0
21.305173460,6.0
21.372018536,13.0
21.438863611,20.0
21.505708687,21.0
21.572553763,21.0
21.639398839,14.0
21.706243915,14.0
21.773088991,6.0
21.839934067,12.0
21.906779143,12.0
21.973624219,13.0
22.040469295,18.0
22.107314371,22.0
22.174159447,32.0
22.241004522,9.0
22.307849598,9.0
22.374694674,4.0
22.441539750,4.0
22.508384826,5.0
22.575229902,1.0
22.642074978,0.0
22.708920054,0.0
22.775765130,5.0
22.842610206,0.0
22.909455282,0.0
22.976300358,5.0
23.043145433,5.0
23.109990509,4.0
23.176835585,1.0
23.243680661,6.0
23.310525737,4.0
23.377370813,1.0
23.444215889,2.0
23.511060965,0.0
23.577906041,2.0
23.644751117,1.0
23.711596193,2.0
23.778441269,1.0
23.845286344,1.0
23.912131420,0.0
23.978976496,5.0
24.045821572,2.0
24.112666648,2.0
24.179511724,2.0
24.246356800,2.0
24.313201876,5.0
24.380046952,0.0
24.446892028,4.0
24.513737104,2.0
24.580582179,2.0
24.647427255,0.0
24.714272331,5.0
24.781117407,0.0
24.847962483,2.0
24.914807559,5.0
24.981652635,0.0
25.048497711,2.0
25.115342787,2.0
25.182187863,1.0
25.249032939,4.0
25.315878015,1.0
25.382723090,2.0
25.449568166,2.0
25.516413242,2.0
25.583258318,1.0
25.650103394,1.0
25.716948470,2.0
25.783793546,2.0
25.850638622,2.0
25.917483698,4.0
25.984328774,2.0
26.051173850,5.0
26.118018926,2.0
26.184864001,0.0
26.251709077,5.0
26.318554153,2.0
26.385399229,1.0
26.452244305,2.0
26.519089381,0.0
26.585934457,5.0
26.652779533,4.0
26.719624609,1.0
26.786469685,0.0
26.853314761,1.0
26.920159837,0.0
26.987004912,1.0
27.053849988,1.0
27.120695064,0.0
27.187540140,0.0
27.254385216,1.0
27.321230292,1.0
27.388075368,1.0
27.454920444,0.0
27.521765520,1.0
27.588610596,2.0
27.655455672,2.0
27.722300747,2.0
27.789145823,5.0
27.855990899,2.0
27.922835975,4.0
27.989681051,4.0
28.056526127,4.0
28.123371203,2.0
28.190216279,4.0
28.257061355,4.0
28.323906431,4.0
28.390751507,1.0
28.457596583,1.0
28.524441658,2.0
28.591286734,2.0
28.658131810,4.0
28.724976886,1.0
28.791821962,4.0
28.858667038,2.0
28.925512114,2.0
28.992357190,1.0
29.059202266,2.0
29.126047342,2.0
29.192892418,0.0
29.259737494,1.0
29.326582569,2.0
29.393427645,0.0
29.460272721,2.0
29.527117797,1.0
29.593962873,1.0
29.660807949,5.0
29.727653025,1.0
29.794498101,1.0
29.861343177,1.0
29.928188253,5.0
29.995033329,9.0
30.061878405,0.0
30.128723480,10.0
30.195568556,4.0
30.262413632,2.0
30.329258708,1.0
30.396103784,1.0
30.462948860,5.0
30.529793936,6.0
30.596639012,8.0
30.663484088,14.0
30.730329164,36.0
30.797174240,48.0
30.864019316,60.0
30.930864391,108.0
30.997709467,139.0
31.064554543,133.0
31.131399619,101.0
31.198244695,68.0
31.265089771,48.0
31.331934847,70.0
31.398779923,58.0
31.465624999,50.0
31.532470075,65.0
31.599315151,40.0
31.666160226,25.0
31.733005302,8.0
31.799850378,6.0
31.866695454,4.0
31.933540530,6.0
32.000385606,5.0
32.067230682,1.0
32.134075758,2.0
32.200920834,2.0
32.267765910,1.0
32.334610986,4.0
32.401456062,0.0
32.468301137,4.0
32.535146213,4.0
32.601991289,1.0
32.668836365,5.0
32.735681441,2.0
32.802526517,5.0
32.869371593,0.0
32.936216669,1.0
33.003061745,0.0
33.069906821,4.0
33.136751897,4.0
33.203596973,1.0
33.270442048,2.0
33.337287124,4.0
33.404132200,0.0
33.470977276,0.0
33.537822352,0.0
33.604667428,2.0
33.671512504,1.0
33.738357580,1.0
33.805202656,2.0
33.872047732,0.0
33.938892808,0.0
34.005737884,0.0
34.072582959,0.0
34.139428035,0.0
34.206273111,1.0
34.273118187,1.0
34.339963263,0.0
34.406808339,1.0
34.473653415,1.0
34.540498491,1.0
34.607343567,1.0
34.674188643,1.0
34.741033719,2.0
34.807878794,2.0
34.874723870,1.0
34.941568946,0.0
35.008414022,1.0
35.075259098,1.0
35.142104174,0.0
35.208949250,4.0
35.275794326,1.0
35.342639402,1.0
35.409484478,0.0
35.476329554,4.0
35.543174630,0.0
35.610019705,0.0
35.676864781,1.0
35.743709857,1.0
35.810554933,1.0
35.877400009,1.0
35.944245085,4.0
36.011090161,1.0
36.077935237,0.0
36.144780313,5.0
36.211625389,1.0
36.278470465,1.0
36.345315541,1.0
36.412160616,1.0
36.479005692,0.0
36.545850768,1.0
36.612695844,1.0
36.679540920,0.0
36.746385996,2.0
36.813231072,6.0
36.880076148,0.0
36.946921224,0.0
37.013766300,4.0
37.080611376,1.0
37.147456452,1.0
37.214301527,0.0
37.281146603,1.0
37.347991679,4.0
37.414836755,1.0
37.481681831,0.0
37.548526907,0.0
37.615371983,2.0
37.682217059,4.0
37.749062135,0.0
37.815907211,1.0
37.882752287,0.0
37.949597363,1.0
38.016442438,5.0
38.083287514,4.0
38.150132590,10.0
38.216977666,12.0
38.283822742,26.0
38.350667818,32.0
38.417512894,41.0
38.484357970,32.0
38.551203046,22.0
38.618048122,6.0
38.684893198,12.0
38.751738273,6.0
38.818583349,6.0
38.885428425,2.0
38.952273501,5.0
39.019118577,2.0
39.085963653,2.0
39.152808729,2.0
39.219653805,0.0
39.286498881,0.0
39.353343957,1.0
39.420189033,0.0
39.487034109,0.0
39.553879184,1.0
39.620724260,1.0
39.687569336,4.0
39.754414412,1.0
39.821259488,1.0
39.888104564,1.0
39.954949640,1.0
40.021794716,2.0
40.088639792,0.0
40.155484868,1.0
40.222329944,0.0
40.289175020,2.0
40.356020095,1.0
40.422865171,0.0
40.489710247,1.0
40.556555323,2.0
40.623400399,1.0
40.690245475,0.0
40.757090551,2.0
40.823935627,0.0
40.890780703,2.0
40.957625779,1.0
41.024470855,2.0
41.091315931,4.0
41.158161006,2.0
41.225006082,2.0
41.291851158,1.0
41.358696234,1.0
41.425541310,1.0
41.492386386,0.0
41.559231462,0.0
41.626076538,1.0
41.692921614,5.0
41.759766690,2.0
41.826611766,1.0
41.893456841,1.0
41.960301917,0.0
42.027146993,4.0
42.093992069,6.0
42.160837145,5.0
42.227682221,1.0
42.294527297,2.0
42.361372373,1.0
42.428217449,1.0
42.495062525,0.0
42.561907601,4.0
42.628752677,1.0
42.695597752,1.0
42.762442828,1.0
42.829287904,6.0
42.896132980,1.0
42.962978056,2.0
43.029823132,1.0
43.096668208,1.0
43.163513284,1.0
43.230358360,6.0
43.297203436,0.0
43.364048512,4.0
43.430893588,0.0
43.497738663,10.0
43.564583739,10.0
43.631428815,9.0
43.698273891,12.0
43.765118967,17.0
43.831964043,16.0
43.898809119,9.0
43.965654195,13.0
44.032499271,4.0
44.099344347,2.0
44.166189423,14.0
44.233034499,2.0
44.299879574,4.0
44.366724650,2.0
44.433569726,8.0
44.500414802,8.0
44.567259878,13.0
44.634104954,9.0
44.700950030,16.0
44.767795106,9.0
44.834640182,12.0
44.901485258,17.0
44.968330334,16.0
45.035175410,40.0
45.102020485,42.0
45.168865561,18.0
45.235710637,20.0
45.302555713,18.0
45.369400789,13.0
45.436245865,12.0
45.503090941,2.0
45.569936017,0.0
45.636781093,2.0
45.703626169,4.0
45.770471245,2.0
45.837316320,2.0
45.904161396,1.0
45.971006472,1.0
46.037851548,1.0
46.104696624,2.0
46.171541700,1.0
46.238386776,1.0
46.305231852,2.0
46.372076928,1.0
46.438922004,0.0
46.505767080,1.0
46.572612156,1.0
46.639457231,5.0
46.706302307,0.0
46.773147383,4.0
46.839992459,1.0
46.906837535,2.0
46.973682611,2.0
47.040527687,4.0
47.107372763,0.0
47.174217839,2.0
47.241062915,0.0
47.307907991,4.0
47.374753067,0.0
47.441598142,1.0
47.508443218,4.0
47.575288294,2.0
47.642133370,0.0
47.708978446,1.0
47.775823522,0.0
47.842668598,1.0
47.909513674,0.0
47.976358750,0.0
48.043203826,1.0
48.110048902,0.0
48.176893978,2.0
48.243739053,0.0
48.310584129,0.0
48.377429205,1.0
48.444274281,0.0
48.511119357,4.0
48.577964433,0.0
48.644809509,1.0
48.711654585,1.0
48.778499661,1.0
48.845344737,0.0
48.912189813,1.0
48.979034888,2.0
49.045879964,0.0
49.112725040,2.0
49.179570116,4.0
49.246415192,2.0
49.313260268,9.0
49.380105344,6.0
49.446950420,12.0
49.513795496,10.0
49.580640572,14.0
49.647485648,10.0
49.714330724,8.0
49.781175799,14.0
49.848020875,10.0
49.914865951,14.0
49.981711027,6.0
50.048556103,8.0
50.115401179,5.0
50.182246255,9.0
50.249091331,2.0
50.315936407,6.0
50.382781483,10.0
50.449626559,12.0
50.516471635,13.0
50.583316710,9.0
50.650161786,4.0
50.717006862,14.0
50.783851938,14.0
50.850697014,5.0
50.917542090,4.0
50.984387166,6.0
51.051232242,5.0
51.118077318,5.0
51.184922394,1.0
51.251767470,1.0
51.318612546,4.0
51.385457621,0.0
51.452302697,2.0
51.519147773,2.0
51.585992849,1.0
51.652837925,4.0
51.719683001,1.0
51.786528077,2.0
51.853373153,4.0
51.920218229,1.0
51.987063305,1.0
52.053908381,1.0
52.120753457,2.0
52.187598532,1.0
52.254443608,0.0
52.321288684,2.0
52.388133760,2.0
52.454978836,1.0
52.521823912,4.0
52.588668988,1.0
52.655514064,0.0
52.722359140,1.0
52.789204216,2.0
52.856049292,1.0
52.922894367,0.0
52.989739443,1.0
53.056584519,1.0
53.123429595,2.0
53.190274671,0.0
53.257119747,2.0
53.323964823,2.0
53.390809899,1.0
53.457654975,5.0
53.524500051,2.0
53.591345127,4.0
53.658190203,1.0
53.725035278,4.0
53.791880354,1.0
53.858725430,4.0
53.925570506,0.0
53.992415582,4.0
54.059260658,1.0
54.126105734,1.0
54.192950810,5.0
54.259795886,1.0
54.326640962,4.0
54.393486038,2.0
54.460331114,5.0
54.527176189,8.0
54.594021265,6.0
54.660866341,9.0
54.727711417,22.0
54.794556493,24.0
54.861401569,24.0
54.928246645,33.0
54.995091721,20.0
55.061936797,8.0
55.128781873,29.0
55.195626949,10.0
55.262472025,26.0
55.329317100,18.0
55.396162176,14.0
55.463007252,20.0
55.529852328,46.0
55.596697404,34.0
55.663542480,37.0
55.730387556,48.0
55.797232632,45.0
55.864077708,26.0
55.930922784,18.0
55.997767860,17.0
56.064612935,10.0
56.131458011,10.0
56.198303087,6.0
56.265148163,2.0
56.331993239,5.0
56.398838315,2.0
56.465683391,2.0
56.532528467,2.0
56.599373543,2.0
56.666218619,1.0
56.733063695,1.0
56.799908771,2.0
56.866753846,0.0
56.933598922,2.0
57.000443998,0.0
57.067289074,0.0
57.134134150,4.0
57.200979226,2.0
57.267824302,1.0
57.334669378,0.0
57.401514454,0.0
57.468359530,1.0
57.535204606,0.0
57.602049682,1.0
57.668894757,1.0
57.735739833,1.0
57.802584909,1.0
57.869429985,2.0
57.936275061,1.0
58.003120137,1.0
58.069965213,1.0
58.136810289,0.0
58.203655365,1.0
58.270500441,1.0
58.337345517,0.0
58.404190593,1.0
58.471035668,6.0
58.537880744,0.0
58.604725820,1.0
58.671570896,2.0
58.738415972,4.0
58.805261048,1.0
58.872106124,1.0
58.938951200,1.0
59.005796276,1.0
59.072641352,0.0
59.139486428,2.0
59.206331504,1.0
59.273176579,0.0
59.340021655,4.0
59.406866731,2.0
59.473711807,4.0
59.540556883,2.0
59.607401959,4.0
59.674247035,2.0
59.741092111,5.0
59.807937187,5.0
59.874782263,0.0
59.941627339,2.0
60.008472414,0.0
60.075317490,2.0
60.142162566,1.0
60.209007642,4.0
60.275852718,4.0
60.342697794,0.0
60.409542870,2.0
60.476387946,2.0
60.543233022,0.0
60.610078098,1.0
60.676923174,2.0
60.743768250,2.0
60.810613325,2.0
60.877458401,2.0
60.944303477,1.0
61.011148553,2.0
61.077993629,1.0
61.144838705,4.0
61.211683781,0.0
61.278528857,4.0
61.345373933,1.0
61.412219009,1.0
61.479064085,0.0
61.545909161,2.0
61.612754236,1.0
61.679599312,5.0
61.746444388,4.0
61.813289464,0.0
61.880134540,1.0
61.946979616,1.0
62.013824692,5.0
62.080669768,2.0
62.147514844,0.0
62.214359920,0.0
62.281204996,1.0
62.348050072,2.0
62.414895147,1.0
62.481740223,1.0
62.548585299,1.0
62.615430375,5.0
62.682275451,6.0
62.749120527,1.0
62.815965603,0.0
62.882810679,4.0
62.949655755,8.0
63.016500831,0.0
63.083345907,0.0
63.150190982,2.0
63.217036058,1.0
63.283881134,4.0
63.350726210,0.0
63.417571286,1.0
63.484416362,0.0
63.551261438,2.0
63.618106514,0.0
63.684951590,4.0
63.751796666,1.0
63.818641742,1.0
63.885486818,5.0
63.952331893,2.0
64.019176969,0.0
64.086022045,5.0
64.152867121,0.0
64.219712197,4.0
64.286557273,6.0
64.353402349,8.0
64.420247425,18.0
64.487092501,12.0
64.553937577,17.0
64.620782653,17.0
64.687627729,17.0
64.754472804,8.0
64.821317880,14.0
64.888162956,10.0
64.955008032,9.0
65.021853108,8.0
65.088698184,12.0
65.155543260,6.0
65.222388336,10.0
65.289233412,8.0
65.356078488,6.0
65.422923564,2.0
65.489768640,10.0
65.556613715,18.0
65.623458791,10.0
65.690303867,9.0
65.757148943,12.0
65.823994019,8.0
65.890839095,10.0
65.957684171,5.0
66.024529247,4.0
66.091374323,2.0
66.158219399,4.0
66.225064475,0.0
66.291909551,2.0
66.358754626,1.0
66.425599702,5.0
66.492444778,2.0
66.559289854,0.0
66.626134930,0.0
66.692980006,1.0
66.759825082,1.0
66.826670158,1.0
66.893515234,1.0
66.960360310,2.0
67.027205386,1.0
67.094050461,1.0
67.160895537,1.0
67.227740613,1.0
67.294585689,4.0
67.361430765,2.0
67.428275841,0.0
67.495120917,2.0
67.561965993,1.0
67.628811069,1.0
67.695656145,1.0
67.762501221,4.0
67.829346297,4.0
67.896191372,1.0
67.963036448,1.0
68.029881524,0.0
68.096726600,4.0
68.163571676,0.0
68.230416752,4.0
68.297261828,2.0
68.364106904,0.0
68.430951980,1.0
68.497797056,2.0
68.564642132,2.0
68.631487208,4.0
68.698332283,6.0
68.765177359,2.0
68.832022435,4.0
68.898867511,5.0
68.965712587,5.0
69.032557663,4.0
69.099402739,10.0
69.166247815,4.0
69.233092891,10.0
69.299937967,9.0
69.366783043,5.0
69.433628119,6.0
69.500473194,5.0
69.567318270,6.0
69.634163346,1.0
69.701008422,2.0
69.767853498,2.0
69.834698574,2.0
69.901543650,2.0
69.968388726,8.0
70.035233802,6.0
70.102078878,2.0
70.168923954,4.0
70.235769029,5.0
70.302614105,6.0
70.369459181,2.0
70.436304257,2.0
70.503149333,2.0
70.569994409,2.0
70.636839485,0.0
70.703684561,2.0
70.770529637,5.0
70.837374713,0.0
70.904219789,2.0
70.971064865,2.0
71.037909940,1.0
71.104755016,4.0
71.171600092,2.0
71.238445168,4.0
71.305290244,0.0
71.372135320,1.0
71.438980396,4.0
71.505825472,5.0
71.572670548,2.0
71.639515624,2.0
71.706360700,0.0
71.773205776,2.0
71.840050851,1.0
71.906895927,1.0
71.973741003,1.0
72.040586079,5.0
72.107431155,2.0
72.174276231,2.0
72.241121307,9.0
72.307966383,16.0
72.374811459,16.0
72.441656535,12.0
72.508501611,10.0
72.575346687,6.0
72.642191762,6.0
72.709036838,4.0
72.775881914,4.0
72.842726990,1.0
72.909572066,5.0
72.976417142,2.0
73.043262218,1.0
73.110107294,1.0
73.176952370,0.0
73.243797446,2.0
73.310642522,6.0
73.377487598,5.0
73.444332673,5.0
73.511177749,6.0
73.578022825,4.0
73.644867901,4.0
73.711712977,1.0
73.778558053,1.0
73.845403129,1.0
73.912248205,6.0
73.979093281,2.0
74.045938357,2.0
74.112783433,8.0
74.179628508,14.0
74.246473584,13.0
74.313318660,6.0
74.380163736,10.0
74.447008812,20.0
74.513853888,8.0
74.580698964,10.0
74.647544040,14.0
74.714389116,9.0
74.781234192,13.0
74.848079268,8.0
74.914924344,8.0
74.981769419,2.0
75.048614495,5.0
75.115459571,4.0
75.182304647,2.0
75.249149723,5.0
75.315994799,1.0
75.382839875,0.0
75.449684951,2.0
75.516530027,4.0
75.583375103,2.0
75.650220179,1.0
75.717065255,1.0
75.783910330,2.0
75.850755406,1.0
75.917600482,2.0
75.984445558,4.0
76.051290634,2.0
76.118135710,2.0
76.184980786,0.0
76.251825862,2.0
76.318670938,2.0
76.385516014,4.0
76.452361090,2.0
76.519206166,5.0
76.586051241,1.0
76.652896317,6.0
76.719741393,1.0
76.786586469,5.0
76.853431545,0.0
76.920276621,4.0
76.987121697,2.0
77.053966773,0.0
77.120811849,2.0
77.187656925,4.0
77.254502001,1.0
77.321347076,0.0
77.388192152,2.0
77.455037228,1.0
77.521882304,0.0
77.588727380,2.0
77.655572456,1.0
77.722417532,4.0
77.789262608,0.0
77.856107684,1.0
77.922952760,0.0
77.989797836,1.0
78.056642912,0.0
78.123487987,4.0
78.190333063,1.0
78.257178139,6.0
78.324023215,1.0
78.390868291,2.0
78.457713367,4.0
78.524558443,5.0
78.591403519,4.0
78.658248595,4.0
78.725093671,8.0
78.791938747,2.0
78.858783823,5.0
78.925628898,1.0
78.992473974,4.0
79.059319050,2.0
79.126164126,1.0
79.193009202,1.0
79.259854278,2.0
79.326699354,1.0
79.393544430,4.0
79.460389506,1.0
79.527234582,2.0
79.594079658,6.0
79.660924734,4.0
79.727769809,2.0
79.794614885,0.0
79.861459961,0.0
79.928305037,2.0
79.995150113,1.0
80.061995189,1.0
80.128840265,1.0
80.195685341,1.0
80.262530417,1.0
80.329375493,4.0
80.396220569,1.0
80.463065645,4.0
80.529910720,1.0
80.596755796,2.0
80.663600872,2.0
80.730445948,1.0
80.797291024,2.0
80.864136100,2.0
80.930981176,1.0
80.997826252,1.0
81.064671328,1.0
81.131516404,2.0
81.198361480,4.0
81.265206555,2.0
81.332051631,2.0
81.398896707,4.0
81.465741783,2.0
81.532586859,5.0
81.599431935,6.0
81.666277011,2.0
81.733122087,5.0
81.799967163,1.0
81.866812239,5.0
81.933657315,2.0
82.000502391,1.0
82.067347466,9.0
82.134192542,5.0
82.201037618,4.0
82.267882694,5.0
82.334727770,10.0
82.401572846,10.0
82.468417922,16.0
82.535262998,4.0
82.602108074,1.0
82.668953150,4.0
82.735798226,4.0
82.802643302,1.0
82.869488377,4.0
82.936333453,5.0
83.003178529,0.0
83.070023605,6.0
83.136868681,1.0
83.203713757,5.0
83.270558833,2.0
83.337403909,1.0
83.404248985,1.0
83.471094061,4.0
83.537939137,2.0
83.604784213,0.0
83.671629288,1.0
83.738474364,1.0
83.805319440,2.0
83.872164516,1.0
83.939009592,2.0
84.005854668,0.0
84.072699744,4.0
84.139544820,2.0
84.206389896,2.0
84.273234972,5.0
84.340080048,1.0
84.406925123,1.0
84.473770199,2.0
84.540615275,0.0
84.607460351,1.0
84.674305427,4.0
84.741150503,2.0
84.807995579,1.0
84.874840655,4.0
84.941685731,5.0
85.008530807,1.0
85.075375883,1.0
85.142220959,4.0
85.209066034,8.0
85.275911110,6.0
85.342756186,6.0
85.409601262,6.0
85.476446338,5.0
85.543291414,6.0
85.610136490,0.0
85.676981566,5.0
85.743826642,0.0
85.810671718,5.0
85.877516794,1.0
85.944361870,2.0
86.011206945,1.0
86.078052021,1.0
86.144897097,4.0
86.211742173,5.0
86.278587249,6.0
86.345432325,6.0
86.412277401,4.0
86.479122477,4.0
86.545967553,0.0
86.612812629,1.0
86.679657705,4.0
86.746502781,4.0
86.813347856,4.0
86.880192932,4.0
86.947038008,4.0
87.013883084,6.0
87.080728160,0.0
87.147573236,0.0
87.214418312,4.0
87.281263388,0.0
87.348108464,4.0
87.414953540,4.0
87.481798616,2.0
87.548643692,4.0
87.615488767,5.0
87.682333843,2.0
87.749178919,0.0
87.816023995,2.0
87.882869071,0.0
87.949714147,2.0
88.016559223,2.0
88.083404299,1.0
88.150249375,1.0
88.217094451,0.0
88.283939527,1.0
88.350784602,2.0
88.417629678,4.0
88.484474754,5.0
88.551319830,4.0
88.618164906,1.0
88.685009982,2.0
88.751855058,2.0
88.818700134,9.0
88.885545210,5.0
88.952390286,4.0
89.019235362,12.0
89.086080438,1.0
89.152925513,4.0
89.219770589,8.0
89.286615665,12.0
89.353460741,16.0
89.420305817,10.0
89.487150893,10.0
89.553995969,10.0
89.620841045,6.0
89.687686121,14.0
89.754531197,6.0
89.821376273,10.0
89.888221349,5.0
89.955066424,6.0
90.021911500,1.0
90.088756576,4.0
90.155601652,5.0
90.222446728,4.0
90.289291804,9.0
90.356136880,4.0
90.422981956,12.0
90.489827032,13.0
90.556672108,6.0
90.623517184,5.0
90.690362260,17.0
90.757207335,5.0
90.824052411,10.0
90.890897487,16.0
90.957742563,10.0
91.024587639,8.0
91.091432715,5.0
91.158277791,8.0
91.225122867,13.0
91.291967943,5.0
91.358813019,14.0
91.425658095,9.0
91.492503170,8.0
91.559348246,5.0
91.626193322,14.0
91.693038398,13.0
91.759883474,5.0
91.826728550,9.0
91.893573626,4.0
91.960418702,1.0
92.027263778,4.0
92.094108854,6.0
92.160953930,0.0
92.227799006,4.0
92.294644081,4.0
92.361489157,1.0
92.428334233,1.0
92.495179309,4.0
92.562024385,1.0
92.628869461,1.0
92.695714537,1.0
92.762559613,0.0
92.829404689,4.0
92.896249765,0.0
92.963094841,1.0
93.029939917,4.0
93.096784992,0.0
93.163630068,1.0
93.230475144,1.0
93.297320220,4.0
93.364165296,4.0
93.431010372,4.0
93.497855448,1.0
93.564700524,1.0
93.631545600,2.0
93.698390676,2.0
93.765235752,1.0
93.832080828,9.0
93.898925903,4.0
93.965770979,5.0
94.032616055,0.0
94.099461131,0.0
94.166306207,2.0
94.233151283,1.0
94.299996359,1.0
94.366841435,0.0
94.433686511,2.0
94.500531587,1.0
94.567376663,1.0
94.634221739,1.0
94.701066814,1.0
94.767911890,1.0
94.834756966,2.0
94.901602042,4.0
94.968447118,1.0
95.035292194,4.0
95.102137270,0.0
95.168982346,1.0
95.235827422,4.0
95.302672498,4.0
95.369517574,1.0
95.436362649,2.0
95.503207725,0.0
95.570052801,0.0
95.636897877,0.0
95.703742953,1.0
95.770588029,4.0
95.837433105,1.0
95.904278181,0.0
95.971123257,5.0
96.037968333,1.0
96.104813409,1.0
96.171658485,0.0
96.238503560,0.0
96.305348636,4.0
96.372193712,4.0
96.439038788,1.0
96.505883864,1.0
96.572728940,1.0
96.639574016,2.0
96.706419092,1.0
96.773264168,4.0
96.840109244,1.0
96.906954320,0.0
96.973799396,1.0
97.040644471,0.0
97.107489547,4.0
97.174334623,1.0
97.241179699,2.0
97.308024775,4.0
97.374869851,8.0
97.441714927,8.0
97.508560003,2.0
97.575405079,2.0
97.642250155,1.0
97.709095231,5.0
97.775940307,1.0
97.842785382,1.0
97.909630458,2.0
97.976475534,0.0
98.043320610,2.0
98.110165686,1.0
98.177010762,5.0
98.243855838,4.0
98.310700914,2.0
98.377545990,2.0
98.444391066,0.0
98.511236142,1.0
98.578081217,6.0
98.644926293,1.0
98.711771369,2.0
98.778616445,4.0
98.845461521,4.0
98.912306597,2.0
98.979151673,4.0
99.045996749,1.0
99.112841825,4.0
99.179686901,2.0
99.246531977,4.0
99.313377053,0.0
99.380222128,2.0
99.447067204,0.0
99.513912280,5.0
99.580757356,2.0
99.647602432,4.0
99.714447508,4.0
99.781292584,5.0
99.848137660,0.0
99.914982736,2.0
99.981827812,0.0
100.048672888,4.0
100.115517964,5.0
100.182363039,4.0
100.249208115,2.0
100.316053191,2.0
100.382898267,5.0
100.449743343,6.0
100.516588419,8.0
100.583433495,4.0
100.650278571,8.0
100.717123647,5.0
100.783968723,2.0
100.850813799,5.0
100.917658875,5.0
100.984503950,2.0
101.051349026,2.0
101.118194102,2.0
101.185039178,1.0
101.251884254,0.0
101.318729330,4.0
101.385574406,2.0
101.452419482,1.0
101.519264558,5.0
101.586109634,2.0
101.652954710,1.0
101.719799786,5.0
101.786644861,4.0
101.853489937,4.0
101.920335013,6.0
101.987180089,1.0
102.054025165,8.0
102.120870241,5.0
102.187715317,5.0
102.254560393,4.0
102.321405469,4.0
102.388250545,2.0
102.455095621,0.0
102.521940696,6.0
102.588785772,4.0
102.655630848,9.0
102.722475924,2.0
102.789321000,2.0
102.856166076,6.0
102.923011152,5.0
102.989856228,1.0
103.056701304,8.0
103.123546380,4.0
103.190391456,2.0
103.257236532,5.0
103.324081607,6.0
103.390926683,5.0
103.457771759,0.0
103.524616835,1.0
103.591461911,8.0
103.658306987,8.0
103.725152063,0.0
103.791997139,4.0
103.858842215,5.0
103.925687291,4.0
103.992532367,6.0
104.059377443,2.0
104.126222518,4.0
104.193067594,2.0
104.259912670,4.0
104.326757746,1.0
104.393602822,5.0
104.460447898,9.0
104.527292974,8.0
104.594138050,5.0
104.660983126,2.0
104.727828202,8.0
104.794673278,8.0
104.861518354,5.0
104.928363429,5.0
104.995208505,4.0
105.062053581,6.0
105.128898657,5.0
105.195743733,4.0
105.262588809,8.0
105.329433885,4.0
105.396278961,5.0
105.463124037,2.0
105.529969113,5.0
105.596814189,1.0
105.663659264,2.0
105.730504340,2.0
105.797349416,1.0
105.864194492,5.0
105.931039568,2.0
105.997884644,2.0
106.064729720,6.0
106.131574796,12.0
106.198419872,5.0
106.265264948,6.0
106.332110024,5.0
106.398955100,8.0
106.465800175,5.0
106.532645251,10.0
106.599490327,1.0
106.666335403,6.0
106.733180479,9.0
106.800025555,4.0
106.866870631,5.0
106.933715707,2.0
107.000560783,4.0
107.067405859,4.0
107.134250935,5.0
107.201096011,6.0
107.267941086,4.0
107.334786162,6.0
107.401631238,4.0
107.468476314,6.0
107.535321390,6.0
107.602166466,9.0
107.669011542,4.0
107.735856618,6.0
107.802701694,5.0
107.869546770,5.0
107.936391846,2.0
108.003236922,2.0
108.070081997,6.0
108.136927073,1.0
108.203772149,2.0
108.270617225,5.0
108.337462301,10.0
108.404307377,10.0
108.471152453,5.0
108.537997529,2.0
108.604842605,9.0
108.671687681,8.0
108.738532757,2.0
108.805377833,6.0
108.872222908,2.0
108.939067984,10.0
109.005913060,8.0
109.072758136,8.0
109.139603212,5.0
109.206448288,1.0
109.273293364,5.0
109.340138440,2.0
109.406983516,5.0
109.473828592,4.0
109.540673668,4.0
109.607518743,4.0
109.674363819,4.0
109.741208895,0.0
109.808053971,4.0
109.874899047,4.0
109.941744123,2.0
109.991877930,1.0