File: PeakFitting/xrdData/ware_pzt/Reactively sintered PZT for XRD - Batch 1_15-70 deg_0.004 step_4 sec per step_1.csv
[Measurement conditions]
Sample identification,
Comment - 1,"Configuration=MPSS New Configuration, Owner=User-1, Creation date=10/27/2010 9:00:11 AM"
Comment - 2,"Goniometer=PW3050/60 (Theta/Theta); Minimum step size 2Theta:0.001; Minimum step size Omega:0.001"
Comment - 3,"Sample stage=Multi purpose sample stage; Minimum step size Phi:2.5"
Comment - 4,"Diffractometer system=XPERT-PRO"
Comment - 5,"Measurement program=C:\PANalytical\Data Collector\Programs\JIvy\15-70 deg_0.004 step_4 sec per step.xrdmp, Identifier={D694021A-0495-4B56-AF4C-96A93E3EEBAF}"
Anode material,Cu
K-Alpha1 wavelength,1.5405980
K-Alpha2 wavelength,1.5444260
Ratio K-Alpha2/K-Alpha1,0.500
Divergence slit,Fixed,0.19mm
Monochromator used,NO
Generator voltage, 45
Tube current, 40
File date and time,20/Oct/2020 15:23
Unit cell,
h k l, 0 0 0
Scan axis,Gonio
Scan range,15.000000001,69.996786209
Scan step size,0.0041778
No. of points, 13164
Scan type,CONTINUOUS
Phi,0.0
Time per step,3.810
[Scan points]
Angle,Intensity
15.002088910,15.0
15.039689265,3.0
15.077289620,3.0
15.114889976,3.0
15.152490331,9.0
15.190090686,7.0
15.227691041,9.0
15.265291396,9.0
15.302891752,10.0
15.340492107,10.0
15.378092462,7.0
15.415692817,5.0
15.453293172,8.0
15.490893528,14.0
15.528493883,14.0
15.566094238,7.0
15.603694593,8.0
15.641294948,9.0
15.678895304,10.0
15.716495659,8.0
15.754096014,5.0
15.791696369,10.0
15.829296724,11.0
15.866897080,3.0
15.904497435,10.0
15.942097790,10.0
15.979698145,9.0
16.017298500,8.0
16.054898856,13.0
16.092499211,5.0
16.130099566,7.0
16.167699921,7.0
16.205300276,7.0
16.242900632,13.0
16.280500987,5.0
16.318101342,7.0
16.355701697,8.0
16.393302052,9.0
16.430902408,7.0
16.468502763,10.0
16.506103118,13.0
16.543703473,11.0
16.581303828,10.0
16.618904184,4.0
16.656504539,4.0
16.694104894,4.0
16.731705249,4.0
16.769305604,4.0
16.806905960,3.0
16.844506315,5.0
16.882106670,7.0
16.919707025,8.0
16.957307380,10.0
16.994907736,4.0
17.032508091,9.0
17.070108446,5.0
17.107708801,8.0
17.145309156,5.0
17.182909512,5.0
17.220509867,3.0
17.258110222,2.0
17.295710577,7.0
17.333310932,7.0
17.370911288,7.0
17.408511643,4.0
17.446111998,10.0
17.483712353,11.0
17.521312708,8.0
17.558913064,13.0
17.596513419,4.0
17.634113774,5.0
17.671714129,8.0
17.709314484,11.0
17.746914840,2.0
17.784515195,8.0
17.822115550,9.0
17.859715905,5.0
17.897316260,10.0
17.934916616,4.0
17.972516971,11.0
18.010117326,8.0
18.047717681,8.0
18.085318036,10.0
18.122918392,4.0
18.160518747,5.0
18.198119102,14.0
18.235719457,5.0
18.273319812,7.0
18.310920168,9.0
18.348520523,7.0
18.386120878,4.0
18.423721233,4.0
18.461321588,8.0
18.498921944,4.0
18.536522299,11.0
18.574122654,7.0
18.611723009,11.0
18.649323364,4.0
18.686923720,11.0
18.724524075,3.0
18.762124430,2.0
18.799724785,3.0
18.837325140,4.0
18.874925496,7.0
18.912525851,7.0
18.950126206,7.0
18.987726561,4.0
19.025326917,2.0
19.062927272,8.0
19.100527627,5.0
19.138127982,5.0
19.175728337,7.0
19.213328693,8.0
19.250929048,2.0
19.288529403,5.0
19.326129758,7.0
19.363730113,3.0
19.401330469,17.0
19.438930824,8.0
19.476531179,10.0
19.514131534,4.0
19.551731889,8.0
19.589332245,14.0
19.626932600,7.0
19.664532955,8.0
19.702133310,7.0
19.739733665,8.0
19.777334021,4.0
19.814934376,5.0
19.852534731,11.0
19.890135086,3.0
19.927735441,7.0
19.965335797,4.0
20.002936152,8.0
20.040536507,5.0
20.078136862,2.0
20.115737217,8.0
20.153337573,10.0
20.190937928,1.0
20.228538283,14.0
20.266138638,7.0
20.303738993,1.0
20.341339349,9.0
20.378939704,8.0
20.416540059,4.0
20.454140414,8.0
20.491740769,7.0
20.529341125,9.0
20.566941480,8.0
20.604541835,5.0
20.642142190,2.0
20.679742545,1.0
20.717342901,4.0
20.754943256,8.0
20.792543611,5.0
20.830143966,3.0
20.867744321,13.0
20.905344677,5.0
20.942945032,4.0
20.980545387,10.0
21.018145742,9.0
21.055746097,8.0
21.093346453,9.0
21.130946808,3.0
21.168547163,1.0
21.206147518,8.0
21.243747873,9.0
21.281348229,10.0
21.318948584,21.0
21.356548939,14.0
21.394149294,39.0
21.431749649,81.0
21.469350005,126.0
21.506950360,126.0
21.544550715,114.0
21.582151070,62.0
21.619751425,36.0
21.657351781,17.0
21.694952136,28.0
21.732552491,21.0
21.770152846,9.0
21.807753201,18.0
21.845353557,10.0
21.882953912,14.0
21.920554267,24.0
21.958154622,17.0
21.995754977,48.0
22.033355333,72.0
22.070955688,93.0
22.108556043,95.0
22.146156398,113.0
22.183756753,107.0
22.221357109,101.0
22.258957464,66.0
22.296557819,74.0
22.334158174,42.0
22.371758529,37.0
22.409358885,21.0
22.446959240,13.0
22.484559595,17.0
22.522159950,7.0
22.559760305,3.0
22.597360661,5.0
22.634961016,4.0
22.672561371,4.0
22.710161726,5.0
22.747762081,8.0
22.785362437,7.0
22.822962792,5.0
22.860563147,4.0
22.898163502,4.0
22.935763857,3.0
22.973364213,2.0
23.010964568,5.0
23.048564923,8.0
23.086165278,4.0
23.123765633,7.0
23.161365989,9.0
23.198966344,3.0
23.236566699,7.0
23.274167054,7.0
23.311767409,1.0
23.349367765,3.0
23.386968120,8.0
23.424568475,7.0
23.462168830,4.0
23.499769185,2.0
23.537369541,15.0
23.574969896,5.0
23.612570251,7.0
23.650170606,4.0
23.687770961,4.0
23.725371317,5.0
23.762971672,3.0
23.800572027,3.0
23.838172382,7.0
23.875772737,2.0
23.913373093,11.0
23.950973448,8.0
23.988573803,11.0
24.026174158,9.0
24.063774513,10.0
24.101374869,26.0
24.138975224,9.0
24.176575579,22.0
24.214175934,11.0
24.251776289,4.0
24.289376645,7.0
24.326977000,11.0
24.364577355,10.0
24.402177710,2.0
24.439778065,8.0
24.477378421,15.0
24.514978776,17.0
24.552579131,10.0
24.590179486,15.0
24.627779841,9.0
24.665380197,7.0
24.702980552,3.0
24.740580907,7.0
24.778181262,7.0
24.815781617,3.0
24.853381973,4.0
24.890982328,8.0
24.928582683,4.0
24.966183038,4.0
25.003783393,3.0
25.041383749,2.0
25.078984104,8.0
25.116584459,5.0
25.154184814,11.0
25.191785169,2.0
25.229385525,7.0
25.266985880,3.0
25.304586235,7.0
25.342186590,4.0
25.379786945,3.0
25.417387301,10.0
25.454987656,5.0
25.492588011,10.0
25.530188366,5.0
25.567788721,7.0
25.605389077,9.0
25.642989432,8.0
25.680589787,8.0
25.718190142,13.0
25.755790497,5.0
25.793390853,4.0
25.830991208,4.0
25.868591563,9.0
25.906191918,1.0
25.943792273,3.0
25.981392629,3.0
26.018992984,1.0
26.056593339,8.0
26.094193694,5.0
26.131794049,4.0
26.169394405,3.0
26.206994760,5.0
26.244595115,10.0
26.282195470,7.0
26.319795825,1.0
26.357396181,3.0
26.394996536,5.0
26.432596891,8.0
26.470197246,7.0
26.507797601,5.0
26.545397957,4.0
26.582998312,3.0
26.620598667,3.0
26.658199022,3.0
26.695799377,4.0
26.733399733,5.0
26.771000088,10.0
26.808600443,4.0
26.846200798,4.0
26.883801153,3.0
26.921401509,2.0
26.959001864,3.0
26.996602219,9.0
27.034202574,2.0
27.071802930,9.0
27.109403285,5.0
27.147003640,4.0
27.184603995,3.0
27.222204350,4.0
27.259804706,2.0
27.297405061,5.0
27.335005416,8.0
27.372605771,3.0
27.410206126,5.0
27.447806482,9.0
27.485406837,3.0
27.523007192,8.0
27.560607547,5.0
27.598207902,9.0
27.635808258,10.0
27.673408613,5.0
27.711008968,4.0
27.748609323,3.0
27.786209678,10.0
27.823810034,7.0
27.861410389,8.0
27.899010744,4.0
27.936611099,13.0
27.974211454,3.0
28.011811810,2.0
28.049412165,5.0
28.087012520,11.0
28.124612875,15.0
28.162213230,16.0
28.199813586,37.0
28.237413941,75.0
28.275014296,81.0
28.312614651,52.0
28.350215006,28.0
28.387815362,22.0
28.425415717,5.0
28.463016072,9.0
28.500616427,8.0
28.538216782,13.0
28.575817138,7.0
28.613417493,2.0
28.651017848,5.0
28.688618203,4.0
28.726218558,3.0
28.763818914,3.0
28.801419269,3.0
28.839019624,7.0
28.876619979,8.0
28.914220334,7.0
28.951820690,7.0
28.989421045,3.0
29.027021400,8.0
29.064621755,3.0
29.102222110,4.0
29.139822466,3.0
29.177422821,3.0
29.215023176,4.0
29.252623531,4.0
29.290223886,8.0
29.327824242,5.0
29.365424597,10.0
29.403024952,9.0
29.440625307,0.0
29.478225662,3.0
29.515826018,8.0
29.553426373,5.0
29.591026728,5.0
29.628627083,9.0
29.666227438,4.0
29.703827794,2.0
29.741428149,7.0
29.779028504,2.0
29.816628859,4.0
29.854229214,7.0
29.891829570,9.0
29.929429925,5.0
29.967030280,7.0
30.004630635,10.0
30.042230990,10.0
30.079831346,15.0
30.117431701,10.0
30.155032056,8.0
30.192632411,3.0
30.230232766,7.0
30.267833122,5.0
30.305433477,8.0
30.343033832,8.0
30.380634187,10.0
30.418234542,10.0
30.455834898,8.0
30.493435253,14.0
30.531035608,20.0
30.568635963,14.0
30.606236318,7.0
30.643836674,18.0
30.681437029,23.0
30.719037384,18.0
30.756637739,27.0
30.794238094,54.0
30.831838450,74.0
30.869438805,99.0
30.907039160,209.0
30.944639515,340.0
30.982239870,517.0
31.019840226,651.0
31.057440581,650.0
31.095040936,522.0
31.132641291,466.0
31.170241646,369.0
31.207842002,229.0
31.245442357,176.0
31.283042712,127.0
31.320643067,155.0
31.358243422,175.0
31.395843778,180.0
31.433444133,217.0
31.471044488,208.0
31.508644843,245.0
31.546245198,232.0
31.583845554,206.0
31.621445909,158.0
31.659046264,130.0
31.696646619,114.0
31.734246974,71.0
31.771847330,53.0
31.809447685,61.0
31.847048040,42.0
31.884648395,33.0
31.922248750,28.0
31.959849106,16.0
31.997449461,18.0
32.035049816,13.0
32.072650171,15.0
32.110250526,9.0
32.147850882,7.0
32.185451237,10.0
32.223051592,8.0
32.260651947,4.0
32.298252302,9.0
32.335852658,3.0
32.373453013,9.0
32.411053368,10.0
32.448653723,4.0
32.486254078,2.0
32.523854434,7.0
32.561454789,4.0
32.599055144,3.0
32.636655499,5.0
32.674255854,2.0
32.711856210,3.0
32.749456565,5.0
32.787056920,8.0
32.824657275,7.0
32.862257630,5.0
32.899857986,3.0
32.937458341,5.0
32.975058696,5.0
33.012659051,3.0
33.050259406,3.0
33.087859762,3.0
33.125460117,5.0
33.163060472,7.0
33.200660827,4.0
33.238261182,8.0
33.275861538,4.0
33.313461893,4.0
33.351062248,8.0
33.388662603,2.0
33.426262958,5.0
33.463863314,7.0
33.501463669,3.0
33.539064024,1.0
33.576664379,8.0
33.614264734,1.0
33.651865090,5.0
33.689465445,2.0
33.727065800,5.0
33.764666155,4.0
33.802266510,2.0
33.839866866,2.0
33.877467221,8.0
33.915067576,1.0
33.952667931,3.0
33.990268286,2.0
34.027868642,4.0
34.065468997,5.0
34.103069352,11.0
34.140669707,7.0
34.178270062,13.0
34.215870418,18.0
34.253470773,11.0
34.291071128,13.0
34.328671483,10.0
34.366271838,7.0
34.403872194,9.0
34.441472549,5.0
34.479072904,13.0
34.516673259,11.0
34.554273614,5.0
34.591873970,8.0
34.629474325,15.0
34.667074680,4.0
34.704675035,4.0
34.742275390,2.0
34.779875746,2.0
34.817476101,3.0
34.855076456,2.0
34.892676811,2.0
34.930277166,2.0
34.967877522,10.0
35.005477877,4.0
35.043078232,4.0
35.080678587,5.0
35.118278943,4.0
35.155879298,4.0
35.193479653,7.0
35.231080008,10.0
35.268680363,5.0
35.306280719,11.0
35.343881074,8.0
35.381481429,17.0
35.419081784,11.0
35.456682139,10.0
35.494282495,8.0
35.531882850,3.0
35.569483205,4.0
35.607083560,2.0
35.644683915,2.0
35.682284271,5.0
35.719884626,5.0
35.757484981,7.0
35.795085336,1.0
35.832685691,4.0
35.870286047,8.0
35.907886402,5.0
35.945486757,8.0
35.983087112,9.0
36.020687467,5.0
36.058287823,1.0
36.095888178,2.0
36.133488533,3.0
36.171088888,2.0
36.208689243,3.0
36.246289599,8.0
36.283889954,1.0
36.321490309,3.0
36.359090664,5.0
36.396691019,8.0
36.434291375,0.0
36.471891730,5.0
36.509492085,7.0
36.547092440,7.0
36.584692795,0.0
36.622293151,4.0
36.659893506,4.0
36.697493861,7.0
36.735094216,0.0
36.772694571,4.0
36.810294927,2.0
36.847895282,4.0
36.885495637,7.0
36.923095992,3.0
36.960696347,1.0
36.998296703,3.0
37.035897058,3.0
37.073497413,5.0
37.111097768,2.0
37.148698123,7.0
37.186298479,4.0
37.223898834,9.0
37.261499189,2.0
37.299099544,7.0
37.336699899,7.0
37.374300255,5.0
37.411900610,2.0
37.449500965,4.0
37.487101320,5.0
37.524701675,4.0
37.562302031,1.0
37.599902386,5.0
37.637502741,1.0
37.675103096,3.0
37.712703451,2.0
37.750303807,7.0
37.787904162,3.0
37.825504517,1.0
37.863104872,3.0
37.900705227,8.0
37.938305583,4.0
37.975905938,7.0
38.013506293,5.0
38.051106648,2.0
38.088707003,4.0
38.126307359,15.0
38.163907714,11.0
38.201508069,18.0
38.239108424,26.0
38.276708779,59.0
38.314309135,65.0
38.351909490,99.0
38.389509845,139.0
38.427110200,137.0
38.464710555,135.0
38.502310911,129.0
38.539911266,116.0
38.577511621,72.0
38.615111976,50.0
38.652712331,65.0
38.690312687,42.0
38.727913042,31.0
38.765513397,28.0
38.803113752,21.0
38.840714107,13.0
38.878314463,14.0
38.915914818,10.0
38.953515173,4.0
38.991115528,11.0
39.028715883,5.0
39.066316239,4.0
39.103916594,3.0
39.141516949,5.0
39.179117304,8.0
39.216717659,4.0
39.254318015,4.0
39.291918370,1.0
39.329518725,5.0
39.367119080,5.0
39.404719435,7.0
39.442319791,4.0
39.479920146,4.0
39.517520501,7.0
39.555120856,1.0
39.592721211,4.0
39.630321567,9.0
39.667921922,1.0
39.705522277,1.0
39.743122632,1.0
39.780722987,1.0
39.818323343,4.0
39.855923698,7.0
39.893524053,7.0
39.931124408,9.0
39.968724763,1.0
40.006325119,1.0
40.043925474,3.0
40.081525829,8.0
40.119126184,2.0
40.156726539,4.0
40.194326895,2.0
40.231927250,3.0
40.269527605,4.0
40.307127960,7.0
40.344728315,3.0
40.382328671,3.0
40.419929026,9.0
40.457529381,7.0
40.495129736,8.0
40.532730091,3.0
40.570330447,5.0
40.607930802,5.0
40.645531157,7.0
40.683131512,4.0
40.720731867,5.0
40.758332223,5.0
40.795932578,11.0
40.833532933,5.0
40.871133288,9.0
40.908733643,9.0
40.946333999,8.0
40.983934354,5.0
41.021534709,4.0
41.059135064,9.0
41.096735419,7.0
41.134335775,3.0
41.171936130,5.0
41.209536485,4.0
41.247136840,3.0
41.284737195,9.0
41.322337551,7.0
41.359937906,4.0
41.397538261,3.0
41.435138616,3.0
41.472738971,5.0
41.510339327,3.0
41.547939682,8.0
41.585540037,2.0
41.623140392,4.0
41.660740747,4.0
41.698341103,3.0
41.735941458,3.0
41.773541813,4.0
41.811142168,9.0
41.848742523,3.0
41.886342879,1.0
41.923943234,5.0
41.961543589,4.0
41.999143944,1.0
42.036744299,3.0
42.074344655,0.0
42.111945010,10.0
42.149545365,5.0
42.187145720,5.0
42.224746075,5.0
42.262346431,2.0
42.299946786,7.0
42.337547141,5.0
42.375147496,5.0
42.412747851,3.0
42.450348207,5.0
42.487948562,3.0
42.525548917,3.0
42.563149272,3.0
42.600749627,2.0
42.638349983,1.0
42.675950338,7.0
42.713550693,1.0
42.751151048,3.0
42.788751403,2.0
42.826351759,4.0
42.863952114,4.0
42.901552469,4.0
42.939152824,5.0
42.976753180,7.0
43.014353535,3.0
43.051953890,7.0
43.089554245,3.0
43.127154600,7.0
43.164754956,5.0
43.202355311,2.0
43.239955666,7.0
43.277556021,3.0
43.315156376,8.0
43.352756732,7.0
43.390357087,5.0
43.427957442,3.0
43.465557797,8.0
43.503158152,3.0
43.540758508,13.0
43.578358863,20.0
43.615959218,29.0
43.653559573,45.0
43.691159928,69.0
43.728760284,72.0
43.766360639,79.0
43.803960994,60.0
43.841561349,59.0
43.879161704,35.0
43.916762060,37.0
43.954362415,14.0
43.991962770,14.0
44.029563125,17.0
44.067163480,8.0
44.104763836,14.0
44.142364191,9.0
44.179964546,14.0
44.217564901,15.0
44.255165256,11.0
44.292765612,7.0
44.330365967,8.0
44.367966322,2.0
44.405566677,11.0
44.443167032,9.0
44.480767388,11.0
44.518367743,9.0
44.555968098,9.0
44.593568453,5.0
44.631168808,9.0
44.668769164,18.0
44.706369519,14.0
44.743969874,4.0
44.781570229,14.0
44.819170584,20.0
44.856770940,29.0
44.894371295,37.0
44.931971650,59.0
44.969572005,81.0
45.007172360,78.0
45.044772716,79.0
45.082373071,80.0
45.119973426,72.0
45.157573781,73.0
45.195174136,74.0
45.232774492,71.0
45.270374847,52.0
45.307975202,58.0
45.345575557,47.0
45.383175912,56.0
45.420776268,60.0
45.458376623,45.0
45.495976978,22.0
45.533577333,30.0
45.571177688,27.0
45.608778044,26.0
45.646378399,26.0
45.683978754,14.0
45.721579109,21.0
45.759179464,16.0
45.796779820,16.0
45.834380175,13.0
45.871980530,4.0
45.909580885,1.0
45.947181240,2.0
45.984781596,4.0
46.022381951,7.0
46.059982306,3.0
46.097582661,3.0
46.135183016,5.0
46.172783372,3.0
46.210383727,3.0
46.247984082,7.0
46.285584437,1.0
46.323184792,1.0
46.360785148,7.0
46.398385503,11.0
46.435985858,7.0
46.473586213,5.0
46.511186568,3.0
46.548786924,7.0
46.586387279,1.0
46.623987634,2.0
46.661587989,1.0
46.699188344,5.0
46.736788700,5.0
46.774389055,1.0
46.811989410,4.0
46.849589765,4.0
46.887190120,5.0
46.924790476,5.0
46.962390831,8.0
46.999991186,5.0
47.037591541,5.0
47.075191896,4.0
47.112792252,3.0
47.150392607,5.0
47.187992962,2.0
47.225593317,3.0
47.263193672,4.0
47.300794028,3.0
47.338394383,5.0
47.375994738,3.0
47.413595093,4.0
47.451195448,3.0
47.488795804,4.0
47.526396159,3.0
47.563996514,5.0
47.601596869,2.0
47.639197224,1.0
47.676797580,4.0
47.714397935,4.0
47.751998290,7.0
47.789598645,1.0
47.827199000,1.0
47.864799356,3.0
47.902399711,5.0
47.940000066,5.0
47.977600421,4.0
48.015200776,3.0
48.052801132,7.0
48.090401487,3.0
48.128001842,4.0
48.165602197,1.0
48.203202552,7.0
48.240802908,4.0
48.278403263,5.0
48.316003618,2.0
48.353603973,5.0
48.391204328,0.0
48.428804684,5.0
48.466405039,7.0
48.504005394,7.0
48.541605749,2.0
48.579206104,10.0
48.616806460,9.0
48.654406815,3.0
48.692007170,4.0
48.729607525,4.0
48.767207880,3.0
48.804808236,4.0
48.842408591,4.0
48.880008946,5.0
48.917609301,7.0
48.955209656,10.0
48.992810012,4.0
49.030410367,10.0
49.068010722,8.0
49.105611077,9.0
49.143211432,5.0
49.180811788,2.0
49.218412143,11.0
49.256012498,11.0
49.293612853,18.0
49.331213208,24.0
49.368813564,18.0
49.406413919,31.0
49.444014274,42.0
49.481614629,60.0
49.519214984,60.0
49.556815340,53.0
49.594415695,61.0
49.632016050,37.0
49.669616405,35.0
49.707216760,20.0
49.744817116,14.0
49.782417471,21.0
49.820017826,10.0
49.857618181,14.0
49.895218536,15.0
49.932818892,7.0
49.970419247,10.0
50.008019602,23.0
50.045619957,9.0
50.083220312,16.0
50.120820668,15.0
50.158421023,14.0
50.196021378,31.0
50.233621733,31.0
50.271222088,37.0
50.308822444,31.0
50.346422799,29.0
50.384023154,22.0
50.421623509,28.0
50.459223864,26.0
50.496824220,29.0
50.534424575,35.0
50.572024930,28.0
50.609625285,39.0
50.647225640,37.0
50.684825996,40.0
50.722426351,29.0
50.760026706,28.0
50.797627061,28.0
50.835227416,18.0
50.872827772,18.0
50.910428127,24.0
50.948028482,16.0
50.985628837,11.0
51.023229193,13.0
51.060829548,17.0
51.098429903,8.0
51.136030258,8.0
51.173630613,13.0
51.211230969,10.0
51.248831324,10.0
51.286431679,11.0
51.324032034,21.0
51.361632389,7.0
51.399232745,8.0
51.436833100,4.0
51.474433455,5.0
51.512033810,3.0
51.549634165,5.0
51.587234521,7.0
51.624834876,7.0
51.662435231,2.0
51.700035586,8.0
51.737635941,10.0
51.775236297,4.0
51.812836652,1.0
51.850437007,7.0
51.888037362,5.0
51.925637717,5.0
51.963238073,3.0
52.000838428,3.0
52.038438783,5.0
52.076039138,3.0
52.113639493,2.0
52.151239849,1.0
52.188840204,7.0
52.226440559,5.0
52.264040914,9.0
52.301641269,7.0
52.339241625,8.0
52.376841980,5.0
52.414442335,7.0
52.452042690,5.0
52.489643045,3.0
52.527243401,4.0
52.564843756,2.0
52.602444111,7.0
52.640044466,2.0
52.677644821,4.0
52.715245177,8.0
52.752845532,3.0
52.790445887,5.0
52.828046242,3.0
52.865646597,10.0
52.903246953,4.0
52.940847308,5.0
52.978447663,7.0
53.016048018,2.0
53.053648373,2.0
53.091248729,9.0
53.128849084,9.0
53.166449439,5.0
53.204049794,4.0
53.241650149,2.0
53.279250505,3.0
53.316850860,4.0
53.354451215,7.0
53.392051570,5.0
53.429651925,5.0
53.467252281,2.0
53.504852636,4.0
53.542452991,4.0
53.580053346,9.0
53.617653701,7.0
53.655254057,7.0
53.692854412,2.0
53.730454767,4.0
53.768055122,4.0
53.805655477,2.0
53.843255833,20.0
53.880856188,10.0
53.918456543,5.0
53.956056898,2.0
53.993657253,7.0
54.031257609,9.0
54.068857964,8.0
54.106458319,10.0
54.144058674,14.0
54.181659029,18.0
54.219259385,10.0
54.256859740,5.0
54.294460095,14.0
54.332060450,10.0
54.369660805,8.0
54.407261161,10.0
54.444861516,18.0
54.482461871,9.0
54.520062226,11.0
54.557662581,8.0
54.595262937,16.0
54.632863292,18.0
54.670463647,11.0
54.708064002,46.0
54.745664357,53.0
54.783264713,86.0
54.820865068,86.0
54.858465423,97.0
54.896065778,78.0
54.933666133,87.0
54.971266489,79.0
55.008866844,61.0
55.046467199,66.0
55.084067554,47.0
55.121667909,53.0
55.159268265,45.0
55.196868620,34.0
55.234468975,27.0
55.272069330,23.0
55.309669685,28.0
55.347270041,36.0
55.384870396,26.0
55.422470751,30.0
55.460071106,47.0
55.497671461,58.0
55.535271817,65.0
55.572872172,93.0
55.610472527,92.0
55.648072882,98.0
55.685673237,90.0
55.723273593,117.0
55.760873948,110.0
55.798474303,127.0
55.836074658,97.0
55.873675013,97.0
55.911275369,103.0
55.948875724,63.0
55.986476079,67.0
56.024076434,80.0
56.061676789,66.0
56.099277145,47.0
56.136877500,52.0
56.174477855,47.0
56.212078210,37.0
56.249678565,34.0
56.287278921,23.0
56.324879276,26.0
56.362479631,26.0
56.400079986,26.0
56.437680341,16.0
56.475280697,7.0
56.512881052,8.0
56.550481407,8.0
56.588081762,10.0
56.625682117,10.0
56.663282473,10.0
56.700882828,3.0
56.738483183,5.0
56.776083538,5.0
56.813683893,3.0
56.851284249,8.0
56.888884604,3.0
56.926484959,4.0
56.964085314,8.0
57.001685669,7.0
57.039286025,8.0
57.076886380,7.0
57.114486735,8.0
57.152087090,10.0
57.189687445,7.0
57.227287801,4.0
57.264888156,4.0
57.302488511,8.0
57.340088866,8.0
57.377689221,4.0
57.415289577,11.0
57.452889932,5.0
57.490490287,8.0
57.528090642,3.0
57.565690997,10.0
57.603291353,4.0
57.640891708,5.0
57.678492063,2.0
57.716092418,5.0
57.753692773,5.0
57.791293129,5.0
57.828893484,2.0
57.866493839,9.0
57.904094194,7.0
57.941694549,9.0
57.979294905,3.0
58.016895260,15.0
58.054495615,7.0
58.092095970,7.0
58.129696325,4.0
58.167296681,2.0
58.204897036,5.0
58.242497391,9.0
58.280097746,3.0
58.317698101,1.0
58.355298457,8.0
58.392898812,8.0
58.430499167,4.0
58.468099522,2.0
58.505699877,5.0
58.543300233,3.0
58.580900588,10.0
58.618500943,8.0
58.656101298,7.0
58.693701653,4.0
58.731302009,5.0
58.768902364,3.0
58.806502719,7.0
58.844103074,5.0
58.881703429,5.0
58.919303785,5.0
58.956904140,7.0
58.994504495,3.0
59.032104850,8.0
59.069705206,4.0
59.107305561,5.0
59.144905916,4.0
59.182506271,0.0
59.220106626,4.0
59.257706982,1.0
59.295307337,4.0
59.332907692,4.0
59.370508047,0.0
59.408108402,3.0
59.445708758,4.0
59.483309113,4.0
59.520909468,4.0
59.558509823,2.0
59.596110178,1.0
59.633710534,4.0
59.671310889,3.0
59.708911244,1.0
59.746511599,5.0
59.784111954,9.0
59.821712310,13.0
59.859312665,9.0
59.896913020,17.0
59.934513375,7.0
59.972113730,8.0
60.009714086,10.0
60.047314441,9.0
60.084914796,8.0
60.122515151,11.0
60.160115506,10.0
60.197715862,9.0
60.235316217,4.0
60.272916572,4.0
60.310516927,9.0
60.348117282,4.0
60.385717638,0.0
60.423317993,3.0
60.460918348,5.0
60.498518703,3.0
60.536119058,8.0
60.573719414,3.0
60.611319769,3.0
60.648920124,5.0
60.686520479,8.0
60.724120834,7.0
60.761721190,3.0
60.799321545,3.0
60.836921900,4.0
60.874522255,2.0
60.912122610,2.0
60.949722966,5.0
60.987323321,2.0
61.024923676,2.0
61.062524031,0.0
61.100124386,2.0
61.137724742,2.0
61.175325097,2.0
61.212925452,3.0
61.250525807,3.0
61.288126162,2.0
61.325726518,4.0
61.363326873,15.0
61.400927228,8.0
61.438527583,3.0
61.476127938,7.0
61.513728294,2.0
61.551328649,9.0
61.588929004,4.0
61.626529359,5.0
61.664129714,3.0
61.701730070,4.0
61.739330425,5.0
61.776930780,8.0
61.814531135,8.0
61.852131490,9.0
61.889731846,3.0
61.927332201,5.0
61.964932556,3.0
62.002532911,7.0
62.040133266,7.0
62.077733622,11.0
62.115333977,3.0
62.152934332,8.0
62.190534687,2.0
62.228135042,13.0
62.265735398,10.0
62.303335753,3.0
62.340936108,2.0
62.378536463,1.0
62.416136818,1.0
62.453737174,0.0
62.491337529,1.0
62.528937884,3.0
62.566538239,3.0
62.604138594,1.0
62.641738950,2.0
62.679339305,4.0
62.716939660,3.0
62.754540015,0.0
62.792140370,4.0
62.829740726,7.0
62.867341081,4.0
62.904941436,9.0
62.942541791,15.0
62.980142146,18.0
63.017742502,4.0
63.055342857,7.0
63.092943212,4.0
63.130543567,13.0
63.168143922,5.0
63.205744278,3.0
63.243344633,9.0
63.280944988,3.0
63.318545343,2.0
63.356145698,5.0
63.393746054,5.0
63.431346409,3.0
63.468946764,5.0
63.506547119,1.0
63.544147474,4.0
63.581747830,9.0
63.619348185,4.0
63.656948540,4.0
63.694548895,2.0
63.732149250,4.0
63.769749606,7.0
63.807349961,10.0
63.844950316,2.0
63.882550671,4.0
63.920151026,2.0
63.957751382,2.0
63.995351737,4.0
64.032952092,7.0
64.070552447,3.0
64.108152802,11.0
64.145753158,5.0
64.183353513,3.0
64.220953868,10.0
64.258554223,13.0
64.296154578,11.0
64.333754934,14.0
64.371355289,14.0
64.408955644,24.0
64.446555999,30.0
64.484156354,36.0
64.521756710,48.0
64.559357065,41.0
64.596957420,40.0
64.634557775,42.0
64.672158130,40.0
64.709758486,55.0
64.747358841,47.0
64.784959196,39.0
64.822559551,34.0
64.860159906,33.0
64.897760262,29.0
64.935360617,21.0
64.972960972,26.0
65.010561327,27.0
65.048161682,17.0
65.085762038,22.0
65.123362393,16.0
65.160962748,18.0
65.198563103,15.0
65.236163458,9.0
65.273763814,11.0
65.311364169,8.0
65.348964524,11.0
65.386564879,13.0
65.424165234,22.0
65.461765590,26.0
65.499365945,22.0
65.536966300,17.0
65.574566655,16.0
65.612167010,11.0
65.649767366,29.0
65.687367721,17.0
65.724968076,11.0
65.762568431,24.0
65.800168786,22.0
65.837769142,14.0
65.875369497,18.0
65.912969852,17.0
65.950570207,27.0
65.988170562,16.0
66.025770918,18.0
66.063371273,9.0
66.100971628,10.0
66.138571983,9.0
66.176172338,16.0
66.213772694,18.0
66.251373049,10.0
66.288973404,14.0
66.326573759,5.0
66.364174114,8.0
66.401774470,3.0
66.439374825,8.0
66.476975180,7.0
66.514575535,4.0
66.552175890,4.0
66.589776246,1.0
66.627376601,9.0
66.664976956,9.0
66.702577311,7.0
66.740177666,7.0
66.777778022,3.0
66.815378377,8.0
66.852978732,8.0
66.890579087,7.0
66.928179443,5.0
66.965779798,3.0
67.003380153,8.0
67.040980508,1.0
67.078580863,3.0
67.116181219,2.0
67.153781574,2.0
67.191381929,5.0
67.228982284,2.0
67.266582639,3.0
67.304182995,7.0
67.341783350,2.0
67.379383705,3.0
67.416984060,2.0
67.454584415,2.0
67.492184771,5.0
67.529785126,5.0
67.567385481,4.0
67.604985836,3.0
67.642586191,4.0
67.680186547,3.0
67.717786902,0.0
67.755387257,5.0
67.792987612,9.0
67.830587967,4.0
67.868188323,5.0
67.905788678,5.0
67.943389033,13.0
67.980989388,10.0
68.018589743,11.0
68.056190099,9.0
68.093790454,7.0
68.131390809,4.0
68.168991164,9.0
68.206591519,2.0
68.244191875,0.0
68.281792230,3.0
68.319392585,4.0
68.356992940,1.0
68.394593295,7.0
68.432193651,3.0
68.469794006,4.0
68.507394361,4.0
68.544994716,2.0
68.582595071,3.0
68.620195427,2.0
68.657795782,7.0
68.695396137,8.0
68.732996492,8.0
68.770596847,3.0
68.808197203,8.0
68.845797558,9.0
68.883397913,5.0
68.920998268,3.0
68.958598623,13.0
68.996198979,16.0
69.033799334,16.0
69.071399689,23.0
69.109000044,11.0
69.146600399,21.0
69.184200755,16.0
69.221801110,11.0
69.259401465,16.0
69.297001820,22.0
69.334602175,20.0
69.372202531,22.0
69.409802886,16.0
69.447403241,14.0
69.485003596,17.0
69.522603951,13.0
69.560204307,13.0
69.597804662,15.0
69.635405017,10.0
69.673005372,14.0
69.710605727,16.0
69.748206083,16.0
69.785806438,8.0
69.823406793,11.0
69.861007148,8.0
69.898607503,9.0
69.936207859,7.0
69.973808214,3.0
69.994697300,17.0