File: PeakFitting/xrdData/ware_pzt/Reactively sintered PZT for XRD - Batch 1_15-70 deg_0.004 step_4 sec per step_2.csv
[Measurement conditions]
Sample identification,
Comment - 1,"Configuration=MPSS New Configuration, Owner=User-1, Creation date=10/27/2010 9:00:11 AM"
Comment - 2,"Goniometer=PW3050/60 (Theta/Theta); Minimum step size 2Theta:0.001; Minimum step size Omega:0.001"
Comment - 3,"Sample stage=Multi purpose sample stage; Minimum step size Phi:2.5"
Comment - 4,"Diffractometer system=XPERT-PRO"
Comment - 5,"Measurement program=C:\PANalytical\Data Collector\Programs\JIvy\15-70 deg_0.004 step_4 sec per step.xrdmp, Identifier={D694021A-0495-4B56-AF4C-96A93E3EEBAF}"
Anode material,Cu
K-Alpha1 wavelength,1.5405980
K-Alpha2 wavelength,1.5444260
Ratio K-Alpha2/K-Alpha1,0.500
Divergence slit,Fixed,0.19mm
Monochromator used,NO
Generator voltage, 45
Tube current, 40
File date and time,20/Oct/2020 15:33
Unit cell,
h k l, 0 0 0
Scan axis,Gonio
Scan range,15.000000001,69.996786209
Scan step size,0.0041778
No. of points, 13164
Scan type,CONTINUOUS
Phi,0.0
Time per step,3.810
[Scan points]
Angle,Intensity
15.002088910,15.0
15.039689265,8.0
15.077289620,13.0
15.114889976,14.0
15.152490331,4.0
15.190090686,7.0
15.227691041,14.0
15.265291396,13.0
15.302891752,8.0
15.340492107,5.0
15.378092462,14.0
15.415692817,10.0
15.453293172,9.0
15.490893528,14.0
15.528493883,8.0
15.566094238,8.0
15.603694593,11.0
15.641294948,11.0
15.678895304,15.0
15.716495659,7.0
15.754096014,8.0
15.791696369,3.0
15.829296724,11.0
15.866897080,7.0
15.904497435,10.0
15.942097790,5.0
15.979698145,8.0
16.017298500,5.0
16.054898856,5.0
16.092499211,5.0
16.130099566,13.0
16.167699921,10.0
16.205300276,3.0
16.242900632,4.0
16.280500987,10.0
16.318101342,7.0
16.355701697,10.0
16.393302052,14.0
16.430902408,8.0
16.468502763,13.0
16.506103118,13.0
16.543703473,9.0
16.581303828,7.0
16.618904184,7.0
16.656504539,13.0
16.694104894,8.0
16.731705249,5.0
16.769305604,4.0
16.806905960,16.0
16.844506315,8.0
16.882106670,4.0
16.919707025,8.0
16.957307380,9.0
16.994907736,7.0
17.032508091,9.0
17.070108446,14.0
17.107708801,7.0
17.145309156,7.0
17.182909512,4.0
17.220509867,4.0
17.258110222,20.0
17.295710577,13.0
17.333310932,9.0
17.370911288,10.0
17.408511643,4.0
17.446111998,11.0
17.483712353,13.0
17.521312708,7.0
17.558913064,9.0
17.596513419,4.0
17.634113774,7.0
17.671714129,9.0
17.709314484,7.0
17.746914840,9.0
17.784515195,5.0
17.822115550,8.0
17.859715905,4.0
17.897316260,7.0
17.934916616,7.0
17.972516971,20.0
18.010117326,8.0
18.047717681,11.0
18.085318036,8.0
18.122918392,9.0
18.160518747,14.0
18.198119102,8.0
18.235719457,3.0
18.273319812,11.0
18.310920168,11.0
18.348520523,4.0
18.386120878,10.0
18.423721233,8.0
18.461321588,9.0
18.498921944,7.0
18.536522299,7.0
18.574122654,10.0
18.611723009,7.0
18.649323364,7.0
18.686923720,7.0
18.724524075,5.0
18.762124430,9.0
18.799724785,9.0
18.837325140,9.0
18.874925496,10.0
18.912525851,8.0
18.950126206,5.0
18.987726561,8.0
19.025326917,8.0
19.062927272,13.0
19.100527627,7.0
19.138127982,13.0
19.175728337,15.0
19.213328693,8.0
19.250929048,8.0
19.288529403,7.0
19.326129758,5.0
19.363730113,5.0
19.401330469,7.0
19.438930824,7.0
19.476531179,10.0
19.514131534,7.0
19.551731889,5.0
19.589332245,3.0
19.626932600,5.0
19.664532955,8.0
19.702133310,7.0
19.739733665,10.0
19.777334021,5.0
19.814934376,10.0
19.852534731,3.0
19.890135086,1.0
19.927735441,5.0
19.965335797,3.0
20.002936152,7.0
20.040536507,4.0
20.078136862,4.0
20.115737217,4.0
20.153337573,5.0
20.190937928,2.0
20.228538283,10.0
20.266138638,7.0
20.303738993,10.0
20.341339349,9.0
20.378939704,4.0
20.416540059,8.0
20.454140414,3.0
20.491740769,8.0
20.529341125,7.0
20.566941480,9.0
20.604541835,16.0
20.642142190,4.0
20.679742545,5.0
20.717342901,13.0
20.754943256,3.0
20.792543611,5.0
20.830143966,7.0
20.867744321,13.0
20.905344677,8.0
20.942945032,10.0
20.980545387,11.0
21.018145742,13.0
21.055746097,8.0
21.093346453,7.0
21.130946808,9.0
21.168547163,11.0
21.206147518,14.0
21.243747873,14.0
21.281348229,23.0
21.318948584,33.0
21.356548939,56.0
21.394149294,56.0
21.431749649,97.0
21.469350005,175.0
21.506950360,137.0
21.544550715,101.0
21.582151070,53.0
21.619751425,30.0
21.657351781,28.0
21.694952136,23.0
21.732552491,13.0
21.770152846,11.0
21.807753201,18.0
21.845353557,13.0
21.882953912,24.0
21.920554267,29.0
21.958154622,46.0
21.995754977,47.0
22.033355333,73.0
22.070955688,107.0
22.108556043,131.0
22.146156398,122.0
22.183756753,138.0
22.221357109,85.0
22.258957464,74.0
22.296557819,69.0
22.334158174,40.0
22.371758529,28.0
22.409358885,21.0
22.446959240,17.0
22.484559595,4.0
22.522159950,7.0
22.559760305,10.0
22.597360661,8.0
22.634961016,5.0
22.672561371,8.0
22.710161726,11.0
22.747762081,4.0
22.785362437,3.0
22.822962792,7.0
22.860563147,5.0
22.898163502,4.0
22.935763857,9.0
22.973364213,5.0
23.010964568,8.0
23.048564923,7.0
23.086165278,8.0
23.123765633,4.0
23.161365989,3.0
23.198966344,9.0
23.236566699,4.0
23.274167054,3.0
23.311767409,4.0
23.349367765,4.0
23.386968120,5.0
23.424568475,7.0
23.462168830,5.0
23.499769185,5.0
23.537369541,5.0
23.574969896,11.0
23.612570251,4.0
23.650170606,7.0
23.687770961,9.0
23.725371317,8.0
23.762971672,9.0
23.800572027,4.0
23.838172382,7.0
23.875772737,3.0
23.913373093,10.0
23.950973448,7.0
23.988573803,8.0
24.026174158,7.0
24.063774513,23.0
24.101374869,17.0
24.138975224,15.0
24.176575579,13.0
24.214175934,11.0
24.251776289,9.0
24.289376645,7.0
24.326977000,2.0
24.364577355,7.0
24.402177710,4.0
24.439778065,8.0
24.477378421,15.0
24.514978776,14.0
24.552579131,18.0
24.590179486,24.0
24.627779841,5.0
24.665380197,10.0
24.702980552,5.0
24.740580907,4.0
24.778181262,7.0
24.815781617,7.0
24.853381973,4.0
24.890982328,8.0
24.928582683,13.0
24.966183038,4.0
25.003783393,3.0
25.041383749,4.0
25.078984104,8.0
25.116584459,7.0
25.154184814,4.0
25.191785169,8.0
25.229385525,4.0
25.266985880,7.0
25.304586235,7.0
25.342186590,4.0
25.379786945,2.0
25.417387301,3.0
25.454987656,7.0
25.492588011,7.0
25.530188366,7.0
25.567788721,5.0
25.605389077,4.0
25.642989432,7.0
25.680589787,14.0
25.718190142,2.0
25.755790497,7.0
25.793390853,4.0
25.830991208,3.0
25.868591563,2.0
25.906191918,9.0
25.943792273,4.0
25.981392629,11.0
26.018992984,4.0
26.056593339,9.0
26.094193694,7.0
26.131794049,5.0
26.169394405,5.0
26.206994760,3.0
26.244595115,8.0
26.282195470,5.0
26.319795825,3.0
26.357396181,8.0
26.394996536,8.0
26.432596891,2.0
26.470197246,3.0
26.507797601,3.0
26.545397957,5.0
26.582998312,4.0
26.620598667,4.0
26.658199022,2.0
26.695799377,9.0
26.733399733,5.0
26.771000088,5.0
26.808600443,5.0
26.846200798,2.0
26.883801153,4.0
26.921401509,3.0
26.959001864,3.0
26.996602219,4.0
27.034202574,3.0
27.071802930,8.0
27.109403285,2.0
27.147003640,7.0
27.184603995,3.0
27.222204350,5.0
27.259804706,3.0
27.297405061,3.0
27.335005416,2.0
27.372605771,9.0
27.410206126,8.0
27.447806482,3.0
27.485406837,8.0
27.523007192,3.0
27.560607547,8.0
27.598207902,8.0
27.635808258,1.0
27.673408613,7.0
27.711008968,10.0
27.748609323,9.0
27.786209678,5.0
27.823810034,7.0
27.861410389,8.0
27.899010744,9.0
27.936611099,3.0
27.974211454,7.0
28.011811810,9.0
28.049412165,7.0
28.087012520,10.0
28.124612875,16.0
28.162213230,37.0
28.199813586,54.0
28.237413941,97.0
28.275014296,73.0
28.312614651,42.0
28.350215006,28.0
28.387815362,11.0
28.425415717,4.0
28.463016072,7.0
28.500616427,7.0
28.538216782,5.0
28.575817138,3.0
28.613417493,9.0
28.651017848,5.0
28.688618203,5.0
28.726218558,1.0
28.763818914,8.0
28.801419269,4.0
28.839019624,5.0
28.876619979,5.0
28.914220334,7.0
28.951820690,2.0
28.989421045,7.0
29.027021400,9.0
29.064621755,7.0
29.102222110,8.0
29.139822466,9.0
29.177422821,7.0
29.215023176,5.0
29.252623531,9.0
29.290223886,3.0
29.327824242,7.0
29.365424597,3.0
29.403024952,3.0
29.440625307,5.0
29.478225662,5.0
29.515826018,3.0
29.553426373,5.0
29.591026728,7.0
29.628627083,5.0
29.666227438,13.0
29.703827794,13.0
29.741428149,7.0
29.779028504,7.0
29.816628859,14.0
29.854229214,4.0
29.891829570,5.0
29.929429925,10.0
29.967030280,9.0
30.004630635,9.0
30.042230990,11.0
30.079831346,10.0
30.117431701,8.0
30.155032056,10.0
30.192632411,8.0
30.230232766,7.0
30.267833122,7.0
30.305433477,8.0
30.343033832,11.0
30.380634187,10.0
30.418234542,18.0
30.455834898,13.0
30.493435253,10.0
30.531035608,14.0
30.568635963,17.0
30.606236318,15.0
30.643836674,26.0
30.681437029,33.0
30.719037384,23.0
30.756637739,39.0
30.794238094,50.0
30.831838450,90.0
30.869438805,142.0
30.907039160,260.0
30.944639515,407.0
30.982239870,688.0
31.019840226,736.0
31.057440581,748.0
31.095040936,677.0
31.132641291,488.0
31.170241646,376.0
31.207842002,231.0
31.245442357,200.0
31.283042712,152.0
31.320643067,188.0
31.358243422,170.0
31.395843778,195.0
31.433444133,214.0
31.471044488,255.0
31.508644843,334.0
31.546245198,316.0
31.583845554,251.0
31.621445909,188.0
31.659046264,144.0
31.696646619,94.0
31.734246974,78.0
31.771847330,66.0
31.809447685,48.0
31.847048040,59.0
31.884648395,36.0
31.922248750,22.0
31.959849106,18.0
31.997449461,11.0
32.035049816,20.0
32.072650171,8.0
32.110250526,8.0
32.147850882,7.0
32.185451237,5.0
32.223051592,7.0
32.260651947,1.0
32.298252302,10.0
32.335852658,4.0
32.373453013,9.0
32.411053368,2.0
32.448653723,7.0
32.486254078,8.0
32.523854434,4.0
32.561454789,5.0
32.599055144,4.0
32.636655499,1.0
32.674255854,3.0
32.711856210,8.0
32.749456565,2.0
32.787056920,3.0
32.824657275,8.0
32.862257630,10.0
32.899857986,5.0
32.937458341,4.0
32.975058696,1.0
33.012659051,3.0
33.050259406,5.0
33.087859762,8.0
33.125460117,3.0
33.163060472,2.0
33.200660827,3.0
33.238261182,4.0
33.275861538,4.0
33.313461893,3.0
33.351062248,8.0
33.388662603,3.0
33.426262958,4.0
33.463863314,5.0
33.501463669,2.0
33.539064024,2.0
33.576664379,3.0
33.614264734,4.0
33.651865090,1.0
33.689465445,5.0
33.727065800,8.0
33.764666155,7.0
33.802266510,7.0
33.839866866,5.0
33.877467221,5.0
33.915067576,2.0
33.952667931,2.0
33.990268286,5.0
34.027868642,3.0
34.065468997,9.0
34.103069352,7.0
34.140669707,10.0
34.178270062,13.0
34.215870418,29.0
34.253470773,23.0
34.291071128,11.0
34.328671483,9.0
34.366271838,4.0
34.403872194,16.0
34.441472549,8.0
34.479072904,21.0
34.516673259,14.0
34.554273614,7.0
34.591873970,7.0
34.629474325,7.0
34.667074680,1.0
34.704675035,7.0
34.742275390,2.0
34.779875746,8.0
34.817476101,4.0
34.855076456,4.0
34.892676811,5.0
34.930277166,8.0
34.967877522,7.0
35.005477877,3.0
35.043078232,7.0
35.080678587,4.0
35.118278943,4.0
35.155879298,2.0
35.193479653,2.0
35.231080008,9.0
35.268680363,3.0
35.306280719,9.0
35.343881074,10.0
35.381481429,16.0
35.419081784,5.0
35.456682139,17.0
35.494282495,10.0
35.531882850,9.0
35.569483205,7.0
35.607083560,4.0
35.644683915,5.0
35.682284271,3.0
35.719884626,4.0
35.757484981,2.0
35.795085336,3.0
35.832685691,3.0
35.870286047,5.0
35.907886402,9.0
35.945486757,8.0
35.983087112,4.0
36.020687467,5.0
36.058287823,3.0
36.095888178,8.0
36.133488533,5.0
36.171088888,4.0
36.208689243,4.0
36.246289599,8.0
36.283889954,1.0
36.321490309,3.0
36.359090664,3.0
36.396691019,3.0
36.434291375,5.0
36.471891730,1.0
36.509492085,4.0
36.547092440,11.0
36.584692795,3.0
36.622293151,5.0
36.659893506,4.0
36.697493861,2.0
36.735094216,7.0
36.772694571,3.0
36.810294927,3.0
36.847895282,7.0
36.885495637,3.0
36.923095992,3.0
36.960696347,5.0
36.998296703,5.0
37.035897058,4.0
37.073497413,3.0
37.111097768,3.0
37.148698123,0.0
37.186298479,2.0
37.223898834,4.0
37.261499189,4.0
37.299099544,3.0
37.336699899,5.0
37.374300255,4.0
37.411900610,4.0
37.449500965,8.0
37.487101320,2.0
37.524701675,5.0
37.562302031,2.0
37.599902386,3.0
37.637502741,5.0
37.675103096,4.0
37.712703451,5.0
37.750303807,4.0
37.787904162,4.0
37.825504517,7.0
37.863104872,5.0
37.900705227,9.0
37.938305583,7.0
37.975905938,5.0
38.013506293,5.0
38.051106648,11.0
38.088707003,13.0
38.126307359,9.0
38.163907714,9.0
38.201508069,18.0
38.239108424,28.0
38.276708779,56.0
38.314309135,88.0
38.351909490,113.0
38.389509845,114.0
38.427110200,120.0
38.464710555,136.0
38.502310911,104.0
38.539911266,106.0
38.577511621,91.0
38.615111976,75.0
38.652712331,68.0
38.690312687,37.0
38.727913042,27.0
38.765513397,15.0
38.803113752,23.0
38.840714107,9.0
38.878314463,11.0
38.915914818,8.0
38.953515173,7.0
38.991115528,1.0
39.028715883,2.0
39.066316239,3.0
39.103916594,9.0
39.141516949,3.0
39.179117304,2.0
39.216717659,4.0
39.254318015,9.0
39.291918370,7.0
39.329518725,8.0
39.367119080,7.0
39.404719435,4.0
39.442319791,9.0
39.479920146,9.0
39.517520501,11.0
39.555120856,4.0
39.592721211,7.0
39.630321567,4.0
39.667921922,3.0
39.705522277,5.0
39.743122632,7.0
39.780722987,7.0
39.818323343,2.0
39.855923698,2.0
39.893524053,3.0
39.931124408,7.0
39.968724763,0.0
40.006325119,5.0
40.043925474,7.0
40.081525829,2.0
40.119126184,5.0
40.156726539,2.0
40.194326895,7.0
40.231927250,4.0
40.269527605,8.0
40.307127960,8.0
40.344728315,3.0
40.382328671,4.0
40.419929026,1.0
40.457529381,4.0
40.495129736,1.0
40.532730091,4.0
40.570330447,3.0
40.607930802,4.0
40.645531157,7.0
40.683131512,5.0
40.720731867,7.0
40.758332223,13.0
40.795932578,23.0
40.833532933,20.0
40.871133288,9.0
40.908733643,8.0
40.946333999,3.0
40.983934354,7.0
41.021534709,5.0
41.059135064,7.0
41.096735419,5.0
41.134335775,5.0
41.171936130,5.0
41.209536485,11.0
41.247136840,8.0
41.284737195,4.0
41.322337551,5.0
41.359937906,4.0
41.397538261,9.0
41.435138616,9.0
41.472738971,8.0
41.510339327,9.0
41.547939682,9.0
41.585540037,5.0
41.623140392,5.0
41.660740747,7.0
41.698341103,3.0
41.735941458,2.0
41.773541813,5.0
41.811142168,5.0
41.848742523,1.0
41.886342879,5.0
41.923943234,3.0
41.961543589,7.0
41.999143944,1.0
42.036744299,4.0
42.074344655,3.0
42.111945010,8.0
42.149545365,2.0
42.187145720,4.0
42.224746075,7.0
42.262346431,1.0
42.299946786,2.0
42.337547141,3.0
42.375147496,3.0
42.412747851,3.0
42.450348207,5.0
42.487948562,1.0
42.525548917,2.0
42.563149272,3.0
42.600749627,2.0
42.638349983,3.0
42.675950338,4.0
42.713550693,7.0
42.751151048,5.0
42.788751403,9.0
42.826351759,4.0
42.863952114,4.0
42.901552469,4.0
42.939152824,8.0
42.976753180,5.0
43.014353535,4.0
43.051953890,14.0
43.089554245,8.0
43.127154600,3.0
43.164754956,3.0
43.202355311,4.0
43.239955666,8.0
43.277556021,4.0
43.315156376,3.0
43.352756732,10.0
43.390357087,4.0
43.427957442,14.0
43.465557797,7.0
43.503158152,5.0
43.540758508,20.0
43.578358863,23.0
43.615959218,46.0
43.653559573,72.0
43.691159928,122.0
43.728760284,98.0
43.766360639,63.0
43.803960994,86.0
43.841561349,61.0
43.879161704,40.0
43.916762060,29.0
43.954362415,18.0
43.991962770,22.0
44.029563125,10.0
44.067163480,17.0
44.104763836,8.0
44.142364191,9.0
44.179964546,10.0
44.217564901,8.0
44.255165256,8.0
44.292765612,8.0
44.330365967,10.0
44.367966322,13.0
44.405566677,7.0
44.443167032,8.0
44.480767388,10.0
44.518367743,7.0
44.555968098,11.0
44.593568453,11.0
44.631168808,10.0
44.668769164,13.0
44.706369519,9.0
44.743969874,16.0
44.781570229,16.0
44.819170584,23.0
44.856770940,42.0
44.894371295,39.0
44.931971650,55.0
44.969572005,75.0
45.007172360,105.0
45.044772716,78.0
45.082373071,116.0
45.119973426,110.0
45.157573781,113.0
45.195174136,98.0
45.232774492,98.0
45.270374847,79.0
45.307975202,65.0
45.345575557,63.0
45.383175912,41.0
45.420776268,62.0
45.458376623,54.0
45.495976978,45.0
45.533577333,35.0
45.571177688,42.0
45.608778044,29.0
45.646378399,39.0
45.683978754,15.0
45.721579109,13.0
45.759179464,9.0
45.796779820,10.0
45.834380175,8.0
45.871980530,8.0
45.909580885,4.0
45.947181240,4.0
45.984781596,8.0
46.022381951,8.0
46.059982306,3.0
46.097582661,4.0
46.135183016,5.0
46.172783372,3.0
46.210383727,9.0
46.247984082,8.0
46.285584437,5.0
46.323184792,7.0
46.360785148,7.0
46.398385503,7.0
46.435985858,4.0
46.473586213,9.0
46.511186568,3.0
46.548786924,0.0
46.586387279,9.0
46.623987634,2.0
46.661587989,3.0
46.699188344,3.0
46.736788700,7.0
46.774389055,2.0
46.811989410,5.0
46.849589765,3.0
46.887190120,3.0
46.924790476,7.0
46.962390831,4.0
46.999991186,3.0
47.037591541,7.0
47.075191896,4.0
47.112792252,4.0
47.150392607,5.0
47.187992962,5.0
47.225593317,5.0
47.263193672,7.0
47.300794028,7.0
47.338394383,3.0
47.375994738,8.0
47.413595093,4.0
47.451195448,8.0
47.488795804,3.0
47.526396159,5.0
47.563996514,4.0
47.601596869,4.0
47.639197224,2.0
47.676797580,8.0
47.714397935,11.0
47.751998290,4.0
47.789598645,8.0
47.827199000,3.0
47.864799356,2.0
47.902399711,4.0
47.940000066,8.0
47.977600421,2.0
48.015200776,8.0
48.052801132,5.0
48.090401487,2.0
48.128001842,2.0
48.165602197,2.0
48.203202552,13.0
48.240802908,2.0
48.278403263,9.0
48.316003618,7.0
48.353603973,4.0
48.391204328,5.0
48.428804684,3.0
48.466405039,5.0
48.504005394,5.0
48.541605749,3.0
48.579206104,8.0
48.616806460,7.0
48.654406815,10.0
48.692007170,3.0
48.729607525,2.0
48.767207880,7.0
48.804808236,3.0
48.842408591,4.0
48.880008946,4.0
48.917609301,3.0
48.955209656,5.0
48.992810012,9.0
49.030410367,5.0
49.068010722,13.0
49.105611077,9.0
49.143211432,10.0
49.180811788,11.0
49.218412143,13.0
49.256012498,11.0
49.293612853,16.0
49.331213208,29.0
49.368813564,24.0
49.406413919,30.0
49.444014274,50.0
49.481614629,53.0
49.519214984,72.0
49.556815340,48.0
49.594415695,52.0
49.632016050,48.0
49.669616405,33.0
49.707216760,33.0
49.744817116,16.0
49.782417471,28.0
49.820017826,15.0
49.857618181,8.0
49.895218536,10.0
49.932818892,14.0
49.970419247,11.0
50.008019602,5.0
50.045619957,14.0
50.083220312,15.0
50.120820668,17.0
50.158421023,21.0
50.196021378,42.0
50.233621733,27.0
50.271222088,24.0
50.308822444,29.0
50.346422799,29.0
50.384023154,30.0
50.421623509,28.0
50.459223864,24.0
50.496824220,27.0
50.534424575,40.0
50.572024930,28.0
50.609625285,43.0
50.647225640,34.0
50.684825996,31.0
50.722426351,29.0
50.760026706,27.0
50.797627061,26.0
50.835227416,30.0
50.872827772,35.0
50.910428127,18.0
50.948028482,21.0
50.985628837,18.0
51.023229193,16.0
51.060829548,18.0
51.098429903,10.0
51.136030258,14.0
51.173630613,16.0
51.211230969,15.0
51.248831324,7.0
51.286431679,15.0
51.324032034,8.0
51.361632389,10.0
51.399232745,5.0
51.436833100,9.0
51.474433455,10.0
51.512033810,4.0
51.549634165,10.0
51.587234521,5.0
51.624834876,1.0
51.662435231,5.0
51.700035586,5.0
51.737635941,4.0
51.775236297,3.0
51.812836652,9.0
51.850437007,5.0
51.888037362,9.0
51.925637717,9.0
51.963238073,4.0
52.000838428,7.0
52.038438783,9.0
52.076039138,3.0
52.113639493,5.0
52.151239849,3.0
52.188840204,2.0
52.226440559,4.0
52.264040914,5.0
52.301641269,4.0
52.339241625,4.0
52.376841980,4.0
52.414442335,4.0
52.452042690,1.0
52.489643045,2.0
52.527243401,5.0
52.564843756,1.0
52.602444111,4.0
52.640044466,5.0
52.677644821,5.0
52.715245177,3.0
52.752845532,5.0
52.790445887,4.0
52.828046242,1.0
52.865646597,7.0
52.903246953,8.0
52.940847308,3.0
52.978447663,8.0
53.016048018,13.0
53.053648373,2.0
53.091248729,3.0
53.128849084,5.0
53.166449439,8.0
53.204049794,3.0
53.241650149,4.0
53.279250505,5.0
53.316850860,4.0
53.354451215,3.0
53.392051570,3.0
53.429651925,7.0
53.467252281,9.0
53.504852636,2.0
53.542452991,5.0
53.580053346,7.0
53.617653701,5.0
53.655254057,4.0
53.692854412,3.0
53.730454767,8.0
53.768055122,11.0
53.805655477,2.0
53.843255833,9.0
53.880856188,13.0
53.918456543,5.0
53.956056898,3.0
53.993657253,5.0
54.031257609,11.0
54.068857964,11.0
54.106458319,14.0
54.144058674,16.0
54.181659029,18.0
54.219259385,9.0
54.256859740,14.0
54.294460095,5.0
54.332060450,9.0
54.369660805,4.0
54.407261161,9.0
54.444861516,8.0
54.482461871,5.0
54.520062226,16.0
54.557662581,16.0
54.595262937,9.0
54.632863292,17.0
54.670463647,33.0
54.708064002,31.0
54.745664357,69.0
54.783264713,85.0
54.820865068,110.0
54.858465423,85.0
54.896065778,85.0
54.933666133,113.0
54.971266489,73.0
55.008866844,81.0
55.046467199,63.0
55.084067554,58.0
55.121667909,48.0
55.159268265,33.0
55.196868620,48.0
55.234468975,34.0
55.272069330,37.0
55.309669685,17.0
55.347270041,35.0
55.384870396,31.0
55.422470751,41.0
55.460071106,47.0
55.497671461,63.0
55.535271817,79.0
55.572872172,85.0
55.610472527,114.0
55.648072882,107.0
55.685673237,108.0
55.723273593,114.0
55.760873948,149.0
55.798474303,112.0
55.836074658,124.0
55.873675013,113.0
55.911275369,112.0
55.948875724,85.0
55.986476079,85.0
56.024076434,77.0
56.061676789,60.0
56.099277145,68.0
56.136877500,46.0
56.174477855,54.0
56.212078210,33.0
56.249678565,17.0
56.287278921,22.0
56.324879276,24.0
56.362479631,24.0
56.400079986,26.0
56.437680341,16.0
56.475280697,17.0
56.512881052,5.0
56.550481407,8.0
56.588081762,8.0
56.625682117,2.0
56.663282473,10.0
56.700882828,5.0
56.738483183,8.0
56.776083538,4.0
56.813683893,4.0
56.851284249,5.0
56.888884604,11.0
56.926484959,9.0
56.964085314,4.0
57.001685669,8.0
57.039286025,5.0
57.076886380,5.0
57.114486735,7.0
57.152087090,13.0
57.189687445,1.0
57.227287801,14.0
57.264888156,10.0
57.302488511,13.0
57.340088866,7.0
57.377689221,5.0
57.415289577,9.0
57.452889932,4.0
57.490490287,7.0
57.528090642,3.0
57.565690997,5.0
57.603291353,4.0
57.640891708,9.0
57.678492063,8.0
57.716092418,3.0
57.753692773,1.0
57.791293129,7.0
57.828893484,4.0
57.866493839,9.0
57.904094194,4.0
57.941694549,16.0
57.979294905,8.0
58.016895260,10.0
58.054495615,5.0
58.092095970,8.0
58.129696325,2.0
58.167296681,1.0
58.204897036,3.0
58.242497391,9.0
58.280097746,4.0
58.317698101,7.0
58.355298457,5.0
58.392898812,11.0
58.430499167,5.0
58.468099522,4.0
58.505699877,3.0
58.543300233,7.0
58.580900588,5.0
58.618500943,7.0
58.656101298,4.0
58.693701653,2.0
58.731302009,8.0
58.768902364,4.0
58.806502719,9.0
58.844103074,10.0
58.881703429,3.0
58.919303785,8.0
58.956904140,7.0
58.994504495,7.0
59.032104850,3.0
59.069705206,8.0
59.107305561,3.0
59.144905916,5.0
59.182506271,3.0
59.220106626,10.0
59.257706982,2.0
59.295307337,5.0
59.332907692,8.0
59.370508047,7.0
59.408108402,2.0
59.445708758,7.0
59.483309113,4.0
59.520909468,5.0
59.558509823,5.0
59.596110178,8.0
59.633710534,5.0
59.671310889,4.0
59.708911244,4.0
59.746511599,8.0
59.784111954,9.0
59.821712310,9.0
59.859312665,16.0
59.896913020,16.0
59.934513375,8.0
59.972113730,7.0
60.009714086,11.0
60.047314441,10.0
60.084914796,7.0
60.122515151,11.0
60.160115506,18.0
60.197715862,7.0
60.235316217,7.0
60.272916572,5.0
60.310516927,13.0
60.348117282,4.0
60.385717638,3.0
60.423317993,5.0
60.460918348,1.0
60.498518703,2.0
60.536119058,1.0
60.573719414,3.0
60.611319769,4.0
60.648920124,4.0
60.686520479,4.0
60.724120834,3.0
60.761721190,8.0
60.799321545,7.0
60.836921900,7.0
60.874522255,3.0
60.912122610,10.0
60.949722966,2.0
60.987323321,1.0
61.024923676,7.0
61.062524031,7.0
61.100124386,2.0
61.137724742,3.0
61.175325097,3.0
61.212925452,2.0
61.250525807,4.0
61.288126162,2.0
61.325726518,4.0
61.363326873,9.0
61.400927228,18.0
61.438527583,18.0
61.476127938,9.0
61.513728294,7.0
61.551328649,7.0
61.588929004,5.0
61.626529359,3.0
61.664129714,9.0
61.701730070,8.0
61.739330425,2.0
61.776930780,4.0
61.814531135,4.0
61.852131490,9.0
61.889731846,2.0
61.927332201,5.0
61.964932556,5.0
62.002532911,3.0
62.040133266,8.0
62.077733622,8.0
62.115333977,7.0
62.152934332,2.0
62.190534687,4.0
62.228135042,5.0
62.265735398,4.0
62.303335753,5.0
62.340936108,8.0
62.378536463,3.0
62.416136818,3.0
62.453737174,4.0
62.491337529,7.0
62.528937884,3.0
62.566538239,2.0
62.604138594,7.0
62.641738950,4.0
62.679339305,10.0
62.716939660,2.0
62.754540015,3.0
62.792140370,3.0
62.829740726,5.0
62.867341081,4.0
62.904941436,18.0
62.942541791,13.0
62.980142146,4.0
63.017742502,9.0
63.055342857,10.0
63.092943212,3.0
63.130543567,9.0
63.168143922,5.0
63.205744278,7.0
63.243344633,3.0
63.280944988,5.0
63.318545343,7.0
63.356145698,1.0
63.393746054,2.0
63.431346409,4.0
63.468946764,7.0
63.506547119,3.0
63.544147474,8.0
63.581747830,8.0
63.619348185,3.0
63.656948540,4.0
63.694548895,7.0
63.732149250,8.0
63.769749606,2.0
63.807349961,5.0
63.844950316,2.0
63.882550671,8.0
63.920151026,2.0
63.957751382,7.0
63.995351737,1.0
64.032952092,4.0
64.070552447,10.0
64.108152802,9.0
64.145753158,5.0
64.183353513,8.0
64.220953868,7.0
64.258554223,3.0
64.296154578,17.0
64.333754934,11.0
64.371355289,14.0
64.408955644,22.0
64.446555999,24.0
64.484156354,42.0
64.521756710,34.0
64.559357065,50.0
64.596957420,54.0
64.634557775,55.0
64.672158130,66.0
64.709758486,56.0
64.747358841,52.0
64.784959196,58.0
64.822559551,49.0
64.860159906,41.0
64.897760262,31.0
64.935360617,23.0
64.972960972,29.0
65.010561327,20.0
65.048161682,23.0
65.085762038,21.0
65.123362393,17.0
65.160962748,14.0
65.198563103,9.0
65.236163458,10.0
65.273763814,10.0
65.311364169,14.0
65.348964524,13.0
65.386564879,10.0
65.424165234,16.0
65.461765590,26.0
65.499365945,23.0
65.536966300,27.0
65.574566655,17.0
65.612167010,29.0
65.649767366,16.0
65.687367721,24.0
65.724968076,18.0
65.762568431,16.0
65.800168786,16.0
65.837769142,18.0
65.875369497,20.0
65.912969852,15.0
65.950570207,34.0
65.988170562,13.0
66.025770918,24.0
66.063371273,10.0
66.100971628,11.0
66.138571983,14.0
66.176172338,13.0
66.213772694,7.0
66.251373049,8.0
66.288973404,7.0
66.326573759,10.0
66.364174114,11.0
66.401774470,8.0
66.439374825,10.0
66.476975180,8.0
66.514575535,4.0
66.552175890,5.0
66.589776246,5.0
66.627376601,11.0
66.664976956,4.0
66.702577311,4.0
66.740177666,8.0
66.777778022,4.0
66.815378377,4.0
66.852978732,5.0
66.890579087,3.0
66.928179443,5.0
66.965779798,0.0
67.003380153,7.0
67.040980508,2.0
67.078580863,5.0
67.116181219,9.0
67.153781574,4.0
67.191381929,1.0
67.228982284,3.0
67.266582639,1.0
67.304182995,1.0
67.341783350,11.0
67.379383705,4.0
67.416984060,4.0
67.454584415,1.0
67.492184771,10.0
67.529785126,9.0
67.567385481,2.0
67.604985836,7.0
67.642586191,3.0
67.680186547,5.0
67.717786902,3.0
67.755387257,9.0
67.792987612,9.0
67.830587967,17.0
67.868188323,11.0
67.905788678,8.0
67.943389033,10.0
67.980989388,7.0
68.018589743,2.0
68.056190099,10.0
68.093790454,5.0
68.131390809,4.0
68.168991164,4.0
68.206591519,9.0
68.244191875,3.0
68.281792230,3.0
68.319392585,5.0
68.356992940,3.0
68.394593295,5.0
68.432193651,4.0
68.469794006,7.0
68.507394361,3.0
68.544994716,14.0
68.582595071,3.0
68.620195427,1.0
68.657795782,5.0
68.695396137,3.0
68.732996492,2.0
68.770596847,11.0
68.808197203,15.0
68.845797558,7.0
68.883397913,11.0
68.920998268,15.0
68.958598623,14.0
68.996198979,15.0
69.033799334,15.0
69.071399689,16.0
69.109000044,20.0
69.146600399,10.0
69.184200755,26.0
69.221801110,24.0
69.259401465,16.0
69.297001820,18.0
69.334602175,16.0
69.372202531,15.0
69.409802886,18.0
69.447403241,9.0
69.485003596,16.0
69.522603951,14.0
69.560204307,9.0
69.597804662,14.0
69.635405017,18.0
69.673005372,11.0
69.710605727,7.0
69.748206083,8.0
69.785806438,8.0
69.823406793,9.0
69.861007148,7.0
69.898607503,16.0
69.936207859,7.0
69.973808214,15.0
69.994697300,15.0