File: PeakFitting/xrdData/915+Si+powder.csv
[Measurement conditions],,,,,,,,,,,,,,,,,,,,,,,
Sample identification,,,,,,,,,,,,,,,,,,,,,,,
Comment - 1,"Configuration=MPSS New Configuration, Owner=User-1, Creation date=10/27/2010 9:00:11 AM",,,,,,,,,,,,,,,,,,,,,,
Comment - 2,Goniometer=PW3050/60 (Theta/Theta); Minimum step size 2Theta:0.001; Minimum step size Omega:0.001,,,,,,,,,,,,,,,,,,,,,,
Comment - 3,Sample stage=Multi purpose sample stage; Minimum step size Phi:2.5,,,,,,,,,,,,,,,,,,,,,,
Comment - 4,Diffractometer system=XPERT-PRO,,,,,,,,,,,,,,,,,,,,,,
Comment - 5,"Measurement program=C:\XRD Data\mcaplan\311 lab.xrdmp, Identifier={45589E5F-173F-4548-9E9A-391A8F8D5901}",,,,,,,,,,,,,,,,,,,,,,
Anode material,Cu,,,,,,,,,,,,,,lambda,2theta,theta,rad,,d,khl2,,a
K-Alpha1 wavelength,1.540598,,,,,,,,,,,,,,1.39225,28.4962,14.2481,0.248676257,2.828383479,7.999753102,3.088,24.70323758,4.970235163
K-Alpha2 wavelength,1.544426,,,,,,,,,,,,,,,47.3549,23.67745,0.413249461,1.733433514,3.004791747,8.222,24.70539774,4.970452469
Ratio K-Alpha2/K-Alpha1,0.5,,,,,,,,,,,,,,,56.1784,28.0892,0.490249024,1.47845707,2.185835307,11.302,24.70431064,4.970343111
Divergence slit,Fixed,0.19mm,,,,,,,,,,,,,,69.1631,34.58155,0.603561908,1.226481993,1.50425808,16.427,24.71044749,4.970960419
Monochromator used,NO,,,,,,,,,,,,,,,88.0468,44.0234,0.768353278,1.001687748,1.003378345,24.623,24.70618498,4.97053166
Generator voltage,45,,,,,,,,,,,,,,,,,,,,,,
Tube current,40,,,,,,,,,,,,,,,,,,,,,,
File date and time,11/6/2018 9:22,,,,,,,,,,,,,,,,,,,,,,
Unit cell,,,,,,,,,,,,,,,,,,,,,,,
h k l, 0 0 0,,,,,,,,,,,,,,,,,,,,,,
Scan axis,Gonio,,,,,,,,,,,,,,,,,,,,,,
Scan range,10.001,149.9996559,,,,,,,,,,,,,,,,,,,,,
Scan step size,0.0083556,,,,,,,,,,,,,,,,,,,,,,
No. of points,16755,,,,,,,,,,,,,,,,,,,,,,
Scan type,CONTINUOUS,,,,,,,,,,,,,,,,,,,,,,
Phi,0,,,,,,,,,,,,,,,,,,,,,,
Time per step,1.905,,,,,,,,,,,,,,,,,,,,,,
[Scan points],,,,,,,,,,,,,,,,,,,,,,,
Angle,Intensity,,,,,,,,,,,,,,,,,,,,,,
10.00517782,17,,,,,,,,,,,,,,,,,,,,,,
10.11380107,12,,,,,,,,,,,,,,,,,,,,,,
10.22242432,16,,,,,,,,,,,,,,,,,,,,,,
10.33104757,8,,,,,,,,,,,,,,,,,,,,,,
10.43967081,8,,,,,,,,,,,,,,,,,,,,,,
10.54829406,5,,,,,,,,,,,,,,,,,,,,,,
10.65691731,12,,,,,,,,,,,,,,,,,,,,,,
10.76554056,5,,,,,,,,,,,,,,,,,,,,,,
10.87416381,14,,,,,,,,,,,,,,,,,,,,,,
10.98278706,8,,,,,,,,,,,,,,,,,,,,,,
11.0914103,6,,,,,,,,,,,,,,,,,,,,,,
11.20003355,4,,,,,,,,,,,,,,,,,,,,,,
11.3086568,14,,,,,,,,,,,,,,,,,,,,,,
11.41728005,8,,,,,,,,,,,,,,,,,,,,,,
11.5259033,10,,,,,,,,,,,,,,,,,,,,,,
11.63452655,9,,,,,,,,,,,,,,,,,,,,,,
11.74314979,6,,,,,,,,,,,,,,,,,,,,,,
11.85177304,6,,,,,,,,,,,,,,,,,,,,,,
11.96039629,2,,,,,,,,,,,,,,,,,,,,,,
12.06901954,8,,,,,,,,,,,,,,,,,,,,,,
12.17764279,8,,,,,,,,,,,,,,,,,,,,,,
12.28626604,17,,,,,,,,,,,,,,,,,,,,,,
12.39488928,6,,,,,,,,,,,,,,,,,,,,,,
12.50351253,8,,,,,,,,,,,,,,,,,,,,,,
12.61213578,6,,,,,,,,,,,,,,,,,,,,,,
12.72075903,13,,,,,,,,,,,,,,,,,,,,,,
12.82938228,9,,,,,,,,,,,,,,,,,,,,,,
12.93800553,6,,,,,,,,,,,,,,,,,,,,,,
13.04662877,6,,,,,,,,,,,,,,,,,,,,,,
13.15525202,10,,,,,,,,,,,,,,,,,,,,,,
13.26387527,6,,,,,,,,,,,,,,,,,,,,,,
13.37249852,12,,,,,,,,,,,,,,,,,,,,,,
13.48112177,10,,,,,,,,,,,,,,,,,,,,,,
13.58974502,5,,,,,,,,,,,,,,,,,,,,,,
13.69836826,4,,,,,,,,,,,,,,,,,,,,,,
13.80699151,8,,,,,,,,,,,,,,,,,,,,,,
13.91561476,6,,,,,,,,,,,,,,,,,,,,,,
14.02423801,12,,,,,,,,,,,,,,,,,,,,,,
14.13286126,5,,,,,,,,,,,,,,,,,,,,,,
14.24148451,8,,,,,,,,,,,,,,,,,,,,,,
14.35010775,4,,,,,,,,,,,,,,,,,,,,,,
14.458731,9,,,,,,,,,,,,,,,,,,,,,,
14.56735425,13,,,,,,,,,,,,,,,,,,,,,,
14.6759775,9,,,,,,,,,,,,,,,,,,,,,,
14.78460075,8,,,,,,,,,,,,,,,,,,,,,,
14.893224,9,,,,,,,,,,,,,,,,,,,,,,
15.00184724,8,,,,,,,,,,,,,,,,,,,,,,
15.11047049,8,,,,,,,,,,,,,,,,,,,,,,
15.21909374,9,,,,,,,,,,,,,,,,,,,,,,
15.32771699,4,,,,,,,,,,,,,,,,,,,,,,
15.43634024,5,,,,,,,,,,,,,,,,,,,,,,
15.54496349,8,,,,,,,,,,,,,,,,,,,,,,
15.65358673,6,,,,,,,,,,,,,,,,,,,,,,
15.76220998,8,,,,,,,,,,,,,,,,,,,,,,
15.87083323,9,,,,,,,,,,,,,,,,,,,,,,
15.97945648,6,,,,,,,,,,,,,,,,,,,,,,
16.08807973,5,,,,,,,,,,,,,,,,,,,,,,
16.19670298,1,,,,,,,,,,,,,,,,,,,,,,
16.30532622,4,,,,,,,,,,,,,,,,,,,,,,
16.41394947,10,,,,,,,,,,,,,,,,,,,,,,
16.52257272,4,,,,,,,,,,,,,,,,,,,,,,
16.63119597,5,,,,,,,,,,,,,,,,,,,,,,
16.73981922,6,,,,,,,,,,,,,,,,,,,,,,
16.84844247,1,,,,,,,,,,,,,,,,,,,,,,
16.95706571,5,,,,,,,,,,,,,,,,,,,,,,
17.06568896,5,,,,,,,,,,,,,,,,,,,,,,
17.17431221,2,,,,,,,,,,,,,,,,,,,,,,
17.28293546,4,,,,,,,,,,,,,,,,,,,,,,
17.39155871,5,,,,,,,,,,,,,,,,,,,,,,
17.50018196,4,,,,,,,,,,,,,,,,,,,,,,
17.60880521,6,,,,,,,,,,,,,,,,,,,,,,
17.71742845,5,,,,,,,,,,,,,,,,,,,,,,
17.8260517,6,,,,,,,,,,,,,,,,,,,,,,
17.93467495,9,,,,,,,,,,,,,,,,,,,,,,
18.0432982,8,,,,,,,,,,,,,,,,,,,,,,
18.15192145,6,,,,,,,,,,,,,,,,,,,,,,
18.2605447,6,,,,,,,,,,,,,,,,,,,,,,
18.36916794,6,,,,,,,,,,,,,,,,,,,,,,
18.47779119,6,,,,,,,,,,,,,,,,,,,,,,
18.58641444,5,,,,,,,,,,,,,,,,,,,,,,
18.69503769,10,,,,,,,,,,,,,,,,,,,,,,
18.80366094,8,,,,,,,,,,,,,,,,,,,,,,
18.91228419,6,,,,,,,,,,,,,,,,,,,,,,
19.02090743,5,,,,,,,,,,,,,,,,,,,,,,
19.12953068,10,,,,,,,,,,,,,,,,,,,,,,
19.23815393,17,,,,,,,,,,,,,,,,,,,,,,
19.34677718,5,,,,,,,,,,,,,,,,,,,,,,
19.45540043,6,,,,,,,,,,,,,,,,,,,,,,
19.56402368,4,,,,,,,,,,,,,,,,,,,,,,
19.67264692,5,,,,,,,,,,,,,,,,,,,,,,
19.78127017,4,,,,,,,,,,,,,,,,,,,,,,
19.88989342,8,,,,,,,,,,,,,,,,,,,,,,
19.99851667,6,,,,,,,,,,,,,,,,,,,,,,
20.10713992,2,,,,,,,,,,,,,,,,,,,,,,
20.21576317,10,,,,,,,,,,,,,,,,,,,,,,
20.32438641,4,,,,,,,,,,,,,,,,,,,,,,
20.43300966,2,,,,,,,,,,,,,,,,,,,,,,
20.54163291,4,,,,,,,,,,,,,,,,,,,,,,
20.65025616,4,,,,,,,,,,,,,,,,,,,,,,
20.75887941,8,,,,,,,,,,,,,,,,,,,,,,
20.86750266,2,,,,,,,,,,,,,,,,,,,,,,
20.9761259,9,,,,,,,,,,,,,,,,,,,,,,
21.08474915,4,,,,,,,,,,,,,,,,,,,,,,
21.1933724,6,,,,,,,,,,,,,,,,,,,,,,
21.30199565,8,,,,,,,,,,,,,,,,,,,,,,
21.4106189,5,,,,,,,,,,,,,,,,,,,,,,
21.51924215,2,,,,,,,,,,,,,,,,,,,,,,
21.62786539,9,,,,,,,,,,,,,,,,,,,,,,
21.73648864,10,,,,,,,,,,,,,,,,,,,,,,
21.84511189,5,,,,,,,,,,,,,,,,,,,,,,
21.95373514,9,,,,,,,,,,,,,,,,,,,,,,
22.06235839,8,,,,,,,,,,,,,,,,,,,,,,
22.17098164,4,,,,,,,,,,,,,,,,,,,,,,
22.27960488,1,,,,,,,,,,,,,,,,,,,,,,
22.38822813,4,,,,,,,,,,,,,,,,,,,,,,
22.49685138,5,,,,,,,,,,,,,,,,,,,,,,
22.60547463,5,,,,,,,,,,,,,,,,,,,,,,
22.71409788,4,,,,,,,,,,,,,,,,,,,,,,
22.82272113,2,,,,,,,,,,,,,,,,,,,,,,
22.93134437,8,,,,,,,,,,,,,,,,,,,,,,
23.03996762,4,,,,,,,,,,,,,,,,,,,,,,
23.14859087,2,,,,,,,,,,,,,,,,,,,,,,
23.25721412,1,,,,,,,,,,,,,,,,,,,,,,
23.36583737,8,,,,,,,,,,,,,,,,,,,,,,
23.47446062,2,,,,,,,,,,,,,,,,,,,,,,
23.58308386,4,,,,,,,,,,,,,,,,,,,,,,
23.69170711,6,,,,,,,,,,,,,,,,,,,,,,
23.80033036,4,,,,,,,,,,,,,,,,,,,,,,
23.90895361,5,,,,,,,,,,,,,,,,,,,,,,
24.01757686,1,,,,,,,,,,,,,,,,,,,,,,
24.12620011,2,,,,,,,,,,,,,,,,,,,,,,
24.23482335,6,,,,,,,,,,,,,,,,,,,,,,
24.3434466,2,,,,,,,,,,,,,,,,,,,,,,
24.45206985,4,,,,,,,,,,,,,,,,,,,,,,
24.5606931,10,,,,,,,,,,,,,,,,,,,,,,
24.66931635,4,,,,,,,,,,,,,,,,,,,,,,
24.7779396,5,,,,,,,,,,,,,,,,,,,,,,
24.88656284,4,,,,,,,,,,,,,,,,,,,,,,
24.99518609,1,,,,,,,,,,,,,,,,,,,,,,
25.10380934,5,,,,,,,,,,,,,,,,,,,,,,
25.21243259,5,,,,,,,,,,,,,,,,,,,,,,
25.32105584,4,,,,,,,,,,,,,,,,,,,,,,
25.42967909,2,,,,,,,,,,,,,,,,,,,,,,
25.53830233,2,,,,,,,,,,,,,,,,,,,,,,
25.64692558,4,,,,,,,,,,,,,,,,,,,,,,
25.75554883,5,,,,,,,,,,,,,,,,,,,,,,
25.86417208,4,,,,,,,,,,,,,,,,,,,,,,
25.97279533,4,,,,,,,,,,,,,,,,,,,,,,
26.08141858,2,,,,,,,,,,,,,,,,,,,,,,
26.19004182,0,,,,,,,,,,,,,,,,,,,,,,
26.29866507,2,,,,,,,,,,,,,,,,,,,,,,
26.40728832,6,,,,,,,,,,,,,,,,,,,,,,
26.51591157,9,,,,,,,,,,,,,,,,,,,,,,
26.62453482,4,,,,,,,,,,,,,,,,,,,,,,
26.73315807,4,,,,,,,,,,,,,,,,,,,,,,
26.84178131,5,,,,,,,,,,,,,,,,,,,,,,
26.95040456,2,,,,,,,,,,,,,,,,,,,,,,
27.05902781,2,,,,,,,,,,,,,,,,,,,,,,
27.16765106,4,,,,,,,,,,,,,,,,,,,,,,
27.27627431,5,,,,,,,,,,,,,,,,,,,,,,
27.38489756,4,,,,,,,,,,,,,,,,,,,,,,
27.4935208,9,,,,,,,,,,,,,,,,,,,,,,
27.60214405,4,,,,,,,,,,,,,,,,,,,,,,
27.7107673,8,,,,,,,,,,,,,,,,,,,,,,
27.81939055,5,,,,,,,,,,,,,,,,,,,,,,
27.9280138,4,,,,,,,,,,,,,,,,,,,,,,
28.03663705,6,,,,,,,,,,,,,,,,,,,,,,
28.14526029,10,,,,,,,,,,,,,,,,,,,,,,
28.25388354,56,,,,,,,,,,,,,,,,,,,,,,
28.36250679,151,,,,,,,,,,,,,,,,,,,,,,
28.47113004,746,,,,,,,,,,,,,,,,,,,,,,
28.57975329,953,,,,,,,,,,,,,,,,,,,,,,
28.68837654,60,,,,,,,,,,,,,,,,,,,,,,
28.79699979,9,,,,,,,,,,,,,,,,,,,,,,
28.90562303,20,,,,,,,,,,,,,,,,,,,,,,
29.01424628,6,,,,,,,,,,,,,,,,,,,,,,
29.12286953,12,,,,,,,,,,,,,,,,,,,,,,
29.23149278,10,,,,,,,,,,,,,,,,,,,,,,
29.34011603,8,,,,,,,,,,,,,,,,,,,,,,
29.44873928,13,,,,,,,,,,,,,,,,,,,,,,
29.55736252,14,,,,,,,,,,,,,,,,,,,,,,
29.66598577,1,,,,,,,,,,,,,,,,,,,,,,
29.77460902,2,,,,,,,,,,,,,,,,,,,,,,
29.88323227,5,,,,,,,,,,,,,,,,,,,,,,
29.99185552,2,,,,,,,,,,,,,,,,,,,,,,
30.10047877,4,,,,,,,,,,,,,,,,,,,,,,
30.20910201,2,,,,,,,,,,,,,,,,,,,,,,
30.31772526,4,,,,,,,,,,,,,,,,,,,,,,
30.42634851,4,,,,,,,,,,,,,,,,,,,,,,
30.53497176,2,,,,,,,,,,,,,,,,,,,,,,
30.64359501,1,,,,,,,,,,,,,,,,,,,,,,
30.75221826,4,,,,,,,,,,,,,,,,,,,,,,
30.8608415,1,,,,,,,,,,,,,,,,,,,,,,
30.96946475,0,,,,,,,,,,,,,,,,,,,,,,
31.078088,4,,,,,,,,,,,,,,,,,,,,,,
31.18671125,1,,,,,,,,,,,,,,,,,,,,,,
31.2953345,1,,,,,,,,,,,,,,,,,,,,,,
31.40395775,4,,,,,,,,,,,,,,,,,,,,,,
31.51258099,1,,,,,,,,,,,,,,,,,,,,,,
31.62120424,5,,,,,,,,,,,,,,,,,,,,,,
31.72982749,4,,,,,,,,,,,,,,,,,,,,,,
31.83845074,4,,,,,,,,,,,,,,,,,,,,,,
31.94707399,4,,,,,,,,,,,,,,,,,,,,,,
32.05569724,5,,,,,,,,,,,,,,,,,,,,,,
32.16432048,5,,,,,,,,,,,,,,,,,,,,,,
32.27294373,6,,,,,,,,,,,,,,,,,,,,,,
32.38156698,1,,,,,,,,,,,,,,,,,,,,,,
32.49019023,2,,,,,,,,,,,,,,,,,,,,,,
32.59881348,1,,,,,,,,,,,,,,,,,,,,,,
32.70743673,6,,,,,,,,,,,,,,,,,,,,,,
32.81605997,4,,,,,,,,,,,,,,,,,,,,,,
32.92468322,5,,,,,,,,,,,,,,,,,,,,,,
33.03330647,1,,,,,,,,,,,,,,,,,,,,,,
33.14192972,2,,,,,,,,,,,,,,,,,,,,,,
33.25055297,5,,,,,,,,,,,,,,,,,,,,,,
33.35917622,4,,,,,,,,,,,,,,,,,,,,,,
33.46779946,1,,,,,,,,,,,,,,,,,,,,,,
33.57642271,0,,,,,,,,,,,,,,,,,,,,,,
33.68504596,1,,,,,,,,,,,,,,,,,,,,,,
33.79366921,1,,,,,,,,,,,,,,,,,,,,,,
33.90229246,0,,,,,,,,,,,,,,,,,,,,,,
34.01091571,4,,,,,,,,,,,,,,,,,,,,,,
34.11953895,1,,,,,,,,,,,,,,,,,,,,,,
34.2281622,8,,,,,,,,,,,,,,,,,,,,,,
34.33678545,2,,,,,,,,,,,,,,,,,,,,,,
34.4454087,1,,,,,,,,,,,,,,,,,,,,,,
34.55403195,2,,,,,,,,,,,,,,,,,,,,,,
34.6626552,1,,,,,,,,,,,,,,,,,,,,,,
34.77127844,4,,,,,,,,,,,,,,,,,,,,,,
34.87990169,1,,,,,,,,,,,,,,,,,,,,,,
34.98852494,2,,,,,,,,,,,,,,,,,,,,,,
35.09714819,2,,,,,,,,,,,,,,,,,,,,,,
35.20577144,0,,,,,,,,,,,,,,,,,,,,,,
35.31439469,1,,,,,,,,,,,,,,,,,,,,,,
35.42301793,4,,,,,,,,,,,,,,,,,,,,,,
35.53164118,2,,,,,,,,,,,,,,,,,,,,,,
35.64026443,8,,,,,,,,,,,,,,,,,,,,,,
35.74888768,1,,,,,,,,,,,,,,,,,,,,,,
35.85751093,4,,,,,,,,,,,,,,,,,,,,,,
35.96613418,1,,,,,,,,,,,,,,,,,,,,,,
36.07475742,1,,,,,,,,,,,,,,,,,,,,,,
36.18338067,2,,,,,,,,,,,,,,,,,,,,,,
36.29200392,1,,,,,,,,,,,,,,,,,,,,,,
36.40062717,2,,,,,,,,,,,,,,,,,,,,,,
36.50925042,0,,,,,,,,,,,,,,,,,,,,,,
36.61787367,0,,,,,,,,,,,,,,,,,,,,,,
36.72649691,2,,,,,,,,,,,,,,,,,,,,,,
36.83512016,5,,,,,,,,,,,,,,,,,,,,,,
36.94374341,1,,,,,,,,,,,,,,,,,,,,,,
37.05236666,2,,,,,,,,,,,,,,,,,,,,,,
37.16098991,6,,,,,,,,,,,,,,,,,,,,,,
37.26961316,4,,,,,,,,,,,,,,,,,,,,,,
37.3782364,0,,,,,,,,,,,,,,,,,,,,,,
37.48685965,5,,,,,,,,,,,,,,,,,,,,,,
37.5954829,4,,,,,,,,,,,,,,,,,,,,,,
37.70410615,4,,,,,,,,,,,,,,,,,,,,,,
37.8127294,5,,,,,,,,,,,,,,,,,,,,,,
37.92135265,5,,,,,,,,,,,,,,,,,,,,,,
38.02997589,1,,,,,,,,,,,,,,,,,,,,,,
38.13859914,6,,,,,,,,,,,,,,,,,,,,,,
38.24722239,25,,,,,,,,,,,,,,,,,,,,,,
38.35584564,57,,,,,,,,,,,,,,,,,,,,,,
38.46446889,32,,,,,,,,,,,,,,,,,,,,,,
38.57309214,4,,,,,,,,,,,,,,,,,,,,,,
38.68171538,10,,,,,,,,,,,,,,,,,,,,,,
38.79033863,0,,,,,,,,,,,,,,,,,,,,,,
38.89896188,4,,,,,,,,,,,,,,,,,,,,,,
39.00758513,6,,,,,,,,,,,,,,,,,,,,,,
39.11620838,5,,,,,,,,,,,,,,,,,,,,,,
39.22483163,0,,,,,,,,,,,,,,,,,,,,,,
39.33345488,5,,,,,,,,,,,,,,,,,,,,,,
39.44207812,5,,,,,,,,,,,,,,,,,,,,,,
39.55070137,1,,,,,,,,,,,,,,,,,,,,,,
39.65932462,2,,,,,,,,,,,,,,,,,,,,,,
39.76794787,6,,,,,,,,,,,,,,,,,,,,,,
39.87657112,5,,,,,,,,,,,,,,,,,,,,,,
39.98519437,4,,,,,,,,,,,,,,,,,,,,,,
40.09381761,1,,,,,,,,,,,,,,,,,,,,,,
40.20244086,2,,,,,,,,,,,,,,,,,,,,,,
40.31106411,1,,,,,,,,,,,,,,,,,,,,,,
40.41968736,8,,,,,,,,,,,,,,,,,,,,,,
40.52831061,4,,,,,,,,,,,,,,,,,,,,,,
40.63693386,0,,,,,,,,,,,,,,,,,,,,,,
40.7455571,5,,,,,,,,,,,,,,,,,,,,,,
40.85418035,4,,,,,,,,,,,,,,,,,,,,,,
40.9628036,5,,,,,,,,,,,,,,,,,,,,,,
41.07142685,2,,,,,,,,,,,,,,,,,,,,,,
41.1800501,4,,,,,,,,,,,,,,,,,,,,,,
41.28867335,4,,,,,,,,,,,,,,,,,,,,,,
41.39729659,4,,,,,,,,,,,,,,,,,,,,,,
41.50591984,2,,,,,,,,,,,,,,,,,,,,,,
41.61454309,5,,,,,,,,,,,,,,,,,,,,,,
41.72316634,2,,,,,,,,,,,,,,,,,,,,,,
41.83178959,2,,,,,,,,,,,,,,,,,,,,,,
41.94041284,8,,,,,,,,,,,,,,,,,,,,,,
42.04903608,1,,,,,,,,,,,,,,,,,,,,,,
42.15765933,2,,,,,,,,,,,,,,,,,,,,,,
42.26628258,4,,,,,,,,,,,,,,,,,,,,,,
42.37490583,1,,,,,,,,,,,,,,,,,,,,,,
42.48352908,1,,,,,,,,,,,,,,,,,,,,,,
42.59215233,5,,,,,,,,,,,,,,,,,,,,,,
42.70077557,4,,,,,,,,,,,,,,,,,,,,,,
42.80939882,5,,,,,,,,,,,,,,,,,,,,,,
42.91802207,6,,,,,,,,,,,,,,,,,,,,,,
43.02664532,8,,,,,,,,,,,,,,,,,,,,,,
43.13526857,2,,,,,,,,,,,,,,,,,,,,,,
43.24389182,4,,,,,,,,,,,,,,,,,,,,,,
43.35251506,2,,,,,,,,,,,,,,,,,,,,,,
43.46113831,5,,,,,,,,,,,,,,,,,,,,,,
43.56976156,4,,,,,,,,,,,,,,,,,,,,,,
43.67838481,1,,,,,,,,,,,,,,,,,,,,,,
43.78700806,2,,,,,,,,,,,,,,,,,,,,,,
43.89563131,5,,,,,,,,,,,,,,,,,,,,,,
44.00425455,2,,,,,,,,,,,,,,,,,,,,,,
44.1128778,4,,,,,,,,,,,,,,,,,,,,,,
44.22150105,10,,,,,,,,,,,,,,,,,,,,,,
44.3301243,4,,,,,,,,,,,,,,,,,,,,,,
44.43874755,14,,,,,,,,,,,,,,,,,,,,,,
44.5473708,68,,,,,,,,,,,,,,,,,,,,,,
44.65599404,101,,,,,,,,,,,,,,,,,,,,,,
44.76461729,54,,,,,,,,,,,,,,,,,,,,,,
44.87324054,10,,,,,,,,,,,,,,,,,,,,,,
44.98186379,4,,,,,,,,,,,,,,,,,,,,,,
45.09048704,5,,,,,,,,,,,,,,,,,,,,,,
45.19911029,1,,,,,,,,,,,,,,,,,,,,,,
45.30773353,1,,,,,,,,,,,,,,,,,,,,,,
45.41635678,2,,,,,,,,,,,,,,,,,,,,,,
45.52498003,0,,,,,,,,,,,,,,,,,,,,,,
45.63360328,6,,,,,,,,,,,,,,,,,,,,,,
45.74222653,6,,,,,,,,,,,,,,,,,,,,,,
45.85084978,5,,,,,,,,,,,,,,,,,,,,,,
45.95947302,4,,,,,,,,,,,,,,,,,,,,,,
46.06809627,5,,,,,,,,,,,,,,,,,,,,,,
46.17671952,5,,,,,,,,,,,,,,,,,,,,,,
46.28534277,2,,,,,,,,,,,,,,,,,,,,,,
46.39396602,1,,,,,,,,,,,,,,,,,,,,,,
46.50258927,9,,,,,,,,,,,,,,,,,,,,,,
46.61121251,6,,,,,,,,,,,,,,,,,,,,,,
46.71983576,4,,,,,,,,,,,,,,,,,,,,,,
46.82845901,6,,,,,,,,,,,,,,,,,,,,,,
46.93708226,6,,,,,,,,,,,,,,,,,,,,,,
47.04570551,8,,,,,,,,,,,,,,,,,,,,,,
47.15432876,44,,,,,,,,,,,,,,,,,,,,,,
47.262952,260,,,,,,,,,,,,,,,,,,,,,,
47.37157525,1263,,,,,,,,,,,,,,,,,,,,,,
47.4801985,811,,,,,,,,,,,,,,,,,,,,,,
47.58882175,34,,,,,,,,,,,,,,,,,,,,,,
47.697445,17,,,,,,,,,,,,,,,,,,,,,,
47.80606825,9,,,,,,,,,,,,,,,,,,,,,,
47.91469149,14,,,,,,,,,,,,,,,,,,,,,,
48.02331474,10,,,,,,,,,,,,,,,,,,,,,,
48.13193799,2,,,,,,,,,,,,,,,,,,,,,,
48.24056124,4,,,,,,,,,,,,,,,,,,,,,,
48.34918449,6,,,,,,,,,,,,,,,,,,,,,,
48.45780774,8,,,,,,,,,,,,,,,,,,,,,,
48.56643098,2,,,,,,,,,,,,,,,,,,,,,,
48.67505423,5,,,,,,,,,,,,,,,,,,,,,,
48.78367748,2,,,,,,,,,,,,,,,,,,,,,,
48.89230073,2,,,,,,,,,,,,,,,,,,,,,,
49.00092398,0,,,,,,,,,,,,,,,,,,,,,,
49.10954723,2,,,,,,,,,,,,,,,,,,,,,,
49.21817047,5,,,,,,,,,,,,,,,,,,,,,,
49.32679372,2,,,,,,,,,,,,,,,,,,,,,,
49.43541697,2,,,,,,,,,,,,,,,,,,,,,,
49.54404022,5,,,,,,,,,,,,,,,,,,,,,,
49.65266347,1,,,,,,,,,,,,,,,,,,,,,,
49.76128672,5,,,,,,,,,,,,,,,,,,,,,,
49.86990997,2,,,,,,,,,,,,,,,,,,,,,,
49.97853321,4,,,,,,,,,,,,,,,,,,,,,,
50.08715646,2,,,,,,,,,,,,,,,,,,,,,,
50.19577971,2,,,,,,,,,,,,,,,,,,,,,,
50.30440296,0,,,,,,,,,,,,,,,,,,,,,,
50.41302621,4,,,,,,,,,,,,,,,,,,,,,,
50.52164946,5,,,,,,,,,,,,,,,,,,,,,,
50.6302727,4,,,,,,,,,,,,,,,,,,,,,,
50.73889595,0,,,,,,,,,,,,,,,,,,,,,,
50.8475192,0,,,,,,,,,,,,,,,,,,,,,,
50.95614245,2,,,,,,,,,,,,,,,,,,,,,,
51.0647657,4,,,,,,,,,,,,,,,,,,,,,,
51.17338895,2,,,,,,,,,,,,,,,,,,,,,,
51.28201219,6,,,,,,,,,,,,,,,,,,,,,,
51.39063544,2,,,,,,,,,,,,,,,,,,,,,,
51.49925869,1,,,,,,,,,,,,,,,,,,,,,,
51.60788194,0,,,,,,,,,,,,,,,,,,,,,,
51.71650519,2,,,,,,,,,,,,,,,,,,,,,,
51.82512844,4,,,,,,,,,,,,,,,,,,,,,,
51.93375168,1,,,,,,,,,,,,,,,,,,,,,,
52.04237493,4,,,,,,,,,,,,,,,,,,,,,,
52.15099818,1,,,,,,,,,,,,,,,,,,,,,,
52.25962143,4,,,,,,,,,,,,,,,,,,,,,,
52.36824468,1,,,,,,,,,,,,,,,,,,,,,,
52.47686793,6,,,,,,,,,,,,,,,,,,,,,,
52.58549117,1,,,,,,,,,,,,,,,,,,,,,,
52.69411442,4,,,,,,,,,,,,,,,,,,,,,,
52.80273767,1,,,,,,,,,,,,,,,,,,,,,,
52.91136092,1,,,,,,,,,,,,,,,,,,,,,,
53.01998417,0,,,,,,,,,,,,,,,,,,,,,,
53.12860742,2,,,,,,,,,,,,,,,,,,,,,,
53.23723066,2,,,,,,,,,,,,,,,,,,,,,,
53.34585391,2,,,,,,,,,,,,,,,,,,,,,,
53.45447716,2,,,,,,,,,,,,,,,,,,,,,,
53.56310041,2,,,,,,,,,,,,,,,,,,,,,,
53.67172366,1,,,,,,,,,,,,,,,,,,,,,,
53.78034691,1,,,,,,,,,,,,,,,,,,,,,,
53.88897015,2,,,,,,,,,,,,,,,,,,,,,,
53.9975934,4,,,,,,,,,,,,,,,,,,,,,,
54.10621665,2,,,,,,,,,,,,,,,,,,,,,,
54.2148399,4,,,,,,,,,,,,,,,,,,,,,,
54.32346315,4,,,,,,,,,,,,,,,,,,,,,,
54.4320864,5,,,,,,,,,,,,,,,,,,,,,,
54.54070964,4,,,,,,,,,,,,,,,,,,,,,,
54.64933289,4,,,,,,,,,,,,,,,,,,,,,,
54.75795614,5,,,,,,,,,,,,,,,,,,,,,,
54.86657939,1,,,,,,,,,,,,,,,,,,,,,,
54.97520264,6,,,,,,,,,,,,,,,,,,,,,,
55.08382589,1,,,,,,,,,,,,,,,,,,,,,,
55.19244913,1,,,,,,,,,,,,,,,,,,,,,,
55.30107238,5,,,,,,,,,,,,,,,,,,,,,,
55.40969563,2,,,,,,,,,,,,,,,,,,,,,,
55.51831888,5,,,,,,,,,,,,,,,,,,,,,,
55.62694213,9,,,,,,,,,,,,,,,,,,,,,,
55.73556538,6,,,,,,,,,,,,,,,,,,,,,,
55.84418862,6,,,,,,,,,,,,,,,,,,,,,,
55.95281187,12,,,,,,,,,,,,,,,,,,,,,,
56.06143512,57,,,,,,,,,,,,,,,,,,,,,,
56.17005837,501,,,,,,,,,,,,,,,,,,,,,,
56.27868162,171,,,,,,,,,,,,,,,,,,,,,,
56.38730487,60,,,,,,,,,,,,,,,,,,,,,,
56.49592811,10,,,,,,,,,,,,,,,,,,,,,,
56.60455136,10,,,,,,,,,,,,,,,,,,,,,,
56.71317461,4,,,,,,,,,,,,,,,,,,,,,,
56.82179786,4,,,,,,,,,,,,,,,,,,,,,,
56.93042111,1,,,,,,,,,,,,,,,,,,,,,,
57.03904436,4,,,,,,,,,,,,,,,,,,,,,,
57.1476676,2,,,,,,,,,,,,,,,,,,,,,,
57.25629085,2,,,,,,,,,,,,,,,,,,,,,,
57.3649141,2,,,,,,,,,,,,,,,,,,,,,,
57.47353735,4,,,,,,,,,,,,,,,,,,,,,,
57.5821606,1,,,,,,,,,,,,,,,,,,,,,,
57.69078385,1,,,,,,,,,,,,,,,,,,,,,,
57.79940709,4,,,,,,,,,,,,,,,,,,,,,,
57.90803034,2,,,,,,,,,,,,,,,,,,,,,,
58.01665359,2,,,,,,,,,,,,,,,,,,,,,,
58.12527684,1,,,,,,,,,,,,,,,,,,,,,,
58.23390009,6,,,,,,,,,,,,,,,,,,,,,,
58.34252334,2,,,,,,,,,,,,,,,,,,,,,,
58.45114658,1,,,,,,,,,,,,,,,,,,,,,,
58.55976983,2,,,,,,,,,,,,,,,,,,,,,,
58.66839308,1,,,,,,,,,,,,,,,,,,,,,,
58.77701633,0,,,,,,,,,,,,,,,,,,,,,,
58.88563958,4,,,,,,,,,,,,,,,,,,,,,,
58.99426283,2,,,,,,,,,,,,,,,,,,,,,,
59.10288607,2,,,,,,,,,,,,,,,,,,,,,,
59.21150932,1,,,,,,,,,,,,,,,,,,,,,,
59.32013257,1,,,,,,,,,,,,,,,,,,,,,,
59.42875582,2,,,,,,,,,,,,,,,,,,,,,,
59.53737907,5,,,,,,,,,,,,,,,,,,,,,,
59.64600232,4,,,,,,,,,,,,,,,,,,,,,,
59.75462556,2,,,,,,,,,,,,,,,,,,,,,,
59.86324881,4,,,,,,,,,,,,,,,,,,,,,,
59.97187206,0,,,,,,,,,,,,,,,,,,,,,,
60.08049531,2,,,,,,,,,,,,,,,,,,,,,,
60.18911856,0,,,,,,,,,,,,,,,,,,,,,,
60.29774181,2,,,,,,,,,,,,,,,,,,,,,,
60.40636506,1,,,,,,,,,,,,,,,,,,,,,,
60.5149883,2,,,,,,,,,,,,,,,,,,,,,,
60.62361155,0,,,,,,,,,,,,,,,,,,,,,,
60.7322348,1,,,,,,,,,,,,,,,,,,,,,,
60.84085805,1,,,,,,,,,,,,,,,,,,,,,,
60.9494813,1,,,,,,,,,,,,,,,,,,,,,,
61.05810455,4,,,,,,,,,,,,,,,,,,,,,,
61.16672779,4,,,,,,,,,,,,,,,,,,,,,,
61.27535104,4,,,,,,,,,,,,,,,,,,,,,,
61.38397429,1,,,,,,,,,,,,,,,,,,,,,,
61.49259754,6,,,,,,,,,,,,,,,,,,,,,,
61.60122079,2,,,,,,,,,,,,,,,,,,,,,,
61.70984404,2,,,,,,,,,,,,,,,,,,,,,,
61.81846728,0,,,,,,,,,,,,,,,,,,,,,,
61.92709053,4,,,,,,,,,,,,,,,,,,,,,,
62.03571378,4,,,,,,,,,,,,,,,,,,,,,,
62.14433703,1,,,,,,,,,,,,,,,,,,,,,,
62.25296028,1,,,,,,,,,,,,,,,,,,,,,,
62.36158353,1,,,,,,,,,,,,,,,,,,,,,,
62.47020677,0,,,,,,,,,,,,,,,,,,,,,,
62.57883002,1,,,,,,,,,,,,,,,,,,,,,,
62.68745327,5,,,,,,,,,,,,,,,,,,,,,,
62.79607652,4,,,,,,,,,,,,,,,,,,,,,,
62.90469977,4,,,,,,,,,,,,,,,,,,,,,,
63.01332302,2,,,,,,,,,,,,,,,,,,,,,,
63.12194626,2,,,,,,,,,,,,,,,,,,,,,,
63.23056951,0,,,,,,,,,,,,,,,,,,,,,,
63.33919276,1,,,,,,,,,,,,,,,,,,,,,,
63.44781601,5,,,,,,,,,,,,,,,,,,,,,,
63.55643926,6,,,,,,,,,,,,,,,,,,,,,,
63.66506251,2,,,,,,,,,,,,,,,,,,,,,,
63.77368575,1,,,,,,,,,,,,,,,,,,,,,,
63.882309,2,,,,,,,,,,,,,,,,,,,,,,
63.99093225,1,,,,,,,,,,,,,,,,,,,,,,
64.0995555,9,,,,,,,,,,,,,,,,,,,,,,
64.20817875,4,,,,,,,,,,,,,,,,,,,,,,
64.316802,1,,,,,,,,,,,,,,,,,,,,,,
64.42542524,4,,,,,,,,,,,,,,,,,,,,,,
64.53404849,4,,,,,,,,,,,,,,,,,,,,,,
64.64267174,1,,,,,,,,,,,,,,,,,,,,,,
64.75129499,8,,,,,,,,,,,,,,,,,,,,,,
64.85991824,16,,,,,,,,,,,,,,,,,,,,,,
64.96854149,70,,,,,,,,,,,,,,,,,,,,,,
65.07716473,41,,,,,,,,,,,,,,,,,,,,,,
65.18578798,18,,,,,,,,,,,,,,,,,,,,,,
65.29441123,4,,,,,,,,,,,,,,,,,,,,,,
65.40303448,2,,,,,,,,,,,,,,,,,,,,,,
65.51165773,4,,,,,,,,,,,,,,,,,,,,,,
65.62028098,1,,,,,,,,,,,,,,,,,,,,,,
65.72890422,4,,,,,,,,,,,,,,,,,,,,,,
65.83752747,1,,,,,,,,,,,,,,,,,,,,,,
65.94615072,0,,,,,,,,,,,,,,,,,,,,,,
66.05477397,2,,,,,,,,,,,,,,,,,,,,,,
66.16339722,4,,,,,,,,,,,,,,,,,,,,,,
66.27202047,1,,,,,,,,,,,,,,,,,,,,,,
66.38064371,4,,,,,,,,,,,,,,,,,,,,,,
66.48926696,1,,,,,,,,,,,,,,,,,,,,,,
66.59789021,0,,,,,,,,,,,,,,,,,,,,,,
66.70651346,0,,,,,,,,,,,,,,,,,,,,,,
66.81513671,0,,,,,,,,,,,,,,,,,,,,,,
66.92375996,2,,,,,,,,,,,,,,,,,,,,,,
67.0323832,2,,,,,,,,,,,,,,,,,,,,,,
67.14100645,1,,,,,,,,,,,,,,,,,,,,,,
67.2496297,0,,,,,,,,,,,,,,,,,,,,,,
67.35825295,2,,,,,,,,,,,,,,,,,,,,,,
67.4668762,6,,,,,,,,,,,,,,,,,,,,,,
67.57549945,4,,,,,,,,,,,,,,,,,,,,,,
67.68412269,1,,,,,,,,,,,,,,,,,,,,,,
67.79274594,4,,,,,,,,,,,,,,,,,,,,,,
67.90136919,5,,,,,,,,,,,,,,,,,,,,,,
68.00999244,1,,,,,,,,,,,,,,,,,,,,,,
68.11861569,0,,,,,,,,,,,,,,,,,,,,,,
68.22723894,0,,,,,,,,,,,,,,,,,,,,,,
68.33586218,2,,,,,,,,,,,,,,,,,,,,,,
68.44448543,1,,,,,,,,,,,,,,,,,,,,,,
68.55310868,2,,,,,,,,,,,,,,,,,,,,,,
68.66173193,4,,,,,,,,,,,,,,,,,,,,,,
68.77035518,6,,,,,,,,,,,,,,,,,,,,,,
68.87897843,4,,,,,,,,,,,,,,,,,,,,,,
68.98760167,9,,,,,,,,,,,,,,,,,,,,,,
69.09622492,56,,,,,,,,,,,,,,,,,,,,,,
69.20484817,65,,,,,,,,,,,,,,,,,,,,,,
69.31347142,61,,,,,,,,,,,,,,,,,,,,,,
69.42209467,22,,,,,,,,,,,,,,,,,,,,,,
69.53071792,5,,,,,,,,,,,,,,,,,,,,,,
69.63934116,5,,,,,,,,,,,,,,,,,,,,,,
69.74796441,5,,,,,,,,,,,,,,,,,,,,,,
69.85658766,0,,,,,,,,,,,,,,,,,,,,,,
69.96521091,4,,,,,,,,,,,,,,,,,,,,,,
70.07383416,0,,,,,,,,,,,,,,,,,,,,,,
70.18245741,4,,,,,,,,,,,,,,,,,,,,,,
70.29108065,4,,,,,,,,,,,,,,,,,,,,,,
70.3997039,0,,,,,,,,,,,,,,,,,,,,,,
70.50832715,0,,,,,,,,,,,,,,,,,,,,,,
70.6169504,1,,,,,,,,,,,,,,,,,,,,,,
70.72557365,4,,,,,,,,,,,,,,,,,,,,,,
70.8341969,4,,,,,,,,,,,,,,,,,,,,,,
70.94282014,2,,,,,,,,,,,,,,,,,,,,,,
71.05144339,6,,,,,,,,,,,,,,,,,,,,,,
71.16006664,2,,,,,,,,,,,,,,,,,,,,,,
71.26868989,1,,,,,,,,,,,,,,,,,,,,,,
71.37731314,5,,,,,,,,,,,,,,,,,,,,,,
71.48593639,1,,,,,,,,,,,,,,,,,,,,,,
71.59455964,0,,,,,,,,,,,,,,,,,,,,,,
71.70318288,2,,,,,,,,,,,,,,,,,,,,,,
71.81180613,1,,,,,,,,,,,,,,,,,,,,,,
71.92042938,0,,,,,,,,,,,,,,,,,,,,,,
72.02905263,2,,,,,,,,,,,,,,,,,,,,,,
72.13767588,4,,,,,,,,,,,,,,,,,,,,,,
72.24629913,2,,,,,,,,,,,,,,,,,,,,,,
72.35492237,1,,,,,,,,,,,,,,,,,,,,,,
72.46354562,1,,,,,,,,,,,,,,,,,,,,,,
72.57216887,4,,,,,,,,,,,,,,,,,,,,,,
72.68079212,4,,,,,,,,,,,,,,,,,,,,,,
72.78941537,0,,,,,,,,,,,,,,,,,,,,,,
72.89803862,4,,,,,,,,,,,,,,,,,,,,,,
73.00666186,4,,,,,,,,,,,,,,,,,,,,,,
73.11528511,1,,,,,,,,,,,,,,,,,,,,,,
73.22390836,1,,,,,,,,,,,,,,,,,,,,,,
73.33253161,4,,,,,,,,,,,,,,,,,,,,,,
73.44115486,4,,,,,,,,,,,,,,,,,,,,,,
73.54977811,4,,,,,,,,,,,,,,,,,,,,,,
73.65840135,1,,,,,,,,,,,,,,,,,,,,,,
73.7670246,2,,,,,,,,,,,,,,,,,,,,,,
73.87564785,0,,,,,,,,,,,,,,,,,,,,,,
73.9842711,1,,,,,,,,,,,,,,,,,,,,,,
74.09289435,4,,,,,,,,,,,,,,,,,,,,,,
74.2015176,4,,,,,,,,,,,,,,,,,,,,,,
74.31014084,2,,,,,,,,,,,,,,,,,,,,,,
74.41876409,5,,,,,,,,,,,,,,,,,,,,,,
74.52738734,4,,,,,,,,,,,,,,,,,,,,,,
74.63601059,2,,,,,,,,,,,,,,,,,,,,,,
74.74463384,2,,,,,,,,,,,,,,,,,,,,,,
74.85325709,2,,,,,,,,,,,,,,,,,,,,,,
74.96188033,4,,,,,,,,,,,,,,,,,,,,,,
75.07050358,4,,,,,,,,,,,,,,,,,,,,,,
75.17912683,2,,,,,,,,,,,,,,,,,,,,,,
75.28775008,4,,,,,,,,,,,,,,,,,,,,,,
75.39637333,0,,,,,,,,,,,,,,,,,,,,,,
75.50499658,2,,,,,,,,,,,,,,,,,,,,,,
75.61361982,4,,,,,,,,,,,,,,,,,,,,,,
75.72224307,6,,,,,,,,,,,,,,,,,,,,,,
75.83086632,2,,,,,,,,,,,,,,,,,,,,,,
75.93948957,1,,,,,,,,,,,,,,,,,,,,,,
76.04811282,0,,,,,,,,,,,,,,,,,,,,,,
76.15673607,6,,,,,,,,,,,,,,,,,,,,,,
76.26535931,9,,,,,,,,,,,,,,,,,,,,,,
76.37398256,90,,,,,,,,,,,,,,,,,,,,,,
76.48260581,53,,,,,,,,,,,,,,,,,,,,,,
76.59122906,25,,,,,,,,,,,,,,,,,,,,,,
76.69985231,17,,,,,,,,,,,,,,,,,,,,,,
76.80847556,4,,,,,,,,,,,,,,,,,,,,,,
76.9170988,6,,,,,,,,,,,,,,,,,,,,,,
77.02572205,5,,,,,,,,,,,,,,,,,,,,,,
77.1343453,9,,,,,,,,,,,,,,,,,,,,,,
77.24296855,0,,,,,,,,,,,,,,,,,,,,,,
77.3515918,0,,,,,,,,,,,,,,,,,,,,,,
77.46021505,4,,,,,,,,,,,,,,,,,,,,,,
77.56883829,0,,,,,,,,,,,,,,,,,,,,,,
77.67746154,2,,,,,,,,,,,,,,,,,,,,,,
77.78608479,1,,,,,,,,,,,,,,,,,,,,,,
77.89470804,5,,,,,,,,,,,,,,,,,,,,,,
78.00333129,2,,,,,,,,,,,,,,,,,,,,,,
78.11195454,6,,,,,,,,,,,,,,,,,,,,,,
78.22057778,6,,,,,,,,,,,,,,,,,,,,,,
78.32920103,10,,,,,,,,,,,,,,,,,,,,,,
78.43782428,4,,,,,,,,,,,,,,,,,,,,,,
78.54644753,4,,,,,,,,,,,,,,,,,,,,,,
78.65507078,1,,,,,,,,,,,,,,,,,,,,,,
78.76369403,5,,,,,,,,,,,,,,,,,,,,,,
78.87231727,1,,,,,,,,,,,,,,,,,,,,,,
78.98094052,4,,,,,,,,,,,,,,,,,,,,,,
79.08956377,1,,,,,,,,,,,,,,,,,,,,,,
79.19818702,4,,,,,,,,,,,,,,,,,,,,,,
79.30681027,4,,,,,,,,,,,,,,,,,,,,,,
79.41543352,2,,,,,,,,,,,,,,,,,,,,,,
79.52405676,1,,,,,,,,,,,,,,,,,,,,,,
79.63268001,1,,,,,,,,,,,,,,,,,,,,,,
79.74130326,1,,,,,,,,,,,,,,,,,,,,,,
79.84992651,1,,,,,,,,,,,,,,,,,,,,,,
79.95854976,1,,,,,,,,,,,,,,,,,,,,,,
80.06717301,1,,,,,,,,,,,,,,,,,,,,,,
80.17579625,0,,,,,,,,,,,,,,,,,,,,,,
80.2844195,2,,,,,,,,,,,,,,,,,,,,,,
80.39304275,4,,,,,,,,,,,,,,,,,,,,,,
80.501666,0,,,,,,,,,,,,,,,,,,,,,,
80.61028925,4,,,,,,,,,,,,,,,,,,,,,,
80.7189125,1,,,,,,,,,,,,,,,,,,,,,,
80.82753574,1,,,,,,,,,,,,,,,,,,,,,,
80.93615899,0,,,,,,,,,,,,,,,,,,,,,,
81.04478224,4,,,,,,,,,,,,,,,,,,,,,,
81.15340549,0,,,,,,,,,,,,,,,,,,,,,,
81.26202874,4,,,,,,,,,,,,,,,,,,,,,,
81.37065199,1,,,,,,,,,,,,,,,,,,,,,,
81.47927523,8,,,,,,,,,,,,,,,,,,,,,,
81.58789848,0,,,,,,,,,,,,,,,,,,,,,,
81.69652173,5,,,,,,,,,,,,,,,,,,,,,,
81.80514498,1,,,,,,,,,,,,,,,,,,,,,,
81.91376823,5,,,,,,,,,,,,,,,,,,,,,,
82.02239148,4,,,,,,,,,,,,,,,,,,,,,,
82.13101473,2,,,,,,,,,,,,,,,,,,,,,,
82.23963797,12,,,,,,,,,,,,,,,,,,,,,,
82.34826122,2,,,,,,,,,,,,,,,,,,,,,,
82.45688447,2,,,,,,,,,,,,,,,,,,,,,,
82.56550772,5,,,,,,,,,,,,,,,,,,,,,,
82.67413097,2,,,,,,,,,,,,,,,,,,,,,,
82.78275422,1,,,,,,,,,,,,,,,,,,,,,,
82.89137746,2,,,,,,,,,,,,,,,,,,,,,,
83.00000071,0,,,,,,,,,,,,,,,,,,,,,,
83.10862396,2,,,,,,,,,,,,,,,,,,,,,,
83.21724721,4,,,,,,,,,,,,,,,,,,,,,,
83.32587046,4,,,,,,,,,,,,,,,,,,,,,,
83.43449371,8,,,,,,,,,,,,,,,,,,,,,,
83.54311695,1,,,,,,,,,,,,,,,,,,,,,,
83.6517402,4,,,,,,,,,,,,,,,,,,,,,,
83.76036345,0,,,,,,,,,,,,,,,,,,,,,,
83.8689867,2,,,,,,,,,,,,,,,,,,,,,,
83.97760995,5,,,,,,,,,,,,,,,,,,,,,,
84.0862332,2,,,,,,,,,,,,,,,,,,,,,,
84.19485644,4,,,,,,,,,,,,,,,,,,,,,,
84.30347969,4,,,,,,,,,,,,,,,,,,,,,,
84.41210294,2,,,,,,,,,,,,,,,,,,,,,,
84.52072619,4,,,,,,,,,,,,,,,,,,,,,,
84.62934944,1,,,,,,,,,,,,,,,,,,,,,,
84.73797269,0,,,,,,,,,,,,,,,,,,,,,,
84.84659593,4,,,,,,,,,,,,,,,,,,,,,,
84.95521918,2,,,,,,,,,,,,,,,,,,,,,,
85.06384243,5,,,,,,,,,,,,,,,,,,,,,,
85.17246568,2,,,,,,,,,,,,,,,,,,,,,,
85.28108893,1,,,,,,,,,,,,,,,,,,,,,,
85.38971218,4,,,,,,,,,,,,,,,,,,,,,,
85.49833542,6,,,,,,,,,,,,,,,,,,,,,,
85.60695867,1,,,,,,,,,,,,,,,,,,,,,,
85.71558192,0,,,,,,,,,,,,,,,,,,,,,,
85.82420517,2,,,,,,,,,,,,,,,,,,,,,,
85.93282842,2,,,,,,,,,,,,,,,,,,,,,,
86.04145167,6,,,,,,,,,,,,,,,,,,,,,,
86.15007491,6,,,,,,,,,,,,,,,,,,,,,,
86.25869816,4,,,,,,,,,,,,,,,,,,,,,,
86.36732141,1,,,,,,,,,,,,,,,,,,,,,,
86.47594466,9,,,,,,,,,,,,,,,,,,,,,,
86.58456791,5,,,,,,,,,,,,,,,,,,,,,,
86.69319116,5,,,,,,,,,,,,,,,,,,,,,,
86.8018144,2,,,,,,,,,,,,,,,,,,,,,,
86.91043765,4,,,,,,,,,,,,,,,,,,,,,,
87.0190609,1,,,,,,,,,,,,,,,,,,,,,,
87.12768415,2,,,,,,,,,,,,,,,,,,,,,,
87.2363074,4,,,,,,,,,,,,,,,,,,,,,,
87.34493065,5,,,,,,,,,,,,,,,,,,,,,,
87.45355389,6,,,,,,,,,,,,,,,,,,,,,,
87.56217714,5,,,,,,,,,,,,,,,,,,,,,,
87.67080039,6,,,,,,,,,,,,,,,,,,,,,,
87.77942364,8,,,,,,,,,,,,,,,,,,,,,,
87.88804689,22,,,,,,,,,,,,,,,,,,,,,,
87.99667014,70,,,,,,,,,,,,,,,,,,,,,,
88.10529338,73,,,,,,,,,,,,,,,,,,,,,,
88.21391663,18,,,,,,,,,,,,,,,,,,,,,,
88.32253988,84,,,,,,,,,,,,,,,,,,,,,,
88.43116313,12,,,,,,,,,,,,,,,,,,,,,,
88.53978638,5,,,,,,,,,,,,,,,,,,,,,,
88.64840963,2,,,,,,,,,,,,,,,,,,,,,,
88.75703287,1,,,,,,,,,,,,,,,,,,,,,,
88.86565612,1,,,,,,,,,,,,,,,,,,,,,,
88.97427937,0,,,,,,,,,,,,,,,,,,,,,,
89.08290262,0,,,,,,,,,,,,,,,,,,,,,,
89.19152587,2,,,,,,,,,,,,,,,,,,,,,,
89.30014912,4,,,,,,,,,,,,,,,,,,,,,,
89.40877236,1,,,,,,,,,,,,,,,,,,,,,,
89.51739561,1,,,,,,,,,,,,,,,,,,,,,,
89.62601886,6,,,,,,,,,,,,,,,,,,,,,,
89.73464211,1,,,,,,,,,,,,,,,,,,,,,,
89.84326536,1,,,,,,,,,,,,,,,,,,,,,,
89.95188861,1,,,,,,,,,,,,,,,,,,,,,,
90.06051185,1,,,,,,,,,,,,,,,,,,,,,,
90.1691351,0,,,,,,,,,,,,,,,,,,,,,,
90.27775835,2,,,,,,,,,,,,,,,,,,,,,,
90.3863816,2,,,,,,,,,,,,,,,,,,,,,,
90.49500485,2,,,,,,,,,,,,,,,,,,,,,,
90.6036281,0,,,,,,,,,,,,,,,,,,,,,,
90.71225134,2,,,,,,,,,,,,,,,,,,,,,,
90.82087459,2,,,,,,,,,,,,,,,,,,,,,,
90.92949784,4,,,,,,,,,,,,,,,,,,,,,,
91.03812109,5,,,,,,,,,,,,,,,,,,,,,,
91.14674434,1,,,,,,,,,,,,,,,,,,,,,,
91.25536759,4,,,,,,,,,,,,,,,,,,,,,,
91.36399083,2,,,,,,,,,,,,,,,,,,,,,,
91.47261408,4,,,,,,,,,,,,,,,,,,,,,,
91.58123733,1,,,,,,,,,,,,,,,,,,,,,,
91.68986058,4,,,,,,,,,,,,,,,,,,,,,,
91.79848383,2,,,,,,,,,,,,,,,,,,,,,,
91.90710708,0,,,,,,,,,,,,,,,,,,,,,,
92.01573032,6,,,,,,,,,,,,,,,,,,,,,,
92.12435357,2,,,,,,,,,,,,,,,,,,,,,,
92.23297682,4,,,,,,,,,,,,,,,,,,,,,,
92.34160007,4,,,,,,,,,,,,,,,,,,,,,,
92.45022332,2,,,,,,,,,,,,,,,,,,,,,,
92.55884657,0,,,,,,,,,,,,,,,,,,,,,,
92.66746982,4,,,,,,,,,,,,,,,,,,,,,,
92.77609306,4,,,,,,,,,,,,,,,,,,,,,,
92.88471631,9,,,,,,,,,,,,,,,,,,,,,,
92.99333956,2,,,,,,,,,,,,,,,,,,,,,,
93.10196281,1,,,,,,,,,,,,,,,,,,,,,,
93.21058606,0,,,,,,,,,,,,,,,,,,,,,,
93.31920931,1,,,,,,,,,,,,,,,,,,,,,,
93.42783255,2,,,,,,,,,,,,,,,,,,,,,,
93.5364558,1,,,,,,,,,,,,,,,,,,,,,,
93.64507905,0,,,,,,,,,,,,,,,,,,,,,,
93.7537023,0,,,,,,,,,,,,,,,,,,,,,,
93.86232555,4,,,,,,,,,,,,,,,,,,,,,,
93.9709488,2,,,,,,,,,,,,,,,,,,,,,,
94.07957204,4,,,,,,,,,,,,,,,,,,,,,,
94.18819529,4,,,,,,,,,,,,,,,,,,,,,,
94.29681854,2,,,,,,,,,,,,,,,,,,,,,,
94.40544179,1,,,,,,,,,,,,,,,,,,,,,,
94.51406504,5,,,,,,,,,,,,,,,,,,,,,,
94.62268829,6,,,,,,,,,,,,,,,,,,,,,,
94.73131153,6,,,,,,,,,,,,,,,,,,,,,,
94.83993478,18,,,,,,,,,,,,,,,,,,,,,,
94.94855803,52,,,,,,,,,,,,,,,,,,,,,,
95.05718128,32,,,,,,,,,,,,,,,,,,,,,,
95.16580453,12,,,,,,,,,,,,,,,,,,,,,,
95.27442778,52,,,,,,,,,,,,,,,,,,,,,,
95.38305102,12,,,,,,,,,,,,,,,,,,,,,,
95.49167427,6,,,,,,,,,,,,,,,,,,,,,,
95.60029752,6,,,,,,,,,,,,,,,,,,,,,,
95.70892077,5,,,,,,,,,,,,,,,,,,,,,,
95.81754402,2,,,,,,,,,,,,,,,,,,,,,,
95.92616727,4,,,,,,,,,,,,,,,,,,,,,,
96.03479051,5,,,,,,,,,,,,,,,,,,,,,,
96.14341376,5,,,,,,,,,,,,,,,,,,,,,,
96.25203701,1,,,,,,,,,,,,,,,,,,,,,,
96.36066026,2,,,,,,,,,,,,,,,,,,,,,,
96.46928351,4,,,,,,,,,,,,,,,,,,,,,,
96.57790676,2,,,,,,,,,,,,,,,,,,,,,,
96.68653,4,,,,,,,,,,,,,,,,,,,,,,
96.79515325,4,,,,,,,,,,,,,,,,,,,,,,
96.9037765,6,,,,,,,,,,,,,,,,,,,,,,
97.01239975,4,,,,,,,,,,,,,,,,,,,,,,
97.121023,0,,,,,,,,,,,,,,,,,,,,,,
97.22964625,1,,,,,,,,,,,,,,,,,,,,,,
97.33826949,1,,,,,,,,,,,,,,,,,,,,,,
97.44689274,4,,,,,,,,,,,,,,,,,,,,,,
97.55551599,2,,,,,,,,,,,,,,,,,,,,,,
97.66413924,1,,,,,,,,,,,,,,,,,,,,,,
97.77276249,2,,,,,,,,,,,,,,,,,,,,,,
97.88138574,1,,,,,,,,,,,,,,,,,,,,,,
97.99000898,4,,,,,,,,,,,,,,,,,,,,,,
98.09863223,1,,,,,,,,,,,,,,,,,,,,,,
98.20725548,5,,,,,,,,,,,,,,,,,,,,,,
98.31587873,5,,,,,,,,,,,,,,,,,,,,,,
98.42450198,4,,,,,,,,,,,,,,,,,,,,,,
98.53312523,6,,,,,,,,,,,,,,,,,,,,,,
98.64174847,4,,,,,,,,,,,,,,,,,,,,,,
98.75037172,5,,,,,,,,,,,,,,,,,,,,,,
98.85899497,2,,,,,,,,,,,,,,,,,,,,,,
98.96761822,8,,,,,,,,,,,,,,,,,,,,,,
99.07624147,10,,,,,,,,,,,,,,,,,,,,,,
99.18486472,5,,,,,,,,,,,,,,,,,,,,,,
99.29348796,1,,,,,,,,,,,,,,,,,,,,,,
99.40211121,2,,,,,,,,,,,,,,,,,,,,,,
99.51073446,1,,,,,,,,,,,,,,,,,,,,,,
99.61935771,4,,,,,,,,,,,,,,,,,,,,,,
99.72798096,8,,,,,,,,,,,,,,,,,,,,,,
99.83660421,0,,,,,,,,,,,,,,,,,,,,,,
99.94522745,5,,,,,,,,,,,,,,,,,,,,,,
100.0538507,1,,,,,,,,,,,,,,,,,,,,,,
100.162474,1,,,,,,,,,,,,,,,,,,,,,,
100.2710972,2,,,,,,,,,,,,,,,,,,,,,,
100.3797204,2,,,,,,,,,,,,,,,,,,,,,,
100.4883437,0,,,,,,,,,,,,,,,,,,,,,,
100.5969669,0,,,,,,,,,,,,,,,,,,,,,,
100.7055902,2,,,,,,,,,,,,,,,,,,,,,,
100.8142134,1,,,,,,,,,,,,,,,,,,,,,,
100.9228367,2,,,,,,,,,,,,,,,,,,,,,,
101.0314599,0,,,,,,,,,,,,,,,,,,,,,,
101.1400832,4,,,,,,,,,,,,,,,,,,,,,,
101.2487064,5,,,,,,,,,,,,,,,,,,,,,,
101.3573297,2,,,,,,,,,,,,,,,,,,,,,,
101.4659529,4,,,,,,,,,,,,,,,,,,,,,,
101.5745762,6,,,,,,,,,,,,,,,,,,,,,,
101.6831994,8,,,,,,,,,,,,,,,,,,,,,,
101.7918227,1,,,,,,,,,,,,,,,,,,,,,,
101.9004459,2,,,,,,,,,,,,,,,,,,,,,,
102.0090692,4,,,,,,,,,,,,,,,,,,,,,,
102.1176924,1,,,,,,,,,,,,,,,,,,,,,,
102.2263157,0,,,,,,,,,,,,,,,,,,,,,,
102.3349389,2,,,,,,,,,,,,,,,,,,,,,,
102.4435622,0,,,,,,,,,,,,,,,,,,,,,,
102.5521854,4,,,,,,,,,,,,,,,,,,,,,,
102.6608087,1,,,,,,,,,,,,,,,,,,,,,,
102.7694319,0,,,,,,,,,,,,,,,,,,,,,,
102.8780552,4,,,,,,,,,,,,,,,,,,,,,,
102.9866784,2,,,,,,,,,,,,,,,,,,,,,,
103.0953017,4,,,,,,,,,,,,,,,,,,,,,,
103.2039249,0,,,,,,,,,,,,,,,,,,,,,,
103.3125482,0,,,,,,,,,,,,,,,,,,,,,,
103.4211714,1,,,,,,,,,,,,,,,,,,,,,,
103.5297947,2,,,,,,,,,,,,,,,,,,,,,,
103.6384179,4,,,,,,,,,,,,,,,,,,,,,,
103.7470411,2,,,,,,,,,,,,,,,,,,,,,,
103.8556644,1,,,,,,,,,,,,,,,,,,,,,,
103.9642876,0,,,,,,,,,,,,,,,,,,,,,,
104.0729109,4,,,,,,,,,,,,,,,,,,,,,,
104.1815341,1,,,,,,,,,,,,,,,,,,,,,,
104.2901574,4,,,,,,,,,,,,,,,,,,,,,,
104.3987806,0,,,,,,,,,,,,,,,,,,,,,,
104.5074039,1,,,,,,,,,,,,,,,,,,,,,,
104.6160271,2,,,,,,,,,,,,,,,,,,,,,,
104.7246504,1,,,,,,,,,,,,,,,,,,,,,,
104.8332736,2,,,,,,,,,,,,,,,,,,,,,,
104.9418969,2,,,,,,,,,,,,,,,,,,,,,,
105.0505201,5,,,,,,,,,,,,,,,,,,,,,,
105.1591434,0,,,,,,,,,,,,,,,,,,,,,,
105.2677666,2,,,,,,,,,,,,,,,,,,,,,,
105.3763899,6,,,,,,,,,,,,,,,,,,,,,,
105.4850131,5,,,,,,,,,,,,,,,,,,,,,,
105.5936364,1,,,,,,,,,,,,,,,,,,,,,,
105.7022596,2,,,,,,,,,,,,,,,,,,,,,,
105.8108829,2,,,,,,,,,,,,,,,,,,,,,,
105.9195061,5,,,,,,,,,,,,,,,,,,,,,,
106.0281294,2,,,,,,,,,,,,,,,,,,,,,,
106.1367526,4,,,,,,,,,,,,,,,,,,,,,,
106.2453759,4,,,,,,,,,,,,,,,,,,,,,,
106.3539991,4,,,,,,,,,,,,,,,,,,,,,,
106.4626224,6,,,,,,,,,,,,,,,,,,,,,,
106.5712456,6,,,,,,,,,,,,,,,,,,,,,,
106.6798689,68,,,,,,,,,,,,,,,,,,,,,,
106.7884921,26,,,,,,,,,,,,,,,,,,,,,,
106.8971153,8,,,,,,,,,,,,,,,,,,,,,,
107.0057386,5,,,,,,,,,,,,,,,,,,,,,,
107.1143618,56,,,,,,,,,,,,,,,,,,,,,,
107.2229851,4,,,,,,,,,,,,,,,,,,,,,,
107.3316083,2,,,,,,,,,,,,,,,,,,,,,,
107.4402316,2,,,,,,,,,,,,,,,,,,,,,,
107.5488548,4,,,,,,,,,,,,,,,,,,,,,,
107.6574781,5,,,,,,,,,,,,,,,,,,,,,,
107.7661013,4,,,,,,,,,,,,,,,,,,,,,,
107.8747246,5,,,,,,,,,,,,,,,,,,,,,,
107.9833478,2,,,,,,,,,,,,,,,,,,,,,,
108.0919711,1,,,,,,,,,,,,,,,,,,,,,,
108.2005943,0,,,,,,,,,,,,,,,,,,,,,,
108.3092176,1,,,,,,,,,,,,,,,,,,,,,,
108.4178408,0,,,,,,,,,,,,,,,,,,,,,,
108.5264641,1,,,,,,,,,,,,,,,,,,,,,,
108.6350873,1,,,,,,,,,,,,,,,,,,,,,,
108.7437106,5,,,,,,,,,,,,,,,,,,,,,,
108.8523338,6,,,,,,,,,,,,,,,,,,,,,,
108.9609571,4,,,,,,,,,,,,,,,,,,,,,,
109.0695803,0,,,,,,,,,,,,,,,,,,,,,,
109.1782036,2,,,,,,,,,,,,,,,,,,,,,,
109.2868268,0,,,,,,,,,,,,,,,,,,,,,,
109.3954501,0,,,,,,,,,,,,,,,,,,,,,,
109.5040733,2,,,,,,,,,,,,,,,,,,,,,,
109.6126966,5,,,,,,,,,,,,,,,,,,,,,,
109.7213198,2,,,,,,,,,,,,,,,,,,,,,,
109.8299431,2,,,,,,,,,,,,,,,,,,,,,,
109.9385663,4,,,,,,,,,,,,,,,,,,,,,,
110.0471896,0,,,,,,,,,,,,,,,,,,,,,,
110.1558128,2,,,,,,,,,,,,,,,,,,,,,,
110.264436,2,,,,,,,,,,,,,,,,,,,,,,
110.3730593,0,,,,,,,,,,,,,,,,,,,,,,
110.4816825,2,,,,,,,,,,,,,,,,,,,,,,
110.5903058,0,,,,,,,,,,,,,,,,,,,,,,
110.698929,0,,,,,,,,,,,,,,,,,,,,,,
110.8075523,2,,,,,,,,,,,,,,,,,,,,,,
110.9161755,2,,,,,,,,,,,,,,,,,,,,,,
111.0247988,5,,,,,,,,,,,,,,,,,,,,,,
111.133422,0,,,,,,,,,,,,,,,,,,,,,,
111.2420453,6,,,,,,,,,,,,,,,,,,,,,,
111.3506685,4,,,,,,,,,,,,,,,,,,,,,,
111.4592918,1,,,,,,,,,,,,,,,,,,,,,,
111.567915,4,,,,,,,,,,,,,,,,,,,,,,
111.6765383,1,,,,,,,,,,,,,,,,,,,,,,
111.7851615,10,,,,,,,,,,,,,,,,,,,,,,
111.8937848,8,,,,,,,,,,,,,,,,,,,,,,
112.002408,9,,,,,,,,,,,,,,,,,,,,,,
112.1110313,2,,,,,,,,,,,,,,,,,,,,,,
112.2196545,4,,,,,,,,,,,,,,,,,,,,,,
112.3282778,4,,,,,,,,,,,,,,,,,,,,,,
112.436901,4,,,,,,,,,,,,,,,,,,,,,,
112.5455243,2,,,,,,,,,,,,,,,,,,,,,,
112.6541475,0,,,,,,,,,,,,,,,,,,,,,,
112.7627708,5,,,,,,,,,,,,,,,,,,,,,,
112.871394,0,,,,,,,,,,,,,,,,,,,,,,
112.9800173,12,,,,,,,,,,,,,,,,,,,,,,
113.0886405,0,,,,,,,,,,,,,,,,,,,,,,
113.1972638,4,,,,,,,,,,,,,,,,,,,,,,
113.305887,5,,,,,,,,,,,,,,,,,,,,,,
113.4145102,4,,,,,,,,,,,,,,,,,,,,,,
113.5231335,5,,,,,,,,,,,,,,,,,,,,,,
113.6317567,10,,,,,,,,,,,,,,,,,,,,,,
113.74038,5,,,,,,,,,,,,,,,,,,,,,,
113.8490032,14,,,,,,,,,,,,,,,,,,,,,,
113.9576265,29,,,,,,,,,,,,,,,,,,,,,,
114.0662497,254,,,,,,,,,,,,,,,,,,,,,,
114.174873,84,,,,,,,,,,,,,,,,,,,,,,
114.2834962,13,,,,,,,,,,,,,,,,,,,,,,
114.3921195,26,,,,,,,,,,,,,,,,,,,,,,
114.5007427,98,,,,,,,,,,,,,,,,,,,,,,
114.609366,44,,,,,,,,,,,,,,,,,,,,,,
114.7179892,18,,,,,,,,,,,,,,,,,,,,,,
114.8266125,5,,,,,,,,,,,,,,,,,,,,,,
114.9352357,6,,,,,,,,,,,,,,,,,,,,,,
115.043859,4,,,,,,,,,,,,,,,,,,,,,,
115.1524822,4,,,,,,,,,,,,,,,,,,,,,,
115.2611055,6,,,,,,,,,,,,,,,,,,,,,,
115.3697287,1,,,,,,,,,,,,,,,,,,,,,,
115.478352,4,,,,,,,,,,,,,,,,,,,,,,
115.5869752,4,,,,,,,,,,,,,,,,,,,,,,
115.6955985,2,,,,,,,,,,,,,,,,,,,,,,
115.8042217,10,,,,,,,,,,,,,,,,,,,,,,
115.912845,1,,,,,,,,,,,,,,,,,,,,,,
116.0214682,1,,,,,,,,,,,,,,,,,,,,,,
116.1300915,1,,,,,,,,,,,,,,,,,,,,,,
116.2387147,4,,,,,,,,,,,,,,,,,,,,,,
116.347338,9,,,,,,,,,,,,,,,,,,,,,,
116.4559612,4,,,,,,,,,,,,,,,,,,,,,,
116.5645845,12,,,,,,,,,,,,,,,,,,,,,,
116.6732077,6,,,,,,,,,,,,,,,,,,,,,,
116.7818309,2,,,,,,,,,,,,,,,,,,,,,,
116.8904542,4,,,,,,,,,,,,,,,,,,,,,,
116.9990774,2,,,,,,,,,,,,,,,,,,,,,,
117.1077007,6,,,,,,,,,,,,,,,,,,,,,,
117.2163239,1,,,,,,,,,,,,,,,,,,,,,,
117.3249472,2,,,,,,,,,,,,,,,,,,,,,,
117.4335704,4,,,,,,,,,,,,,,,,,,,,,,
117.5421937,1,,,,,,,,,,,,,,,,,,,,,,
117.6508169,0,,,,,,,,,,,,,,,,,,,,,,
117.7594402,1,,,,,,,,,,,,,,,,,,,,,,
117.8680634,4,,,,,,,,,,,,,,,,,,,,,,
117.9766867,4,,,,,,,,,,,,,,,,,,,,,,
118.0853099,2,,,,,,,,,,,,,,,,,,,,,,
118.1939332,4,,,,,,,,,,,,,,,,,,,,,,
118.3025564,5,,,,,,,,,,,,,,,,,,,,,,
118.4111797,2,,,,,,,,,,,,,,,,,,,,,,
118.5198029,0,,,,,,,,,,,,,,,,,,,,,,
118.6284262,1,,,,,,,,,,,,,,,,,,,,,,
118.7370494,4,,,,,,,,,,,,,,,,,,,,,,
118.8456727,2,,,,,,,,,,,,,,,,,,,,,,
118.9542959,6,,,,,,,,,,,,,,,,,,,,,,
119.0629192,4,,,,,,,,,,,,,,,,,,,,,,
119.1715424,1,,,,,,,,,,,,,,,,,,,,,,
119.2801657,5,,,,,,,,,,,,,,,,,,,,,,
119.3887889,2,,,,,,,,,,,,,,,,,,,,,,
119.4974122,2,,,,,,,,,,,,,,,,,,,,,,
119.6060354,2,,,,,,,,,,,,,,,,,,,,,,
119.7146587,5,,,,,,,,,,,,,,,,,,,,,,
119.8232819,1,,,,,,,,,,,,,,,,,,,,,,
119.9319052,1,,,,,,,,,,,,,,,,,,,,,,
120.0405284,0,,,,,,,,,,,,,,,,,,,,,,
120.1491516,5,,,,,,,,,,,,,,,,,,,,,,
120.2577749,4,,,,,,,,,,,,,,,,,,,,,,
120.3663981,2,,,,,,,,,,,,,,,,,,,,,,
120.4750214,2,,,,,,,,,,,,,,,,,,,,,,
120.5836446,2,,,,,,,,,,,,,,,,,,,,,,
120.6922679,4,,,,,,,,,,,,,,,,,,,,,,
120.8008911,6,,,,,,,,,,,,,,,,,,,,,,
120.9095144,1,,,,,,,,,,,,,,,,,,,,,,
121.0181376,6,,,,,,,,,,,,,,,,,,,,,,
121.1267609,0,,,,,,,,,,,,,,,,,,,,,,
121.2353841,2,,,,,,,,,,,,,,,,,,,,,,
121.3440074,2,,,,,,,,,,,,,,,,,,,,,,
121.4526306,2,,,,,,,,,,,,,,,,,,,,,,
121.5612539,2,,,,,,,,,,,,,,,,,,,,,,
121.6698771,5,,,,,,,,,,,,,,,,,,,,,,
121.7785004,5,,,,,,,,,,,,,,,,,,,,,,
121.8871236,1,,,,,,,,,,,,,,,,,,,,,,
121.9957469,4,,,,,,,,,,,,,,,,,,,,,,
122.1043701,1,,,,,,,,,,,,,,,,,,,,,,
122.2129934,5,,,,,,,,,,,,,,,,,,,,,,
122.3216166,4,,,,,,,,,,,,,,,,,,,,,,
122.4302399,1,,,,,,,,,,,,,,,,,,,,,,
122.5388631,5,,,,,,,,,,,,,,,,,,,,,,
122.6474864,4,,,,,,,,,,,,,,,,,,,,,,
122.7561096,1,,,,,,,,,,,,,,,,,,,,,,
122.8647329,5,,,,,,,,,,,,,,,,,,,,,,
122.9733561,5,,,,,,,,,,,,,,,,,,,,,,
123.0819794,1,,,,,,,,,,,,,,,,,,,,,,
123.1906026,2,,,,,,,,,,,,,,,,,,,,,,
123.2992258,5,,,,,,,,,,,,,,,,,,,,,,
123.4078491,5,,,,,,,,,,,,,,,,,,,,,,
123.5164723,2,,,,,,,,,,,,,,,,,,,,,,
123.6250956,5,,,,,,,,,,,,,,,,,,,,,,
123.7337188,2,,,,,,,,,,,,,,,,,,,,,,
123.8423421,1,,,,,,,,,,,,,,,,,,,,,,
123.9509653,2,,,,,,,,,,,,,,,,,,,,,,
124.0595886,2,,,,,,,,,,,,,,,,,,,,,,
124.1682118,8,,,,,,,,,,,,,,,,,,,,,,
124.2768351,4,,,,,,,,,,,,,,,,,,,,,,
124.3854583,1,,,,,,,,,,,,,,,,,,,,,,
124.4940816,1,,,,,,,,,,,,,,,,,,,,,,
124.6027048,2,,,,,,,,,,,,,,,,,,,,,,
124.7113281,1,,,,,,,,,,,,,,,,,,,,,,
124.8199513,2,,,,,,,,,,,,,,,,,,,,,,
124.9285746,0,,,,,,,,,,,,,,,,,,,,,,
125.0371978,4,,,,,,,,,,,,,,,,,,,,,,
125.1458211,5,,,,,,,,,,,,,,,,,,,,,,
125.2544443,5,,,,,,,,,,,,,,,,,,,,,,
125.3630676,2,,,,,,,,,,,,,,,,,,,,,,
125.4716908,1,,,,,,,,,,,,,,,,,,,,,,
125.5803141,5,,,,,,,,,,,,,,,,,,,,,,
125.6889373,2,,,,,,,,,,,,,,,,,,,,,,
125.7975606,6,,,,,,,,,,,,,,,,,,,,,,
125.9061838,1,,,,,,,,,,,,,,,,,,,,,,
126.0148071,4,,,,,,,,,,,,,,,,,,,,,,
126.1234303,5,,,,,,,,,,,,,,,,,,,,,,
126.2320536,2,,,,,,,,,,,,,,,,,,,,,,
126.3406768,5,,,,,,,,,,,,,,,,,,,,,,
126.4493001,5,,,,,,,,,,,,,,,,,,,,,,
126.5579233,9,,,,,,,,,,,,,,,,,,,,,,
126.6665465,1,,,,,,,,,,,,,,,,,,,,,,
126.7751698,2,,,,,,,,,,,,,,,,,,,,,,
126.883793,4,,,,,,,,,,,,,,,,,,,,,,
126.9924163,8,,,,,,,,,,,,,,,,,,,,,,
127.1010395,8,,,,,,,,,,,,,,,,,,,,,,
127.2096628,8,,,,,,,,,,,,,,,,,,,,,,
127.318286,12,,,,,,,,,,,,,,,,,,,,,,
127.4269093,25,,,,,,,,,,,,,,,,,,,,,,
127.5355325,124,,,,,,,,,,,,,,,,,,,,,,
127.6441558,93,,,,,,,,,,,,,,,,,,,,,,
127.752779,28,,,,,,,,,,,,,,,,,,,,,,
127.8614023,17,,,,,,,,,,,,,,,,,,,,,,
127.9700255,24,,,,,,,,,,,,,,,,,,,,,,
128.0786488,44,,,,,,,,,,,,,,,,,,,,,,
128.187272,93,,,,,,,,,,,,,,,,,,,,,,
128.2958953,20,,,,,,,,,,,,,,,,,,,,,,
128.4045185,8,,,,,,,,,,,,,,,,,,,,,,
128.5131418,6,,,,,,,,,,,,,,,,,,,,,,
128.621765,2,,,,,,,,,,,,,,,,,,,,,,
128.7303883,2,,,,,,,,,,,,,,,,,,,,,,
128.8390115,4,,,,,,,,,,,,,,,,,,,,,,
128.9476348,4,,,,,,,,,,,,,,,,,,,,,,
129.056258,5,,,,,,,,,,,,,,,,,,,,,,
129.1648813,6,,,,,,,,,,,,,,,,,,,,,,
129.2735045,5,,,,,,,,,,,,,,,,,,,,,,
129.3821278,4,,,,,,,,,,,,,,,,,,,,,,
129.490751,6,,,,,,,,,,,,,,,,,,,,,,
129.5993743,4,,,,,,,,,,,,,,,,,,,,,,
129.7079975,10,,,,,,,,,,,,,,,,,,,,,,
129.8166208,6,,,,,,,,,,,,,,,,,,,,,,
129.925244,5,,,,,,,,,,,,,,,,,,,,,,
130.0338672,0,,,,,,,,,,,,,,,,,,,,,,
130.1424905,2,,,,,,,,,,,,,,,,,,,,,,
130.2511137,4,,,,,,,,,,,,,,,,,,,,,,
130.359737,4,,,,,,,,,,,,,,,,,,,,,,
130.4683602,1,,,,,,,,,,,,,,,,,,,,,,
130.5769835,5,,,,,,,,,,,,,,,,,,,,,,
130.6856067,4,,,,,,,,,,,,,,,,,,,,,,
130.79423,1,,,,,,,,,,,,,,,,,,,,,,
130.9028532,1,,,,,,,,,,,,,,,,,,,,,,
131.0114765,5,,,,,,,,,,,,,,,,,,,,,,
131.1200997,6,,,,,,,,,,,,,,,,,,,,,,
131.228723,4,,,,,,,,,,,,,,,,,,,,,,
131.3373462,1,,,,,,,,,,,,,,,,,,,,,,
131.4459695,5,,,,,,,,,,,,,,,,,,,,,,
131.5545927,2,,,,,,,,,,,,,,,,,,,,,,
131.663216,8,,,,,,,,,,,,,,,,,,,,,,
131.7718392,2,,,,,,,,,,,,,,,,,,,,,,
131.8804625,5,,,,,,,,,,,,,,,,,,,,,,
131.9890857,1,,,,,,,,,,,,,,,,,,,,,,
132.097709,2,,,,,,,,,,,,,,,,,,,,,,
132.2063322,9,,,,,,,,,,,,,,,,,,,,,,
132.3149555,8,,,,,,,,,,,,,,,,,,,,,,
132.4235787,5,,,,,,,,,,,,,,,,,,,,,,
132.532202,2,,,,,,,,,,,,,,,,,,,,,,
132.6408252,1,,,,,,,,,,,,,,,,,,,,,,
132.7494485,2,,,,,,,,,,,,,,,,,,,,,,
132.8580717,4,,,,,,,,,,,,,,,,,,,,,,
132.966695,0,,,,,,,,,,,,,,,,,,,,,,
133.0753182,9,,,,,,,,,,,,,,,,,,,,,,
133.1839414,4,,,,,,,,,,,,,,,,,,,,,,
133.2925647,1,,,,,,,,,,,,,,,,,,,,,,
133.4011879,2,,,,,,,,,,,,,,,,,,,,,,
133.5098112,9,,,,,,,,,,,,,,,,,,,,,,
133.6184344,2,,,,,,,,,,,,,,,,,,,,,,
133.7270577,2,,,,,,,,,,,,,,,,,,,,,,
133.8356809,1,,,,,,,,,,,,,,,,,,,,,,
133.9443042,6,,,,,,,,,,,,,,,,,,,,,,
134.0529274,5,,,,,,,,,,,,,,,,,,,,,,
134.1615507,2,,,,,,,,,,,,,,,,,,,,,,
134.2701739,8,,,,,,,,,,,,,,,,,,,,,,
134.3787972,9,,,,,,,,,,,,,,,,,,,,,,
134.4874204,5,,,,,,,,,,,,,,,,,,,,,,
134.5960437,2,,,,,,,,,,,,,,,,,,,,,,
134.7046669,4,,,,,,,,,,,,,,,,,,,,,,
134.8132902,5,,,,,,,,,,,,,,,,,,,,,,
134.9219134,0,,,,,,,,,,,,,,,,,,,,,,
135.0305367,4,,,,,,,,,,,,,,,,,,,,,,
135.1391599,9,,,,,,,,,,,,,,,,,,,,,,
135.2477832,6,,,,,,,,,,,,,,,,,,,,,,
135.3564064,4,,,,,,,,,,,,,,,,,,,,,,
135.4650297,5,,,,,,,,,,,,,,,,,,,,,,
135.5736529,4,,,,,,,,,,,,,,,,,,,,,,
135.6822762,6,,,,,,,,,,,,,,,,,,,,,,
135.7908994,5,,,,,,,,,,,,,,,,,,,,,,
135.8995227,4,,,,,,,,,,,,,,,,,,,,,,
136.0081459,2,,,,,,,,,,,,,,,,,,,,,,
136.1167692,4,,,,,,,,,,,,,,,,,,,,,,
136.2253924,6,,,,,,,,,,,,,,,,,,,,,,
136.3340157,6,,,,,,,,,,,,,,,,,,,,,,
136.4426389,4,,,,,,,,,,,,,,,,,,,,,,
136.5512621,10,,,,,,,,,,,,,,,,,,,,,,
136.6598854,17,,,,,,,,,,,,,,,,,,,,,,
136.7685086,38,,,,,,,,,,,,,,,,,,,,,,
136.8771319,149,,,,,,,,,,,,,,,,,,,,,,
136.9857551,77,,,,,,,,,,,,,,,,,,,,,,
137.0943784,22,,,,,,,,,,,,,,,,,,,,,,
137.2030016,20,,,,,,,,,,,,,,,,,,,,,,
137.3116249,5,,,,,,,,,,,,,,,,,,,,,,
137.4202481,9,,,,,,,,,,,,,,,,,,,,,,
137.5288714,32,,,,,,,,,,,,,,,,,,,,,,
137.6374946,98,,,,,,,,,,,,,,,,,,,,,,
137.7461179,34,,,,,,,,,,,,,,,,,,,,,,
137.8547411,12,,,,,,,,,,,,,,,,,,,,,,
137.9633644,2,,,,,,,,,,,,,,,,,,,,,,
138.0719876,9,,,,,,,,,,,,,,,,,,,,,,
138.1806109,4,,,,,,,,,,,,,,,,,,,,,,
138.2892341,2,,,,,,,,,,,,,,,,,,,,,,
138.3978574,9,,,,,,,,,,,,,,,,,,,,,,
138.5064806,2,,,,,,,,,,,,,,,,,,,,,,
138.6151039,6,,,,,,,,,,,,,,,,,,,,,,
138.7237271,4,,,,,,,,,,,,,,,,,,,,,,
138.8323504,5,,,,,,,,,,,,,,,,,,,,,,
138.9409736,2,,,,,,,,,,,,,,,,,,,,,,
139.0495969,6,,,,,,,,,,,,,,,,,,,,,,
139.1582201,6,,,,,,,,,,,,,,,,,,,,,,
139.2668434,8,,,,,,,,,,,,,,,,,,,,,,
139.3754666,4,,,,,,,,,,,,,,,,,,,,,,
139.4840899,2,,,,,,,,,,,,,,,,,,,,,,
139.5927131,0,,,,,,,,,,,,,,,,,,,,,,
139.7013364,2,,,,,,,,,,,,,,,,,,,,,,
139.8099596,2,,,,,,,,,,,,,,,,,,,,,,
139.9185828,4,,,,,,,,,,,,,,,,,,,,,,
140.0272061,5,,,,,,,,,,,,,,,,,,,,,,
140.1358293,1,,,,,,,,,,,,,,,,,,,,,,
140.2444526,4,,,,,,,,,,,,,,,,,,,,,,
140.3530758,1,,,,,,,,,,,,,,,,,,,,,,
140.4616991,14,,,,,,,,,,,,,,,,,,,,,,
140.5703223,5,,,,,,,,,,,,,,,,,,,,,,
140.6789456,6,,,,,,,,,,,,,,,,,,,,,,
140.7875688,1,,,,,,,,,,,,,,,,,,,,,,
140.8961921,1,,,,,,,,,,,,,,,,,,,,,,
141.0048153,4,,,,,,,,,,,,,,,,,,,,,,
141.1134386,2,,,,,,,,,,,,,,,,,,,,,,
141.2220618,8,,,,,,,,,,,,,,,,,,,,,,
141.3306851,6,,,,,,,,,,,,,,,,,,,,,,
141.4393083,2,,,,,,,,,,,,,,,,,,,,,,
141.5479316,2,,,,,,,,,,,,,,,,,,,,,,
141.6565548,4,,,,,,,,,,,,,,,,,,,,,,
141.7651781,8,,,,,,,,,,,,,,,,,,,,,,
141.8738013,4,,,,,,,,,,,,,,,,,,,,,,
141.9824246,4,,,,,,,,,,,,,,,,,,,,,,
142.0910478,5,,,,,,,,,,,,,,,,,,,,,,
142.1996711,5,,,,,,,,,,,,,,,,,,,,,,
142.3082943,2,,,,,,,,,,,,,,,,,,,,,,
142.4169176,8,,,,,,,,,,,,,,,,,,,,,,
142.5255408,5,,,,,,,,,,,,,,,,,,,,,,
142.6341641,2,,,,,,,,,,,,,,,,,,,,,,
142.7427873,5,,,,,,,,,,,,,,,,,,,,,,
142.8514106,1,,,,,,,,,,,,,,,,,,,,,,
142.9600338,8,,,,,,,,,,,,,,,,,,,,,,
143.068657,4,,,,,,,,,,,,,,,,,,,,,,
143.1772803,6,,,,,,,,,,,,,,,,,,,,,,
143.2859035,4,,,,,,,,,,,,,,,,,,,,,,
143.3945268,4,,,,,,,,,,,,,,,,,,,,,,
143.50315,0,,,,,,,,,,,,,,,,,,,,,,
143.6117733,5,,,,,,,,,,,,,,,,,,,,,,
143.7203965,6,,,,,,,,,,,,,,,,,,,,,,
143.8290198,1,,,,,,,,,,,,,,,,,,,,,,
143.937643,4,,,,,,,,,,,,,,,,,,,,,,
144.0462663,4,,,,,,,,,,,,,,,,,,,,,,
144.1548895,2,,,,,,,,,,,,,,,,,,,,,,
144.2635128,6,,,,,,,,,,,,,,,,,,,,,,
144.372136,2,,,,,,,,,,,,,,,,,,,,,,
144.4807593,0,,,,,,,,,,,,,,,,,,,,,,
144.5893825,4,,,,,,,,,,,,,,,,,,,,,,
144.6980058,5,,,,,,,,,,,,,,,,,,,,,,
144.806629,5,,,,,,,,,,,,,,,,,,,,,,
144.9152523,5,,,,,,,,,,,,,,,,,,,,,,
145.0238755,6,,,,,,,,,,,,,,,,,,,,,,
145.1324988,5,,,,,,,,,,,,,,,,,,,,,,
145.241122,4,,,,,,,,,,,,,,,,,,,,,,
145.3497453,10,,,,,,,,,,,,,,,,,,,,,,
145.4583685,2,,,,,,,,,,,,,,,,,,,,,,
145.5669918,8,,,,,,,,,,,,,,,,,,,,,,
145.675615,2,,,,,,,,,,,,,,,,,,,,,,
145.7842383,2,,,,,,,,,,,,,,,,,,,,,,
145.8928615,0,,,,,,,,,,,,,,,,,,,,,,
146.0014848,2,,,,,,,,,,,,,,,,,,,,,,
146.110108,2,,,,,,,,,,,,,,,,,,,,,,
146.2187313,6,,,,,,,,,,,,,,,,,,,,,,
146.3273545,5,,,,,,,,,,,,,,,,,,,,,,
146.4359777,6,,,,,,,,,,,,,,,,,,,,,,
146.544601,2,,,,,,,,,,,,,,,,,,,,,,
146.6532242,4,,,,,,,,,,,,,,,,,,,,,,
146.7618475,1,,,,,,,,,,,,,,,,,,,,,,
146.8704707,6,,,,,,,,,,,,,,,,,,,,,,
146.979094,5,,,,,,,,,,,,,,,,,,,,,,
147.0877172,8,,,,,,,,,,,,,,,,,,,,,,
147.1963405,6,,,,,,,,,,,,,,,,,,,,,,
147.3049637,1,,,,,,,,,,,,,,,,,,,,,,
147.413587,4,,,,,,,,,,,,,,,,,,,,,,
147.5222102,4,,,,,,,,,,,,,,,,,,,,,,
147.6308335,1,,,,,,,,,,,,,,,,,,,,,,
147.7394567,2,,,,,,,,,,,,,,,,,,,,,,
147.84808,2,,,,,,,,,,,,,,,,,,,,,,
147.9567032,1,,,,,,,,,,,,,,,,,,,,,,
148.0653265,4,,,,,,,,,,,,,,,,,,,,,,
148.1739497,4,,,,,,,,,,,,,,,,,,,,,,
148.282573,8,,,,,,,,,,,,,,,,,,,,,,
148.3911962,2,,,,,,,,,,,,,,,,,,,,,,
148.4998195,1,,,,,,,,,,,,,,,,,,,,,,
148.6084427,8,,,,,,,,,,,,,,,,,,,,,,
148.717066,5,,,,,,,,,,,,,,,,,,,,,,
148.8256892,6,,,,,,,,,,,,,,,,,,,,,,
148.9343125,5,,,,,,,,,,,,,,,,,,,,,,
149.0429357,6,,,,,,,,,,,,,,,,,,,,,,
149.151559,2,,,,,,,,,,,,,,,,,,,,,,
149.2601822,2,,,,,,,,,,,,,,,,,,,,,,
149.3688055,4,,,,,,,,,,,,,,,,,,,,,,
149.4774287,2,,,,,,,,,,,,,,,,,,,,,,
149.586052,4,,,,,,,,,,,,,,,,,,,,,,
149.6946752,8,,,,,,,,,,,,,,,,,,,,,,
149.8032984,9,,,,,,,,,,,,,,,,,,,,,,
149.9119217,5,,,,,,,,,,,,,,,,,,,,,,
149.995478,4,,,,,,,,,,,,,,,,,,,,,,