File: PeakFitting/xrdData/915+aluminum.csv
[Measurement conditions]
Sample identification,
Comment - 1,"Configuration=MPSS New Configuration, Owner=User-1, Creation date=10/27/2010 9:00:11 AM"
Comment - 2,"Goniometer=PW3050/60 (Theta/Theta); Minimum step size 2Theta:0.001; Minimum step size Omega:0.001"
Comment - 3,"Sample stage=Multi purpose sample stage; Minimum step size Phi:2.5"
Comment - 4,"Diffractometer system=XPERT-PRO"
Comment - 5,"Measurement program=C:\XRD Data\mcaplan\311 lab.xrdmp, Identifier={45589E5F-173F-4548-9E9A-391A8F8D5901}"
Anode material,Cu
K-Alpha1 wavelength,1.5405980
K-Alpha2 wavelength,1.5444260
Ratio K-Alpha2/K-Alpha1,0.500
Divergence slit,Fixed,0.19mm
Monochromator used,NO
Generator voltage, 45
Tube current, 40
File date and time,06/Nov/2018 13:39
Unit cell,
h k l, 0 0 0
Scan axis,Gonio
Scan range,10.001000003,149.999655857
Scan step size,0.0083556
No. of points, 16755
Scan type,CONTINUOUS
Phi,0.0
Time per step,1.905
[Scan points]
Angle,Intensity
10.005177820,8.0
10.105445434,13.0
10.205713048,14.0
10.305980662,13.0
10.406248275,18.0
10.506515889,13.0
10.606783503,5.0
10.707051117,6.0
10.807318731,8.0
10.907586345,14.0
11.007853959,8.0
11.108121572,6.0
11.208389186,10.0
11.308656800,13.0
11.408924414,16.0
11.509192028,10.0
11.609459642,10.0
11.709727256,12.0
11.809994870,12.0
11.910262483,12.0
12.010530097,12.0
12.110797711,4.0
12.211065325,12.0
12.311332939,6.0
12.411600553,5.0
12.511868167,2.0
12.612135780,6.0
12.712403394,12.0
12.812671008,5.0
12.912938622,8.0
13.013206236,6.0
13.113473850,9.0
13.213741464,8.0
13.314009077,5.0
13.414276691,1.0
13.514544305,13.0
13.614811919,9.0
13.715079533,10.0
13.815347147,10.0
13.915614761,2.0
14.015882374,5.0
14.116149988,5.0
14.216417602,2.0
14.316685216,5.0
14.416952830,5.0
14.517220444,14.0
14.617488058,12.0
14.717755672,10.0
14.818023285,10.0
14.918290899,6.0
15.018558513,5.0
15.118826127,4.0
15.219093741,6.0
15.319361355,5.0
15.419628969,8.0
15.519896582,12.0
15.620164196,9.0
15.720431810,4.0
15.820699424,9.0
15.920967038,4.0
16.021234652,5.0
16.121502266,8.0
16.221769879,10.0
16.322037493,4.0
16.422305107,8.0
16.522572721,5.0
16.622840335,9.0
16.723107949,1.0
16.823375563,12.0
16.923643176,5.0
17.023910790,5.0
17.124178404,5.0
17.224446018,10.0
17.324713632,0.0
17.424981246,2.0
17.525248860,12.0
17.625516473,2.0
17.725784087,4.0
17.826051701,6.0
17.926319315,5.0
18.026586929,0.0
18.126854543,6.0
18.227122157,1.0
18.327389771,5.0
18.427657384,5.0
18.527924998,1.0
18.628192612,12.0
18.728460226,4.0
18.828727840,6.0
18.928995454,8.0
19.029263068,1.0
19.129530681,2.0
19.229798295,5.0
19.330065909,5.0
19.430333523,1.0
19.530601137,8.0
19.630868751,6.0
19.731136365,4.0
19.831403978,6.0
19.931671592,5.0
20.031939206,5.0
20.132206820,6.0
20.232474434,6.0
20.332742048,4.0
20.433009662,2.0
20.533277275,6.0
20.633544889,4.0
20.733812503,5.0
20.834080117,5.0
20.934347731,5.0
21.034615345,9.0
21.134882959,4.0
21.235150573,5.0
21.335418186,1.0
21.435685800,6.0
21.535953414,5.0
21.636221028,4.0
21.736488642,8.0
21.836756256,4.0
21.937023870,1.0
22.037291483,5.0
22.137559097,5.0
22.237826711,2.0
22.338094325,4.0
22.438361939,1.0
22.538629553,4.0
22.638897167,2.0
22.739164780,9.0
22.839432394,2.0
22.939700008,1.0
23.039967622,4.0
23.140235236,4.0
23.240502850,2.0
23.340770464,6.0
23.441038077,2.0
23.541305691,4.0
23.641573305,6.0
23.741840919,1.0
23.842108533,4.0
23.942376147,5.0
24.042643761,6.0
24.142911375,8.0
24.243178988,5.0
24.343446602,0.0
24.443714216,6.0
24.543981830,2.0
24.644249444,6.0
24.744517058,4.0
24.844784672,5.0
24.945052285,2.0
25.045319899,4.0
25.145587513,5.0
25.245855127,5.0
25.346122741,2.0
25.446390355,1.0
25.546657969,8.0
25.646925582,6.0
25.747193196,6.0
25.847460810,4.0
25.947728424,0.0
26.047996038,2.0
26.148263652,2.0
26.248531266,5.0
26.348798879,1.0
26.449066493,9.0
26.549334107,4.0
26.649601721,5.0
26.749869335,8.0
26.850136949,4.0
26.950404563,0.0
27.050672176,1.0
27.150939790,1.0
27.251207404,8.0
27.351475018,1.0
27.451742632,8.0
27.552010246,4.0
27.652277860,6.0
27.752545474,6.0
27.852813087,10.0
27.953080701,8.0
28.053348315,8.0
28.153615929,9.0
28.253883543,5.0
28.354151157,8.0
28.454418771,6.0
28.554686384,2.0
28.654953998,4.0
28.755221612,4.0
28.855489226,2.0
28.955756840,5.0
29.056024454,5.0
29.156292068,0.0
29.256559681,0.0
29.356827295,2.0
29.457094909,6.0
29.557362523,4.0
29.657630137,8.0
29.757897751,4.0
29.858165365,1.0
29.958432978,10.0
30.058700592,5.0
30.158968206,9.0
30.259235820,6.0
30.359503434,1.0
30.459771048,8.0
30.560038662,4.0
30.660306276,6.0
30.760573889,6.0
30.860841503,5.0
30.961109117,2.0
31.061376731,6.0
31.161644345,9.0
31.261911959,4.0
31.362179573,8.0
31.462447186,5.0
31.562714800,5.0
31.662982414,6.0
31.763250028,9.0
31.863517642,2.0
31.963785256,8.0
32.064052870,1.0
32.164320483,2.0
32.264588097,2.0
32.364855711,8.0
32.465123325,4.0
32.565390939,5.0
32.665658553,2.0
32.765926167,10.0
32.866193780,4.0
32.966461394,5.0
33.066729008,9.0
33.166996622,5.0
33.267264236,2.0
33.367531850,6.0
33.467799464,4.0
33.568067078,4.0
33.668334691,5.0
33.768602305,6.0
33.868869919,9.0
33.969137533,2.0
34.069405147,4.0
34.169672761,6.0
34.269940375,10.0
34.370207988,6.0
34.470475602,2.0
34.570743216,5.0
34.671010830,2.0
34.771278444,9.0
34.871546058,8.0
34.971813672,6.0
35.072081285,4.0
35.172348899,6.0
35.272616513,1.0
35.372884127,2.0
35.473151741,4.0
35.573419355,5.0
35.673686969,6.0
35.773954582,6.0
35.874222196,6.0
35.974489810,5.0
36.074757424,1.0
36.175025038,13.0
36.275292652,9.0
36.375560266,1.0
36.475827880,13.0
36.576095493,5.0
36.676363107,8.0
36.776630721,12.0
36.876898335,6.0
36.977165949,8.0
37.077433563,8.0
37.177701177,9.0
37.277968790,13.0
37.378236404,8.0
37.478504018,4.0
37.578771632,9.0
37.679039246,6.0
37.779306860,8.0
37.879574474,4.0
37.979842087,2.0
38.080109701,6.0
38.180377315,8.0
38.280644929,16.0
38.380912543,17.0
38.481180157,8.0
38.581447771,8.0
38.681715384,13.0
38.781982998,10.0
38.882250612,9.0
38.982518226,5.0
39.082785840,6.0
39.183053454,12.0
39.283321068,10.0
39.383588681,17.0
39.483856295,17.0
39.584123909,20.0
39.684391523,14.0
39.784659137,10.0
39.884926751,16.0
39.985194365,18.0
40.085461979,14.0
40.185729592,13.0
40.285997206,12.0
40.386264820,17.0
40.486532434,18.0
40.586800048,14.0
40.687067662,14.0
40.787335276,10.0
40.887602889,17.0
40.987870503,16.0
41.088138117,24.0
41.188405731,16.0
41.288673345,38.0
41.388940959,16.0
41.489208573,20.0
41.589476186,18.0
41.689743800,26.0
41.790011414,21.0
41.890279028,18.0
41.990546642,20.0
42.090814256,22.0
42.191081870,20.0
42.291349483,25.0
42.391617097,40.0
42.491884711,32.0
42.592152325,26.0
42.692419939,46.0
42.792687553,80.0
42.892955167,94.0
42.993222781,168.0
43.093490394,192.0
43.193758008,129.0
43.294025622,98.0
43.394293236,56.0
43.494560850,48.0
43.594828464,48.0
43.695096078,48.0
43.795363691,48.0
43.895631305,58.0
43.995898919,46.0
44.096166533,44.0
44.196434147,46.0
44.296701761,37.0
44.396969375,48.0
44.497236988,44.0
44.597504602,48.0
44.697772216,36.0
44.798039830,42.0
44.898307444,50.0
44.998575058,34.0
45.098842672,34.0
45.199110285,41.0
45.299377899,38.0
45.399645513,60.0
45.499913127,34.0
45.600180741,30.0
45.700448355,42.0
45.800715969,48.0
45.900983583,41.0
46.001251196,38.0
46.101518810,42.0
46.201786424,44.0
46.302054038,37.0
46.402321652,40.0
46.502589266,40.0
46.602856880,46.0
46.703124493,33.0
46.803392107,49.0
46.903659721,34.0
47.003927335,29.0
47.104194949,33.0
47.204462563,36.0
47.304730177,34.0
47.404997790,29.0
47.505265404,28.0
47.605533018,30.0
47.705800632,22.0
47.806068246,36.0
47.906335860,29.0
48.006603474,25.0
48.106871087,26.0
48.207138701,25.0
48.307406315,14.0
48.407673929,28.0
48.507941543,21.0
48.608209157,21.0
48.708476771,17.0
48.808744385,18.0
48.909011998,20.0
49.009279612,18.0
49.109547226,26.0
49.209814840,21.0
49.310082454,32.0
49.410350068,33.0
49.510617682,21.0
49.610885295,28.0
49.711152909,60.0
49.811420523,57.0
49.911688137,82.0
50.011955751,114.0
50.112223365,117.0
50.212490979,94.0
50.312758592,61.0
50.413026206,40.0
50.513293820,42.0
50.613561434,20.0
50.713829048,25.0
50.814096662,17.0
50.914364276,10.0
51.014631889,17.0
51.114899503,21.0
51.215167117,16.0
51.315434731,12.0
51.415702345,9.0
51.515969959,25.0
51.616237573,17.0
51.716505186,10.0
51.816772800,10.0
51.917040414,17.0
52.017308028,12.0
52.117575642,14.0
52.217843256,10.0
52.318110870,8.0
52.418378484,10.0
52.518646097,9.0
52.618913711,12.0
52.719181325,10.0
52.819448939,2.0
52.919716553,14.0
53.019984167,8.0
53.120251781,13.0
53.220519394,9.0
53.320787008,10.0
53.421054622,14.0
53.521322236,4.0
53.621589850,13.0
53.721857464,5.0
53.822125078,8.0
53.922392691,8.0
54.022660305,6.0
54.122927919,12.0
54.223195533,9.0
54.323463147,9.0
54.423730761,9.0
54.523998375,4.0
54.624265988,8.0
54.724533602,9.0
54.824801216,14.0
54.925068830,9.0
55.025336444,13.0
55.125604058,13.0
55.225871672,8.0
55.326139286,4.0
55.426406899,6.0
55.526674513,8.0
55.626942127,4.0
55.727209741,4.0
55.827477355,10.0
55.927744969,5.0
56.028012583,10.0
56.128280196,5.0
56.228547810,4.0
56.328815424,6.0
56.429083038,6.0
56.529350652,4.0
56.629618266,4.0
56.729885880,4.0
56.830153493,8.0
56.930421107,8.0
57.030688721,8.0
57.130956335,8.0
57.231223949,2.0
57.331491563,6.0
57.431759177,5.0
57.532026790,6.0
57.632294404,10.0
57.732562018,8.0
57.832829632,9.0
57.933097246,5.0
58.033364860,1.0
58.133632474,6.0
58.233900088,10.0
58.334167701,6.0
58.434435315,4.0
58.534702929,2.0
58.634970543,1.0
58.735238157,10.0
58.835505771,1.0
58.935773385,6.0
59.036040998,5.0
59.136308612,2.0
59.236576226,4.0
59.336843840,4.0
59.437111454,6.0
59.537379068,2.0
59.637646682,2.0
59.737914295,2.0
59.838181909,1.0
59.938449523,2.0
60.038717137,8.0
60.138984751,6.0
60.239252365,2.0
60.339519979,8.0
60.439787592,9.0
60.540055206,5.0
60.640322820,9.0
60.740590434,4.0
60.840858048,6.0
60.941125662,5.0
61.041393276,0.0
61.141660889,6.0
61.241928503,2.0
61.342196117,4.0
61.442463731,12.0
61.542731345,4.0
61.642998959,8.0
61.743266573,1.0
61.843534187,4.0
61.943801800,4.0
62.044069414,5.0
62.144337028,9.0
62.244604642,2.0
62.344872256,6.0
62.445139870,6.0
62.545407484,5.0
62.645675097,1.0
62.745942711,4.0
62.846210325,4.0
62.946477939,0.0
63.046745553,4.0
63.147013167,1.0
63.247280781,9.0
63.347548394,5.0
63.447816008,9.0
63.548083622,6.0
63.648351236,8.0
63.748618850,0.0
63.848886464,1.0
63.949154078,2.0
64.049421691,4.0
64.149689305,4.0
64.249956919,8.0
64.350224533,5.0
64.450492147,2.0
64.550759761,5.0
64.651027375,8.0
64.751294989,14.0
64.851562602,4.0
64.951830216,5.0
65.052097830,4.0
65.152365444,6.0
65.252633058,2.0
65.352900672,8.0
65.453168286,8.0
65.553435899,4.0
65.653703513,1.0
65.753971127,1.0
65.854238741,0.0
65.954506355,5.0
66.054773969,6.0
66.155041583,9.0
66.255309196,4.0
66.355576810,2.0
66.455844424,5.0
66.556112038,12.0
66.656379652,6.0
66.756647266,8.0
66.856914880,8.0
66.957182493,6.0
67.057450107,8.0
67.157717721,4.0
67.257985335,4.0
67.358252949,5.0
67.458520563,2.0
67.558788177,2.0
67.659055791,5.0
67.759323404,6.0
67.859591018,9.0
67.959858632,6.0
68.060126246,5.0
68.160393860,5.0
68.260661474,6.0
68.360929088,2.0
68.461196701,9.0
68.561464315,5.0
68.661731929,8.0
68.761999543,6.0
68.862267157,4.0
68.962534771,5.0
69.062802385,2.0
69.163069998,6.0
69.263337612,5.0
69.363605226,8.0
69.463872840,6.0
69.564140454,9.0
69.664408068,14.0
69.764675682,16.0
69.864943295,8.0
69.965210909,4.0
70.065478523,2.0
70.165746137,2.0
70.266013751,6.0
70.366281365,5.0
70.466548979,14.0
70.566816593,9.0
70.667084206,17.0
70.767351820,4.0
70.867619434,9.0
70.967887048,8.0
71.068154662,12.0
71.168422276,10.0
71.268689890,6.0
71.368957503,4.0
71.469225117,8.0
71.569492731,12.0
71.669760345,10.0
71.770027959,12.0
71.870295573,16.0
71.970563187,14.0
72.070830800,20.0
72.171098414,25.0
72.271366028,16.0
72.371633642,14.0
72.471901256,33.0
72.572168870,20.0
72.672436484,30.0
72.772704097,33.0
72.872971711,49.0
72.973239325,58.0
73.073506939,120.0
73.173774553,153.0
73.274042167,304.0
73.374309781,530.0
73.474577394,697.0
73.574845008,645.0
73.675112622,502.0
73.775380236,370.0
73.875647850,232.0
73.975915464,152.0
74.076183078,84.0
74.176450692,60.0
74.276718305,41.0
74.376985919,38.0
74.477253533,37.0
74.577521147,24.0
74.677788761,20.0
74.778056375,24.0
74.878323989,20.0
74.978591602,10.0
75.078859216,10.0
75.179126830,14.0
75.279394444,22.0
75.379662058,16.0
75.479929672,18.0
75.580197286,22.0
75.680464899,9.0
75.780732513,17.0
75.881000127,6.0
75.981267741,8.0
76.081535355,17.0
76.181802969,8.0
76.282070583,13.0
76.382338196,12.0
76.482605810,13.0
76.582873424,10.0
76.683141038,14.0
76.783408652,8.0
76.883676266,8.0
76.983943880,2.0
77.084211494,12.0
77.184479107,10.0
77.284746721,5.0
77.385014335,21.0
77.485281949,6.0
77.585549563,6.0
77.685817177,6.0
77.786084791,6.0
77.886352404,6.0
77.986620018,13.0
78.086887632,9.0
78.187155246,10.0
78.287422860,9.0
78.387690474,10.0
78.487958088,6.0
78.588225701,5.0
78.688493315,9.0
78.788760929,6.0
78.889028543,6.0
78.989296157,8.0
79.089563771,12.0
79.189831385,10.0
79.290098998,5.0
79.390366612,9.0
79.490634226,8.0
79.590901840,10.0
79.691169454,2.0
79.791437068,6.0
79.891704682,5.0
79.991972296,8.0
80.092239909,13.0
80.192507523,8.0
80.292775137,14.0
80.393042751,4.0
80.493310365,9.0
80.593577979,2.0
80.693845593,6.0
80.794113206,9.0
80.894380820,4.0
80.994648434,6.0
81.094916048,8.0
81.195183662,8.0
81.295451276,5.0
81.395718890,9.0
81.495986503,2.0
81.596254117,5.0
81.696521731,4.0
81.796789345,6.0
81.897056959,10.0
81.997324573,6.0
82.097592187,8.0
82.197859800,5.0
82.298127414,10.0
82.398395028,8.0
82.498662642,4.0
82.598930256,9.0
82.699197870,10.0
82.799465484,8.0
82.899733098,5.0
83.000000711,4.0
83.100268325,5.0
83.200535939,9.0
83.300803553,9.0
83.401071167,4.0
83.501338781,6.0
83.601606395,8.0
83.701874008,9.0
83.802141622,6.0
83.902409236,5.0
84.002676850,8.0
84.102944464,6.0
84.203212078,16.0
84.303479692,6.0
84.403747305,6.0
84.504014919,8.0
84.604282533,6.0
84.704550147,12.0
84.804817761,5.0
84.905085375,10.0
85.005352989,8.0
85.105620602,5.0
85.205888216,13.0
85.306155830,4.0
85.406423444,8.0
85.506691058,4.0
85.606958672,6.0
85.707226286,10.0
85.807493899,5.0
85.907761513,9.0
86.008029127,4.0
86.108296741,2.0
86.208564355,6.0
86.308831969,8.0
86.409099583,6.0
86.509367197,5.0
86.609634810,5.0
86.709902424,6.0
86.810170038,4.0
86.910437652,4.0
87.010705266,9.0
87.110972880,10.0
87.211240494,6.0
87.311508107,5.0
87.411775721,9.0
87.512043335,8.0
87.612310949,10.0
87.712578563,9.0
87.812846177,18.0
87.913113791,9.0
88.013381404,10.0
88.113649018,12.0
88.213916632,16.0
88.314184246,20.0
88.414451860,21.0
88.514719474,37.0
88.614987088,60.0
88.715254701,54.0
88.815522315,98.0
88.915789929,90.0
89.016057543,104.0
89.116325157,116.0
89.216592771,124.0
89.316860385,86.0
89.417127999,92.0
89.517395612,49.0
89.617663226,46.0
89.717930840,37.0
89.818198454,24.0
89.918466068,20.0
90.018733682,21.0
90.119001296,20.0
90.219268909,16.0
90.319536523,9.0
90.419804137,10.0
90.520071751,8.0
90.620339365,9.0
90.720606979,6.0
90.820874593,10.0
90.921142206,8.0
91.021409820,8.0
91.121677434,6.0
91.221945048,12.0
91.322212662,10.0
91.422480276,8.0
91.522747890,5.0
91.623015503,6.0
91.723283117,2.0
91.823550731,8.0
91.923818345,5.0
92.024085959,10.0
92.124353573,6.0
92.224621187,4.0
92.324888801,2.0
92.425156414,8.0
92.525424028,1.0
92.625691642,5.0
92.725959256,9.0
92.826226870,9.0
92.926494484,5.0
93.026762098,6.0
93.127029711,6.0
93.227297325,2.0
93.327564939,5.0
93.427832553,2.0
93.528100167,1.0
93.628367781,12.0
93.728635395,4.0
93.828903008,4.0
93.929170622,5.0
94.029438236,6.0
94.129705850,14.0
94.229973464,12.0
94.330241078,8.0
94.430508692,6.0
94.530776305,10.0
94.631043919,6.0
94.731311533,4.0
94.831579147,6.0
94.931846761,10.0
95.032114375,1.0
95.132381989,5.0
95.232649602,5.0
95.332917216,1.0
95.433184830,5.0
95.533452444,6.0
95.633720058,10.0
95.733987672,1.0
95.834255286,9.0
95.934522900,6.0
96.034790513,5.0
96.135058127,2.0
96.235325741,2.0
96.335593355,1.0
96.435860969,2.0
96.536128583,4.0
96.636396197,9.0
96.736663810,5.0
96.836931424,4.0
96.937199038,6.0
97.037466652,4.0
97.137734266,5.0
97.238001880,1.0
97.338269494,4.0
97.438537107,2.0
97.538804721,2.0
97.639072335,6.0
97.739339949,6.0
97.839607563,2.0
97.939875177,2.0
98.040142791,2.0
98.140410404,2.0
98.240678018,1.0
98.340945632,8.0
98.441213246,5.0
98.541480860,0.0
98.641748474,1.0
98.742016088,2.0
98.842283702,2.0
98.942551315,4.0
99.042818929,4.0
99.143086543,8.0
99.243354157,2.0
99.343621771,4.0
99.443889385,0.0
99.544156999,4.0
99.644424612,4.0
99.744692226,5.0
99.844959840,2.0
99.945227454,4.0
100.045495068,4.0
100.145762682,4.0
100.246030296,4.0
100.346297909,2.0
100.446565523,2.0
100.546833137,6.0
100.647100751,8.0
100.747368365,5.0
100.847635979,1.0
100.947903593,4.0
101.048171206,2.0
101.148438820,4.0
101.248706434,5.0
101.348974048,2.0
101.449241662,6.0
101.549509276,5.0
101.649776890,4.0
101.750044504,4.0
101.850312117,2.0
101.950579731,2.0
102.050847345,2.0
102.151114959,5.0
102.251382573,9.0
102.351650187,6.0
102.451917801,5.0
102.552185414,4.0
102.652453028,6.0
102.752720642,5.0
102.852988256,6.0
102.953255870,9.0
103.053523484,5.0
103.153791098,4.0
103.254058711,4.0
103.354326325,2.0
103.454593939,6.0
103.554861553,5.0
103.655129167,4.0
103.755396781,5.0
103.855664395,0.0
103.955932008,2.0
104.056199622,2.0
104.156467236,4.0
104.256734850,1.0
104.357002464,4.0
104.457270078,5.0
104.557537692,1.0
104.657805306,4.0
104.758072919,6.0
104.858340533,2.0
104.958608147,2.0
105.058875761,8.0
105.159143375,1.0
105.259410989,5.0
105.359678603,2.0
105.459946216,1.0
105.560213830,4.0
105.660481444,2.0
105.760749058,4.0
105.861016672,6.0
105.961284286,1.0
106.061551900,1.0
106.161819513,4.0
106.262087127,2.0
106.362354741,1.0
106.462622355,1.0
106.562889969,4.0
106.663157583,5.0
106.763425197,5.0
106.863692810,2.0
106.963960424,1.0
107.064228038,4.0
107.164495652,4.0
107.264763266,2.0
107.365030880,10.0
107.465298494,5.0
107.565566107,2.0
107.665833721,1.0
107.766101335,1.0
107.866368949,5.0
107.966636563,4.0
108.066904177,2.0
108.167171791,4.0
108.267439405,4.0
108.367707018,2.0
108.467974632,8.0
108.568242246,0.0
108.668509860,5.0
108.768777474,4.0
108.869045088,5.0
108.969312702,1.0
109.069580315,1.0
109.169847929,6.0
109.270115543,4.0
109.370383157,1.0
109.470650771,1.0
109.570918385,8.0
109.671185999,4.0
109.771453612,4.0
109.871721226,4.0
109.971988840,2.0
110.072256454,4.0
110.172524068,2.0
110.272791682,2.0
110.373059296,2.0
110.473326909,1.0
110.573594523,5.0
110.673862137,2.0
110.774129751,5.0
110.874397365,2.0
110.974664979,4.0
111.074932593,6.0
111.175200207,5.0
111.275467820,2.0
111.375735434,8.0
111.476003048,6.0
111.576270662,8.0
111.676538276,2.0
111.776805890,4.0
111.877073504,1.0
111.977341117,1.0
112.077608731,4.0
112.177876345,5.0
112.278143959,2.0
112.378411573,5.0
112.478679187,4.0
112.578946801,1.0
112.679214414,1.0
112.779482028,4.0
112.879749642,2.0
112.980017256,6.0
113.080284870,5.0
113.180552484,4.0
113.280820098,4.0
113.381087711,6.0
113.481355325,5.0
113.581622939,8.0
113.681890553,2.0
113.782158167,2.0
113.882425781,1.0
113.982693395,0.0
114.082961009,4.0
114.183228622,6.0
114.283496236,4.0
114.383763850,1.0
114.484031464,6.0
114.584299078,4.0
114.684566692,4.0
114.784834306,8.0
114.885101919,8.0
114.985369533,6.0
115.085637147,8.0
115.185904761,5.0
115.286172375,1.0
115.386439989,12.0
115.486707603,6.0
115.586975216,8.0
115.687242830,5.0
115.787510444,8.0
115.887778058,6.0
115.988045672,6.0
116.088313286,6.0
116.188580900,8.0
116.288848513,6.0
116.389116127,13.0
116.489383741,9.0
116.589651355,2.0
116.689918969,5.0
116.790186583,2.0
116.890454197,0.0
116.990721811,5.0
117.090989424,2.0
117.191257038,9.0
117.291524652,8.0
117.391792266,2.0
117.492059880,5.0
117.592327494,2.0
117.692595108,5.0
117.792862721,6.0
117.893130335,1.0
117.993397949,5.0
118.093665563,4.0
118.193933177,0.0
118.294200791,6.0
118.394468405,5.0
118.494736018,5.0
118.595003632,4.0
118.695271246,5.0
118.795538860,5.0
118.895806474,4.0
118.996074088,0.0
119.096341702,8.0
119.196609315,6.0
119.296876929,4.0
119.397144543,2.0
119.497412157,6.0
119.597679771,6.0
119.697947385,6.0
119.798214999,8.0
119.898482612,5.0
119.998750226,5.0
120.099017840,4.0
120.199285454,2.0
120.299553068,5.0
120.399820682,2.0
120.500088296,5.0
120.600355910,4.0
120.700623523,4.0
120.800891137,2.0
120.901158751,5.0
121.001426365,1.0
121.101693979,4.0
121.201961593,2.0
121.302229207,9.0
121.402496820,8.0
121.502764434,2.0
121.603032048,2.0
121.703299662,4.0
121.803567276,4.0
121.903834890,9.0
122.004102504,6.0
122.104370117,10.0
122.204637731,6.0
122.304905345,6.0
122.405172959,6.0
122.505440573,6.0
122.605708187,5.0
122.705975801,8.0
122.806243414,2.0
122.906511028,1.0
123.006778642,6.0
123.107046256,0.0
123.207313870,4.0
123.307581484,6.0
123.407849098,8.0
123.508116712,1.0
123.608384325,5.0
123.708651939,0.0
123.808919553,4.0
123.909187167,4.0
124.009454781,2.0
124.109722395,9.0
124.209990009,6.0
124.310257622,5.0
124.410525236,4.0
124.510792850,8.0
124.611060464,5.0
124.711328078,1.0
124.811595692,5.0
124.911863306,6.0
125.012130919,6.0
125.112398533,2.0
125.212666147,5.0
125.312933761,5.0
125.413201375,2.0
125.513468989,6.0
125.613736603,8.0
125.714004216,4.0
125.814271830,6.0
125.914539444,4.0
126.014807058,6.0
126.115074672,12.0
126.215342286,2.0
126.315609900,4.0
126.415877514,8.0
126.516145127,4.0
126.616412741,4.0
126.716680355,2.0
126.816947969,5.0
126.917215583,10.0
127.017483197,6.0
127.117750811,4.0
127.218018424,10.0
127.318286038,2.0
127.418553652,4.0
127.518821266,4.0
127.619088880,5.0
127.719356494,9.0
127.819624108,5.0
127.919891721,9.0
128.020159335,6.0
128.120426949,4.0
128.220694563,4.0
128.320962177,14.0
128.421229791,8.0
128.521497405,5.0
128.621765018,13.0
128.722032632,4.0
128.822300246,13.0
128.922567860,6.0
129.022835474,9.0
129.123103088,9.0
129.223370702,4.0
129.323638315,5.0
129.423905929,4.0
129.524173543,4.0
129.624441157,5.0
129.724708771,9.0
129.824976385,5.0
129.925243999,9.0
130.025511613,5.0
130.125779226,8.0
130.226046840,10.0
130.326314454,5.0
130.426582068,2.0
130.526849682,4.0
130.627117296,12.0
130.727384910,10.0
130.827652523,10.0
130.927920137,9.0
131.028187751,9.0
131.128455365,5.0
131.228722979,5.0
131.328990593,2.0
131.429258207,5.0
131.529525820,5.0
131.629793434,5.0
131.730061048,5.0
131.830328662,10.0
131.930596276,9.0
132.030863890,6.0
132.131131504,5.0
132.231399117,17.0
132.331666731,12.0
132.431934345,10.0
132.532201959,9.0
132.632469573,12.0
132.732737187,12.0
132.833004801,6.0
132.933272415,17.0
133.033540028,13.0
133.133807642,17.0
133.234075256,18.0
133.334342870,26.0
133.434610484,34.0
133.534878098,20.0
133.635145712,33.0
133.735413325,37.0
133.835680939,34.0
133.935948553,36.0
134.036216167,49.0
134.136483781,34.0
134.236751395,26.0
134.337019009,40.0
134.437286622,38.0
134.537554236,32.0
134.637821850,41.0
134.738089464,29.0
134.838357078,38.0
134.938624692,20.0
135.038892306,18.0
135.139159919,24.0
135.239427533,16.0
135.339695147,20.0
135.439962761,25.0
135.540230375,9.0
135.640497989,18.0
135.740765603,12.0
135.841033217,10.0
135.941300830,14.0
136.041568444,12.0
136.141836058,14.0
136.242103672,13.0
136.342371286,14.0
136.442638900,12.0
136.542906514,8.0
136.643174127,17.0
136.743441741,16.0
136.843709355,10.0
136.943976969,9.0
137.044244583,4.0
137.144512197,10.0
137.244779811,14.0
137.345047424,9.0
137.445315038,9.0
137.545582652,2.0
137.645850266,14.0
137.746117880,14.0
137.846385494,21.0
137.946653108,8.0
138.046920721,6.0
138.147188335,10.0
138.247455949,9.0
138.347723563,14.0
138.447991177,12.0
138.548258791,6.0
138.648526405,9.0
138.748794019,13.0
138.849061632,8.0
138.949329246,12.0
139.049596860,10.0
139.149864474,9.0
139.250132088,13.0
139.350399702,9.0
139.450667316,9.0
139.550934929,16.0
139.651202543,12.0
139.751470157,9.0
139.851737771,9.0
139.952005385,16.0
140.052272999,8.0
140.152540613,9.0
140.252808226,17.0
140.353075840,12.0
140.453343454,17.0
140.553611068,22.0
140.653878682,24.0
140.754146296,13.0
140.854413910,29.0
140.954681523,29.0
141.054949137,36.0
141.155216751,29.0
141.255484365,33.0
141.355751979,34.0
141.456019593,36.0
141.556287207,42.0
141.656554820,41.0
141.756822434,49.0
141.857090048,38.0
141.957357662,45.0
142.057625276,16.0
142.157892890,34.0
142.258160504,33.0
142.358428118,40.0
142.458695731,28.0
142.558963345,24.0
142.659230959,34.0
142.759498573,29.0
142.859766187,29.0
142.960033801,25.0
143.060301415,22.0
143.160569028,21.0
143.260836642,17.0
143.361104256,18.0
143.461371870,22.0
143.561639484,21.0
143.661907098,16.0
143.762174712,12.0
143.862442325,12.0
143.962709939,14.0
144.062977553,14.0
144.163245167,14.0
144.263512781,10.0
144.363780395,9.0
144.464048009,6.0
144.564315622,12.0
144.664583236,18.0
144.764850850,9.0
144.865118464,12.0
144.965386078,10.0
145.065653692,6.0
145.165921306,8.0
145.266188920,10.0
145.366456533,9.0
145.466724147,8.0
145.566991761,5.0
145.667259375,9.0
145.767526989,4.0
145.867794603,12.0
145.968062217,12.0
146.068329830,9.0
146.168597444,8.0
146.268865058,10.0
146.369132672,8.0
146.469400286,6.0
146.569667900,8.0
146.669935514,6.0
146.770203127,10.0
146.870470741,5.0
146.970738355,12.0
147.071005969,9.0
147.171273583,8.0
147.271541197,8.0
147.371808811,8.0
147.472076424,9.0
147.572344038,10.0
147.672611652,6.0
147.772879266,12.0
147.873146880,6.0
147.973414494,6.0
148.073682108,1.0
148.173949722,5.0
148.274217335,9.0
148.374484949,10.0
148.474752563,10.0
148.575020177,8.0
148.675287791,10.0
148.775555405,1.0
148.875823019,8.0
148.976090632,2.0
149.076358246,9.0
149.176625860,10.0
149.276893474,5.0
149.377161088,6.0
149.477428702,8.0
149.577696316,2.0
149.677963929,4.0
149.778231543,9.0
149.878499157,6.0
149.978766771,10.0
149.995478040,6.0