File: PeakFitting/xrdData/915+glass.csv
[Measurement conditions]
Sample identification,
Comment - 1,"Configuration=MPSS New Configuration, Owner=User-1, Creation date=10/27/2010 9:00:11 AM"
Comment - 2,"Goniometer=PW3050/60 (Theta/Theta); Minimum step size 2Theta:0.001; Minimum step size Omega:0.001"
Comment - 3,"Sample stage=Multi purpose sample stage; Minimum step size Phi:2.5"
Comment - 4,"Diffractometer system=XPERT-PRO"
Comment - 5,"Measurement program=C:\XRD Data\mcaplan\311 lab.xrdmp, Identifier={45589E5F-173F-4548-9E9A-391A8F8D5901}"
Anode material,Cu
K-Alpha1 wavelength,1.5405980
K-Alpha2 wavelength,1.5444260
Ratio K-Alpha2/K-Alpha1,0.500
Divergence slit,Fixed,0.19mm
Monochromator used,NO
Generator voltage, 45
Tube current, 40
File date and time,06/Nov/2018 10:00
Unit cell,
h k l, 0 0 0
Scan axis,Gonio
Scan range,10.001000003,149.999655857
Scan step size,0.0083556
No. of points, 16755
Scan type,CONTINUOUS
Phi,0.0
Time per step,1.905
[Scan points]
Angle,Intensity
10.005177820,14.0
10.105445434,13.0
10.205713048,14.0
10.305980662,8.0
10.406248275,12.0
10.506515889,10.0
10.606783503,9.0
10.707051117,6.0
10.807318731,13.0
10.907586345,8.0
11.007853959,10.0
11.108121572,14.0
11.208389186,4.0
11.308656800,10.0
11.408924414,8.0
11.509192028,10.0
11.609459642,9.0
11.709727256,9.0
11.809994870,12.0
11.910262483,12.0
12.010530097,9.0
12.110797711,13.0
12.211065325,9.0
12.311332939,8.0
12.411600553,9.0
12.511868167,12.0
12.612135780,10.0
12.712403394,9.0
12.812671008,16.0
12.912938622,13.0
13.013206236,20.0
13.113473850,14.0
13.213741464,16.0
13.314009077,14.0
13.414276691,10.0
13.514544305,13.0
13.614811919,10.0
13.715079533,20.0
13.815347147,16.0
13.915614761,16.0
14.015882374,12.0
14.116149988,18.0
14.216417602,10.0
14.316685216,14.0
14.416952830,10.0
14.517220444,16.0
14.617488058,14.0
14.717755672,21.0
14.818023285,14.0
14.918290899,8.0
15.018558513,21.0
15.118826127,12.0
15.219093741,16.0
15.319361355,16.0
15.419628969,10.0
15.519896582,18.0
15.620164196,8.0
15.720431810,13.0
15.820699424,20.0
15.920967038,17.0
16.021234652,13.0
16.121502266,12.0
16.221769879,13.0
16.322037493,26.0
16.422305107,24.0
16.522572721,16.0
16.622840335,8.0
16.723107949,12.0
16.823375563,14.0
16.923643176,22.0
17.023910790,20.0
17.124178404,18.0
17.224446018,8.0
17.324713632,12.0
17.424981246,17.0
17.525248860,16.0
17.625516473,20.0
17.725784087,16.0
17.826051701,24.0
17.926319315,8.0
18.026586929,24.0
18.126854543,16.0
18.227122157,25.0
18.327389771,6.0
18.427657384,22.0
18.527924998,13.0
18.628192612,16.0
18.728460226,17.0
18.828727840,17.0
18.928995454,17.0
19.029263068,22.0
19.129530681,28.0
19.229798295,24.0
19.330065909,22.0
19.430333523,21.0
19.530601137,17.0
19.630868751,24.0
19.731136365,29.0
19.831403978,29.0
19.931671592,34.0
20.031939206,34.0
20.132206820,32.0
20.232474434,18.0
20.332742048,26.0
20.433009662,29.0
20.533277275,26.0
20.633544889,34.0
20.733812503,28.0
20.834080117,40.0
20.934347731,26.0
21.034615345,29.0
21.134882959,36.0
21.235150573,26.0
21.335418186,25.0
21.435685800,25.0
21.535953414,37.0
21.636221028,25.0
21.736488642,37.0
21.836756256,30.0
21.937023870,34.0
22.037291483,42.0
22.137559097,33.0
22.237826711,36.0
22.338094325,32.0
22.438361939,38.0
22.538629553,42.0
22.638897167,30.0
22.739164780,29.0
22.839432394,32.0
22.939700008,34.0
23.039967622,45.0
23.140235236,28.0
23.240502850,40.0
23.340770464,32.0
23.441038077,32.0
23.541305691,42.0
23.641573305,32.0
23.741840919,34.0
23.842108533,26.0
23.942376147,32.0
24.042643761,34.0
24.142911375,30.0
24.243178988,30.0
24.343446602,25.0
24.443714216,25.0
24.543981830,41.0
24.644249444,32.0
24.744517058,41.0
24.844784672,42.0
24.945052285,25.0
25.045319899,41.0
25.145587513,28.0
25.245855127,30.0
25.346122741,26.0
25.446390355,29.0
25.546657969,30.0
25.646925582,25.0
25.747193196,36.0
25.847460810,37.0
25.947728424,37.0
26.047996038,30.0
26.148263652,14.0
26.248531266,42.0
26.348798879,22.0
26.449066493,30.0
26.549334107,36.0
26.649601721,37.0
26.749869335,26.0
26.850136949,29.0
26.950404563,32.0
27.050672176,28.0
27.150939790,42.0
27.251207404,34.0
27.351475018,29.0
27.451742632,26.0
27.552010246,32.0
27.652277860,29.0
27.752545474,24.0
27.852813087,28.0
27.953080701,21.0
28.053348315,22.0
28.153615929,29.0
28.253883543,26.0
28.354151157,20.0
28.454418771,17.0
28.554686384,32.0
28.654953998,32.0
28.755221612,29.0
28.855489226,37.0
28.955756840,46.0
29.056024454,30.0
29.156292068,22.0
29.256559681,38.0
29.356827295,30.0
29.457094909,20.0
29.557362523,21.0
29.657630137,29.0
29.757897751,30.0
29.858165365,22.0
29.958432978,25.0
30.058700592,20.0
30.158968206,29.0
30.259235820,20.0
30.359503434,25.0
30.459771048,26.0
30.560038662,21.0
30.660306276,30.0
30.760573889,20.0
30.860841503,33.0
30.961109117,26.0
31.061376731,37.0
31.161644345,22.0
31.261911959,22.0
31.362179573,17.0
31.462447186,24.0
31.562714800,16.0
31.662982414,29.0
31.763250028,28.0
31.863517642,18.0
31.963785256,26.0
32.064052870,12.0
32.164320483,30.0
32.264588097,30.0
32.364855711,30.0
32.465123325,20.0
32.565390939,14.0
32.665658553,33.0
32.765926167,20.0
32.866193780,36.0
32.966461394,26.0
33.066729008,18.0
33.166996622,30.0
33.267264236,20.0
33.367531850,25.0
33.467799464,29.0
33.568067078,16.0
33.668334691,17.0
33.768602305,18.0
33.868869919,20.0
33.969137533,22.0
34.069405147,9.0
34.169672761,28.0
34.269940375,26.0
34.370207988,17.0
34.470475602,9.0
34.570743216,17.0
34.671010830,14.0
34.771278444,21.0
34.871546058,17.0
34.971813672,17.0
35.072081285,16.0
35.172348899,10.0
35.272616513,14.0
35.372884127,21.0
35.473151741,18.0
35.573419355,16.0
35.673686969,20.0
35.773954582,14.0
35.874222196,6.0
35.974489810,22.0
36.074757424,18.0
36.175025038,20.0
36.275292652,26.0
36.375560266,20.0
36.475827880,10.0
36.576095493,18.0
36.676363107,12.0
36.776630721,14.0
36.876898335,13.0
36.977165949,10.0
37.077433563,13.0
37.177701177,18.0
37.277968790,10.0
37.378236404,6.0
37.478504018,17.0
37.578771632,10.0
37.679039246,10.0
37.779306860,10.0
37.879574474,10.0
37.979842087,12.0
38.080109701,17.0
38.180377315,17.0
38.280644929,13.0
38.380912543,17.0
38.481180157,12.0
38.581447771,18.0
38.681715384,10.0
38.781982998,18.0
38.882250612,16.0
38.982518226,10.0
39.082785840,12.0
39.183053454,17.0
39.283321068,9.0
39.383588681,17.0
39.483856295,13.0
39.584123909,9.0
39.684391523,14.0
39.784659137,12.0
39.884926751,12.0
39.985194365,20.0
40.085461979,12.0
40.185729592,10.0
40.285997206,6.0
40.386264820,18.0
40.486532434,13.0
40.586800048,18.0
40.687067662,18.0
40.787335276,14.0
40.887602889,16.0
40.987870503,14.0
41.088138117,17.0
41.188405731,12.0
41.288673345,13.0
41.388940959,13.0
41.489208573,13.0
41.589476186,18.0
41.689743800,14.0
41.790011414,12.0
41.890279028,14.0
41.990546642,13.0
42.090814256,1.0
42.191081870,12.0
42.291349483,12.0
42.391617097,17.0
42.491884711,10.0
42.592152325,12.0
42.692419939,14.0
42.792687553,12.0
42.892955167,10.0
42.993222781,5.0
43.093490394,12.0
43.193758008,18.0
43.294025622,14.0
43.394293236,13.0
43.494560850,2.0
43.594828464,14.0
43.695096078,21.0
43.795363691,16.0
43.895631305,10.0
43.995898919,8.0
44.096166533,6.0
44.196434147,16.0
44.296701761,8.0
44.396969375,16.0
44.497236988,10.0
44.597504602,17.0
44.697772216,17.0
44.798039830,10.0
44.898307444,12.0
44.998575058,12.0
45.098842672,17.0
45.199110285,20.0
45.299377899,6.0
45.399645513,5.0
45.499913127,13.0
45.600180741,6.0
45.700448355,13.0
45.800715969,9.0
45.900983583,13.0
46.001251196,2.0
46.101518810,14.0
46.201786424,13.0
46.302054038,12.0
46.402321652,12.0
46.502589266,6.0
46.602856880,14.0
46.703124493,10.0
46.803392107,10.0
46.903659721,14.0
47.003927335,13.0
47.104194949,16.0
47.204462563,14.0
47.304730177,8.0
47.404997790,10.0
47.505265404,9.0
47.605533018,13.0
47.705800632,9.0
47.806068246,9.0
47.906335860,5.0
48.006603474,13.0
48.106871087,18.0
48.207138701,14.0
48.307406315,18.0
48.407673929,9.0
48.507941543,17.0
48.608209157,20.0
48.708476771,17.0
48.808744385,18.0
48.909011998,13.0
49.009279612,14.0
49.109547226,9.0
49.209814840,9.0
49.310082454,10.0
49.410350068,10.0
49.510617682,16.0
49.610885295,21.0
49.711152909,13.0
49.811420523,12.0
49.911688137,9.0
50.011955751,8.0
50.112223365,17.0
50.212490979,6.0
50.312758592,9.0
50.413026206,13.0
50.513293820,9.0
50.613561434,8.0
50.713829048,13.0
50.814096662,12.0
50.914364276,5.0
51.014631889,14.0
51.114899503,9.0
51.215167117,13.0
51.315434731,12.0
51.415702345,14.0
51.515969959,10.0
51.616237573,6.0
51.716505186,14.0
51.816772800,10.0
51.917040414,9.0
52.017308028,10.0
52.117575642,10.0
52.217843256,8.0
52.318110870,6.0
52.418378484,12.0
52.518646097,20.0
52.618913711,13.0
52.719181325,14.0
52.819448939,4.0
52.919716553,5.0
53.019984167,8.0
53.120251781,5.0
53.220519394,10.0
53.320787008,8.0
53.421054622,13.0
53.521322236,14.0
53.621589850,13.0
53.721857464,14.0
53.822125078,9.0
53.922392691,16.0
54.022660305,5.0
54.122927919,2.0
54.223195533,4.0
54.323463147,8.0
54.423730761,16.0
54.523998375,18.0
54.624265988,6.0
54.724533602,12.0
54.824801216,12.0
54.925068830,16.0
55.025336444,10.0
55.125604058,8.0
55.225871672,17.0
55.326139286,9.0
55.426406899,8.0
55.526674513,12.0
55.626942127,12.0
55.727209741,6.0
55.827477355,8.0
55.927744969,8.0
56.028012583,10.0
56.128280196,13.0
56.228547810,14.0
56.328815424,12.0
56.429083038,12.0
56.529350652,8.0
56.629618266,10.0
56.729885880,6.0
56.830153493,18.0
56.930421107,17.0
57.030688721,12.0
57.130956335,6.0
57.231223949,14.0
57.331491563,6.0
57.431759177,16.0
57.532026790,8.0
57.632294404,8.0
57.732562018,14.0
57.832829632,10.0
57.933097246,13.0
58.033364860,8.0
58.133632474,5.0
58.233900088,10.0
58.334167701,12.0
58.434435315,4.0
58.534702929,13.0
58.634970543,9.0
58.735238157,5.0
58.835505771,12.0
58.935773385,12.0
59.036040998,9.0
59.136308612,12.0
59.236576226,5.0
59.336843840,12.0
59.437111454,10.0
59.537379068,10.0
59.637646682,9.0
59.737914295,8.0
59.838181909,17.0
59.938449523,10.0
60.038717137,17.0
60.138984751,14.0
60.239252365,13.0
60.339519979,20.0
60.439787592,13.0
60.540055206,6.0
60.640322820,9.0
60.740590434,9.0
60.840858048,10.0
60.941125662,9.0
61.041393276,8.0
61.141660889,16.0
61.241928503,9.0
61.342196117,9.0
61.442463731,9.0
61.542731345,10.0
61.642998959,10.0
61.743266573,9.0
61.843534187,9.0
61.943801800,12.0
62.044069414,13.0
62.144337028,10.0
62.244604642,12.0
62.344872256,14.0
62.445139870,6.0
62.545407484,10.0
62.645675097,6.0
62.745942711,12.0
62.846210325,17.0
62.946477939,21.0
63.046745553,13.0
63.147013167,6.0
63.247280781,8.0
63.347548394,4.0
63.447816008,12.0
63.548083622,9.0
63.648351236,4.0
63.748618850,8.0
63.848886464,16.0
63.949154078,6.0
64.049421691,8.0
64.149689305,20.0
64.249956919,12.0
64.350224533,5.0
64.450492147,9.0
64.550759761,24.0
64.651027375,17.0
64.751294989,10.0
64.851562602,8.0
64.951830216,13.0
65.052097830,9.0
65.152365444,16.0
65.252633058,8.0
65.352900672,8.0
65.453168286,4.0
65.553435899,13.0
65.653703513,9.0
65.753971127,9.0
65.854238741,8.0
65.954506355,6.0
66.054773969,9.0
66.155041583,6.0
66.255309196,10.0
66.355576810,12.0
66.455844424,9.0
66.556112038,12.0
66.656379652,9.0
66.756647266,6.0
66.856914880,5.0
66.957182493,8.0
67.057450107,16.0
67.157717721,8.0
67.257985335,6.0
67.358252949,10.0
67.458520563,12.0
67.558788177,12.0
67.659055791,13.0
67.759323404,8.0
67.859591018,12.0
67.959858632,16.0
68.060126246,12.0
68.160393860,14.0
68.260661474,8.0
68.360929088,10.0
68.461196701,8.0
68.561464315,9.0
68.661731929,9.0
68.761999543,8.0
68.862267157,4.0
68.962534771,9.0
69.062802385,8.0
69.163069998,10.0
69.263337612,6.0
69.363605226,10.0
69.463872840,17.0
69.564140454,13.0
69.664408068,5.0
69.764675682,8.0
69.864943295,13.0
69.965210909,4.0
70.065478523,9.0
70.165746137,9.0
70.266013751,10.0
70.366281365,12.0
70.466548979,4.0
70.566816593,14.0
70.667084206,21.0
70.767351820,12.0
70.867619434,10.0
70.967887048,9.0
71.068154662,8.0
71.168422276,13.0
71.268689890,9.0
71.368957503,6.0
71.469225117,16.0
71.569492731,16.0
71.669760345,6.0
71.770027959,6.0
71.870295573,12.0
71.970563187,5.0
72.070830800,9.0
72.171098414,5.0
72.271366028,10.0
72.371633642,10.0
72.471901256,6.0
72.572168870,9.0
72.672436484,8.0
72.772704097,6.0
72.872971711,9.0
72.973239325,9.0
73.073506939,8.0
73.173774553,13.0
73.274042167,9.0
73.374309781,10.0
73.474577394,6.0
73.574845008,16.0
73.675112622,5.0
73.775380236,4.0
73.875647850,10.0
73.975915464,10.0
74.076183078,8.0
74.176450692,4.0
74.276718305,12.0
74.376985919,9.0
74.477253533,10.0
74.577521147,9.0
74.677788761,9.0
74.778056375,6.0
74.878323989,5.0
74.978591602,10.0
75.078859216,8.0
75.179126830,2.0
75.279394444,9.0
75.379662058,16.0
75.479929672,6.0
75.580197286,4.0
75.680464899,1.0
75.780732513,5.0
75.881000127,5.0
75.981267741,6.0
76.081535355,6.0
76.181802969,6.0
76.282070583,5.0
76.382338196,4.0
76.482605810,5.0
76.582873424,6.0
76.683141038,6.0
76.783408652,8.0
76.883676266,12.0
76.983943880,14.0
77.084211494,10.0
77.184479107,5.0
77.284746721,8.0
77.385014335,12.0
77.485281949,1.0
77.585549563,13.0
77.685817177,12.0
77.786084791,13.0
77.886352404,9.0
77.986620018,5.0
78.086887632,4.0
78.187155246,8.0
78.287422860,17.0
78.387690474,10.0
78.487958088,8.0
78.588225701,10.0
78.688493315,8.0
78.788760929,5.0
78.889028543,2.0
78.989296157,5.0
79.089563771,10.0
79.189831385,5.0
79.290098998,5.0
79.390366612,5.0
79.490634226,4.0
79.590901840,5.0
79.691169454,8.0
79.791437068,12.0
79.891704682,9.0
79.991972296,4.0
80.092239909,13.0
80.192507523,10.0
80.292775137,6.0
80.393042751,6.0
80.493310365,5.0
80.593577979,12.0
80.693845593,0.0
80.794113206,5.0
80.894380820,9.0
80.994648434,4.0
81.094916048,8.0
81.195183662,4.0
81.295451276,5.0
81.395718890,5.0
81.495986503,8.0
81.596254117,10.0
81.696521731,9.0
81.796789345,5.0
81.897056959,9.0
81.997324573,2.0
82.097592187,4.0
82.197859800,4.0
82.298127414,9.0
82.398395028,5.0
82.498662642,10.0
82.598930256,9.0
82.699197870,5.0
82.799465484,8.0
82.899733098,8.0
83.000000711,9.0
83.100268325,5.0
83.200535939,6.0
83.300803553,14.0
83.401071167,8.0
83.501338781,4.0
83.601606395,6.0
83.701874008,5.0
83.802141622,5.0
83.902409236,8.0
84.002676850,4.0
84.102944464,5.0
84.203212078,12.0
84.303479692,4.0
84.403747305,8.0
84.504014919,4.0
84.604282533,13.0
84.704550147,8.0
84.804817761,6.0
84.905085375,4.0
85.005352989,1.0
85.105620602,6.0
85.205888216,4.0
85.306155830,6.0
85.406423444,4.0
85.506691058,6.0
85.606958672,10.0
85.707226286,8.0
85.807493899,1.0
85.907761513,4.0
86.008029127,5.0
86.108296741,6.0
86.208564355,9.0
86.308831969,8.0
86.409099583,8.0
86.509367197,9.0
86.609634810,4.0
86.709902424,5.0
86.810170038,9.0
86.910437652,8.0
87.010705266,5.0
87.110972880,9.0
87.211240494,14.0
87.311508107,4.0
87.411775721,6.0
87.512043335,5.0
87.612310949,10.0
87.712578563,9.0
87.812846177,8.0
87.913113791,10.0
88.013381404,5.0
88.113649018,5.0
88.213916632,12.0
88.314184246,9.0
88.414451860,8.0
88.514719474,5.0
88.614987088,10.0
88.715254701,6.0
88.815522315,4.0
88.915789929,2.0
89.016057543,6.0
89.116325157,9.0
89.216592771,1.0
89.316860385,9.0
89.417127999,9.0
89.517395612,9.0
89.617663226,9.0
89.717930840,9.0
89.818198454,6.0
89.918466068,2.0
90.018733682,5.0
90.119001296,6.0
90.219268909,4.0
90.319536523,4.0
90.419804137,2.0
90.520071751,5.0
90.620339365,6.0
90.720606979,1.0
90.820874593,4.0
90.921142206,13.0
91.021409820,1.0
91.121677434,6.0
91.221945048,9.0
91.322212662,6.0
91.422480276,6.0
91.522747890,10.0
91.623015503,8.0
91.723283117,1.0
91.823550731,5.0
91.923818345,6.0
92.024085959,6.0
92.124353573,12.0
92.224621187,6.0
92.324888801,10.0
92.425156414,6.0
92.525424028,6.0
92.625691642,4.0
92.725959256,10.0
92.826226870,8.0
92.926494484,8.0
93.026762098,9.0
93.127029711,5.0
93.227297325,10.0
93.327564939,6.0
93.427832553,4.0
93.528100167,5.0
93.628367781,12.0
93.728635395,2.0
93.828903008,2.0
93.929170622,6.0
94.029438236,2.0
94.129705850,2.0
94.229973464,10.0
94.330241078,4.0
94.430508692,1.0
94.530776305,8.0
94.631043919,4.0
94.731311533,6.0
94.831579147,4.0
94.931846761,4.0
95.032114375,5.0
95.132381989,4.0
95.232649602,8.0
95.332917216,8.0
95.433184830,5.0
95.533452444,8.0
95.633720058,10.0
95.733987672,5.0
95.834255286,8.0
95.934522900,13.0
96.034790513,4.0
96.135058127,6.0
96.235325741,8.0
96.335593355,6.0
96.435860969,6.0
96.536128583,2.0
96.636396197,8.0
96.736663810,0.0
96.836931424,9.0
96.937199038,12.0
97.037466652,6.0
97.137734266,10.0
97.238001880,0.0
97.338269494,2.0
97.438537107,5.0
97.538804721,6.0
97.639072335,5.0
97.739339949,5.0
97.839607563,5.0
97.939875177,6.0
98.040142791,2.0
98.140410404,5.0
98.240678018,4.0
98.340945632,5.0
98.441213246,5.0
98.541480860,8.0
98.641748474,6.0
98.742016088,2.0
98.842283702,2.0
98.942551315,2.0
99.042818929,8.0
99.143086543,9.0
99.243354157,6.0
99.343621771,2.0
99.443889385,9.0
99.544156999,4.0
99.644424612,10.0
99.744692226,9.0
99.844959840,8.0
99.945227454,5.0
100.045495068,8.0
100.145762682,2.0
100.246030296,13.0
100.346297909,5.0
100.446565523,1.0
100.546833137,5.0
100.647100751,8.0
100.747368365,6.0
100.847635979,4.0
100.947903593,2.0
101.048171206,5.0
101.148438820,5.0
101.248706434,4.0
101.348974048,12.0
101.449241662,6.0
101.549509276,4.0
101.649776890,5.0
101.750044504,4.0
101.850312117,8.0
101.950579731,4.0
102.050847345,8.0
102.151114959,6.0
102.251382573,10.0
102.351650187,13.0
102.451917801,4.0
102.552185414,4.0
102.652453028,4.0
102.752720642,8.0
102.852988256,5.0
102.953255870,5.0
103.053523484,6.0
103.153791098,10.0
103.254058711,8.0
103.354326325,1.0
103.454593939,5.0
103.554861553,2.0
103.655129167,14.0
103.755396781,12.0
103.855664395,4.0
103.955932008,8.0
104.056199622,0.0
104.156467236,4.0
104.256734850,14.0
104.357002464,6.0
104.457270078,6.0
104.557537692,5.0
104.657805306,5.0
104.758072919,4.0
104.858340533,1.0
104.958608147,4.0
105.058875761,4.0
105.159143375,6.0
105.259410989,6.0
105.359678603,4.0
105.459946216,6.0
105.560213830,5.0
105.660481444,1.0
105.760749058,4.0
105.861016672,1.0
105.961284286,6.0
106.061551900,6.0
106.161819513,2.0
106.262087127,2.0
106.362354741,5.0
106.462622355,6.0
106.562889969,2.0
106.663157583,10.0
106.763425197,5.0
106.863692810,9.0
106.963960424,10.0
107.064228038,2.0
107.164495652,5.0
107.264763266,6.0
107.365030880,5.0
107.465298494,6.0
107.565566107,5.0
107.665833721,2.0
107.766101335,2.0
107.866368949,6.0
107.966636563,5.0
108.066904177,5.0
108.167171791,6.0
108.267439405,12.0
108.367707018,2.0
108.467974632,2.0
108.568242246,12.0
108.668509860,2.0
108.768777474,2.0
108.869045088,8.0
108.969312702,4.0
109.069580315,9.0
109.169847929,4.0
109.270115543,5.0
109.370383157,1.0
109.470650771,4.0
109.570918385,2.0
109.671185999,4.0
109.771453612,5.0
109.871721226,6.0
109.971988840,5.0
110.072256454,12.0
110.172524068,4.0
110.272791682,8.0
110.373059296,6.0
110.473326909,4.0
110.573594523,6.0
110.673862137,4.0
110.774129751,2.0
110.874397365,9.0
110.974664979,9.0
111.074932593,4.0
111.175200207,5.0
111.275467820,10.0
111.375735434,4.0
111.476003048,5.0
111.576270662,8.0
111.676538276,8.0
111.776805890,5.0
111.877073504,4.0
111.977341117,2.0
112.077608731,5.0
112.177876345,8.0
112.278143959,4.0
112.378411573,8.0
112.478679187,4.0
112.578946801,5.0
112.679214414,5.0
112.779482028,2.0
112.879749642,5.0
112.980017256,5.0
113.080284870,2.0
113.180552484,4.0
113.280820098,4.0
113.381087711,1.0
113.481355325,6.0
113.581622939,1.0
113.681890553,5.0
113.782158167,8.0
113.882425781,8.0
113.982693395,6.0
114.082961009,4.0
114.183228622,5.0
114.283496236,8.0
114.383763850,9.0
114.484031464,6.0
114.584299078,4.0
114.684566692,9.0
114.784834306,2.0
114.885101919,4.0
114.985369533,2.0
115.085637147,4.0
115.185904761,6.0
115.286172375,4.0
115.386439989,6.0
115.486707603,4.0
115.586975216,2.0
115.687242830,10.0
115.787510444,8.0
115.887778058,12.0
115.988045672,5.0
116.088313286,5.0
116.188580900,9.0
116.288848513,4.0
116.389116127,4.0
116.489383741,5.0
116.589651355,4.0
116.689918969,8.0
116.790186583,6.0
116.890454197,5.0
116.990721811,4.0
117.090989424,8.0
117.191257038,13.0
117.291524652,6.0
117.391792266,5.0
117.492059880,4.0
117.592327494,5.0
117.692595108,9.0
117.792862721,5.0
117.893130335,4.0
117.993397949,4.0
118.093665563,5.0
118.193933177,6.0
118.294200791,4.0
118.394468405,2.0
118.494736018,4.0
118.595003632,8.0
118.695271246,4.0
118.795538860,2.0
118.895806474,8.0
118.996074088,4.0
119.096341702,5.0
119.196609315,5.0
119.296876929,6.0
119.397144543,6.0
119.497412157,10.0
119.597679771,6.0
119.697947385,0.0
119.798214999,6.0
119.898482612,5.0
119.998750226,4.0
120.099017840,5.0
120.199285454,1.0
120.299553068,2.0
120.399820682,4.0
120.500088296,5.0
120.600355910,4.0
120.700623523,8.0
120.800891137,6.0
120.901158751,4.0
121.001426365,5.0
121.101693979,1.0
121.201961593,6.0
121.302229207,5.0
121.402496820,4.0
121.502764434,4.0
121.603032048,2.0
121.703299662,8.0
121.803567276,5.0
121.903834890,5.0
122.004102504,10.0
122.104370117,9.0
122.204637731,4.0
122.304905345,8.0
122.405172959,5.0
122.505440573,6.0
122.605708187,2.0
122.705975801,4.0
122.806243414,5.0
122.906511028,2.0
123.006778642,6.0
123.107046256,8.0
123.207313870,4.0
123.307581484,2.0
123.407849098,6.0
123.508116712,2.0
123.608384325,4.0
123.708651939,5.0
123.808919553,12.0
123.909187167,4.0
124.009454781,8.0
124.109722395,6.0
124.209990009,6.0
124.310257622,12.0
124.410525236,9.0
124.510792850,6.0
124.611060464,13.0
124.711328078,6.0
124.811595692,6.0
124.911863306,8.0
125.012130919,6.0
125.112398533,4.0
125.212666147,2.0
125.312933761,6.0
125.413201375,5.0
125.513468989,10.0
125.613736603,2.0
125.714004216,6.0
125.814271830,4.0
125.914539444,2.0
126.014807058,5.0
126.115074672,6.0
126.215342286,5.0
126.315609900,6.0
126.415877514,6.0
126.516145127,5.0
126.616412741,13.0
126.716680355,12.0
126.816947969,4.0
126.917215583,5.0
127.017483197,6.0
127.117750811,10.0
127.218018424,13.0
127.318286038,6.0
127.418553652,8.0
127.518821266,4.0
127.619088880,8.0
127.719356494,4.0
127.819624108,5.0
127.919891721,4.0
128.020159335,8.0
128.120426949,8.0
128.220694563,6.0
128.320962177,6.0
128.421229791,9.0
128.521497405,9.0
128.621765018,10.0
128.722032632,6.0
128.822300246,10.0
128.922567860,2.0
129.022835474,9.0
129.123103088,5.0
129.223370702,8.0
129.323638315,0.0
129.423905929,2.0
129.524173543,10.0
129.624441157,10.0
129.724708771,4.0
129.824976385,9.0
129.925243999,5.0
130.025511613,5.0
130.125779226,6.0
130.226046840,4.0
130.326314454,5.0
130.426582068,9.0
130.526849682,5.0
130.627117296,6.0
130.727384910,8.0
130.827652523,8.0
130.927920137,6.0
131.028187751,1.0
131.128455365,10.0
131.228722979,9.0
131.328990593,6.0
131.429258207,8.0
131.529525820,9.0
131.629793434,8.0
131.730061048,4.0
131.830328662,2.0
131.930596276,4.0
132.030863890,6.0
132.131131504,10.0
132.231399117,9.0
132.331666731,6.0
132.431934345,9.0
132.532201959,8.0
132.632469573,2.0
132.732737187,10.0
132.833004801,6.0
132.933272415,8.0
133.033540028,8.0
133.133807642,6.0
133.234075256,10.0
133.334342870,9.0
133.434610484,5.0
133.534878098,6.0
133.635145712,5.0
133.735413325,9.0
133.835680939,14.0
133.935948553,6.0
134.036216167,8.0
134.136483781,9.0
134.236751395,6.0
134.337019009,5.0
134.437286622,9.0
134.537554236,4.0
134.637821850,1.0
134.738089464,2.0
134.838357078,12.0
134.938624692,13.0
135.038892306,5.0
135.139159919,6.0
135.239427533,4.0
135.339695147,6.0
135.439962761,6.0
135.540230375,2.0
135.640497989,10.0
135.740765603,6.0
135.841033217,6.0
135.941300830,5.0
136.041568444,8.0
136.141836058,12.0
136.242103672,8.0
136.342371286,8.0
136.442638900,12.0
136.542906514,5.0
136.643174127,2.0
136.743441741,13.0
136.843709355,6.0
136.943976969,10.0
137.044244583,8.0
137.144512197,12.0
137.244779811,6.0
137.345047424,6.0
137.445315038,5.0
137.545582652,8.0
137.645850266,2.0
137.746117880,6.0
137.846385494,12.0
137.946653108,6.0
138.046920721,6.0
138.147188335,9.0
138.247455949,1.0
138.347723563,6.0
138.447991177,5.0
138.548258791,12.0
138.648526405,6.0
138.748794019,8.0
138.849061632,13.0
138.949329246,4.0
139.049596860,4.0
139.149864474,8.0
139.250132088,8.0
139.350399702,10.0
139.450667316,6.0
139.550934929,2.0
139.651202543,4.0
139.751470157,5.0
139.851737771,8.0
139.952005385,5.0
140.052272999,9.0
140.152540613,9.0
140.252808226,2.0
140.353075840,5.0
140.453343454,9.0
140.553611068,6.0
140.653878682,6.0
140.754146296,4.0
140.854413910,5.0
140.954681523,8.0
141.054949137,6.0
141.155216751,6.0
141.255484365,5.0
141.355751979,16.0
141.456019593,5.0
141.556287207,9.0
141.656554820,8.0
141.756822434,4.0
141.857090048,5.0
141.957357662,12.0
142.057625276,9.0
142.157892890,17.0
142.258160504,9.0
142.358428118,14.0
142.458695731,5.0
142.558963345,6.0
142.659230959,10.0
142.759498573,6.0
142.859766187,14.0
142.960033801,9.0
143.060301415,13.0
143.160569028,13.0
143.260836642,9.0
143.361104256,9.0
143.461371870,8.0
143.561639484,5.0
143.661907098,16.0
143.762174712,5.0
143.862442325,8.0
143.962709939,10.0
144.062977553,9.0
144.163245167,6.0
144.263512781,10.0
144.363780395,5.0
144.464048009,9.0
144.564315622,10.0
144.664583236,9.0
144.764850850,12.0
144.865118464,6.0
144.965386078,8.0
145.065653692,9.0
145.165921306,14.0
145.266188920,13.0
145.366456533,9.0
145.466724147,6.0
145.566991761,5.0
145.667259375,12.0
145.767526989,5.0
145.867794603,8.0
145.968062217,8.0
146.068329830,5.0
146.168597444,9.0
146.268865058,13.0
146.369132672,10.0
146.469400286,8.0
146.569667900,10.0
146.669935514,10.0
146.770203127,13.0
146.870470741,9.0
146.970738355,17.0
147.071005969,6.0
147.171273583,6.0
147.271541197,10.0
147.371808811,12.0
147.472076424,6.0
147.572344038,13.0
147.672611652,6.0
147.772879266,6.0
147.873146880,14.0
147.973414494,12.0
148.073682108,8.0
148.173949722,9.0
148.274217335,10.0
148.374484949,8.0
148.474752563,14.0
148.575020177,4.0
148.675287791,10.0
148.775555405,13.0
148.875823019,9.0
148.976090632,10.0
149.076358246,14.0
149.176625860,2.0
149.276893474,10.0
149.377161088,12.0
149.477428702,6.0
149.577696316,9.0
149.677963929,10.0
149.778231543,8.0
149.878499157,16.0
149.978766771,14.0
149.995478040,14.0