File: PeakFitting/xrdData/915+Si+wafer+run+1.csv
[Measurement conditions]
Sample identification,
Comment - 1,"Configuration=MPSS New Configuration, Owner=User-1, Creation date=10/27/2010 9:00:11 AM"
Comment - 2,"Goniometer=PW3050/60 (Theta/Theta); Minimum step size 2Theta:0.001; Minimum step size Omega:0.001"
Comment - 3,"Sample stage=Multi purpose sample stage; Minimum step size Phi:2.5"
Comment - 4,"Diffractometer system=XPERT-PRO"
Comment - 5,"Measurement program=C:\XRD Data\mcaplan\311 lab.xrdmp, Identifier={45589E5F-173F-4548-9E9A-391A8F8D5901}"
Anode material,Cu
K-Alpha1 wavelength,1.5405980
K-Alpha2 wavelength,1.5444260
Ratio K-Alpha2/K-Alpha1,0.500
Divergence slit,Fixed,0.19mm
Monochromator used,NO
Generator voltage, 45
Tube current, 40
File date and time,06/Nov/2018 09:30
Unit cell,
h k l, 0 0 0
Scan axis,Gonio
Scan range,10.001000003,149.999655857
Scan step size,0.0083556
No. of points, 16755
Scan type,CONTINUOUS
Phi,0.0
Time per step,1.905
[Scan points]
Angle,Intensity
10.005177820,9.0
10.105445434,5.0
10.205713048,8.0
10.305980662,5.0
10.406248275,9.0
10.506515889,9.0
10.606783503,17.0
10.707051117,8.0
10.807318731,12.0
10.907586345,10.0
11.007853959,12.0
11.108121572,8.0
11.208389186,5.0
11.308656800,9.0
11.408924414,8.0
11.509192028,8.0
11.609459642,8.0
11.709727256,6.0
11.809994870,9.0
11.910262483,8.0
12.010530097,4.0
12.110797711,4.0
12.211065325,10.0
12.311332939,4.0
12.411600553,13.0
12.511868167,8.0
12.612135780,8.0
12.712403394,13.0
12.812671008,12.0
12.912938622,4.0
13.013206236,8.0
13.113473850,6.0
13.213741464,6.0
13.314009077,2.0
13.414276691,13.0
13.514544305,1.0
13.614811919,4.0
13.715079533,12.0
13.815347147,8.0
13.915614761,4.0
14.015882374,5.0
14.116149988,2.0
14.216417602,2.0
14.316685216,5.0
14.416952830,8.0
14.517220444,9.0
14.617488058,6.0
14.717755672,4.0
14.818023285,5.0
14.918290899,1.0
15.018558513,8.0
15.118826127,4.0
15.219093741,8.0
15.319361355,10.0
15.419628969,5.0
15.519896582,2.0
15.620164196,2.0
15.720431810,9.0
15.820699424,2.0
15.920967038,8.0
16.021234652,4.0
16.121502266,8.0
16.221769879,5.0
16.322037493,6.0
16.422305107,2.0
16.522572721,4.0
16.622840335,9.0
16.723107949,2.0
16.823375563,4.0
16.923643176,1.0
17.023910790,4.0
17.124178404,8.0
17.224446018,0.0
17.324713632,12.0
17.424981246,2.0
17.525248860,2.0
17.625516473,4.0
17.725784087,2.0
17.826051701,4.0
17.926319315,6.0
18.026586929,6.0
18.126854543,2.0
18.227122157,6.0
18.327389771,1.0
18.427657384,2.0
18.527924998,2.0
18.628192612,4.0
18.728460226,6.0
18.828727840,5.0
18.928995454,2.0
19.029263068,6.0
19.129530681,4.0
19.229798295,1.0
19.330065909,6.0
19.430333523,4.0
19.530601137,2.0
19.630868751,2.0
19.731136365,2.0
19.831403978,6.0
19.931671592,4.0
20.031939206,5.0
20.132206820,4.0
20.232474434,4.0
20.332742048,6.0
20.433009662,4.0
20.533277275,4.0
20.633544889,2.0
20.733812503,4.0
20.834080117,2.0
20.934347731,2.0
21.034615345,2.0
21.134882959,8.0
21.235150573,2.0
21.335418186,2.0
21.435685800,4.0
21.535953414,2.0
21.636221028,5.0
21.736488642,8.0
21.836756256,4.0
21.937023870,9.0
22.037291483,0.0
22.137559097,1.0
22.237826711,10.0
22.338094325,1.0
22.438361939,4.0
22.538629553,4.0
22.638897167,10.0
22.739164780,4.0
22.839432394,4.0
22.939700008,5.0
23.039967622,1.0
23.140235236,2.0
23.240502850,2.0
23.340770464,2.0
23.441038077,6.0
23.541305691,1.0
23.641573305,2.0
23.741840919,2.0
23.842108533,5.0
23.942376147,0.0
24.042643761,1.0
24.142911375,0.0
24.243178988,0.0
24.343446602,4.0
24.443714216,2.0
24.543981830,0.0
24.644249444,2.0
24.744517058,4.0
24.844784672,5.0
24.945052285,1.0
25.045319899,4.0
25.145587513,2.0
25.245855127,5.0
25.346122741,0.0
25.446390355,4.0
25.546657969,4.0
25.646925582,5.0
25.747193196,2.0
25.847460810,2.0
25.947728424,1.0
26.047996038,2.0
26.148263652,1.0
26.248531266,2.0
26.348798879,0.0
26.449066493,2.0
26.549334107,4.0
26.649601721,4.0
26.749869335,2.0
26.850136949,1.0
26.950404563,2.0
27.050672176,2.0
27.150939790,2.0
27.251207404,0.0
27.351475018,0.0
27.451742632,1.0
27.552010246,1.0
27.652277860,1.0
27.752545474,5.0
27.852813087,0.0
27.953080701,2.0
28.053348315,2.0
28.153615929,0.0
28.253883543,2.0
28.354151157,0.0
28.454418771,2.0
28.554686384,1.0
28.654953998,0.0
28.755221612,0.0
28.855489226,0.0
28.955756840,2.0
29.056024454,1.0
29.156292068,4.0
29.256559681,1.0
29.356827295,2.0
29.457094909,1.0
29.557362523,2.0
29.657630137,0.0
29.757897751,1.0
29.858165365,1.0
29.958432978,1.0
30.058700592,1.0
30.158968206,1.0
30.259235820,0.0
30.359503434,1.0
30.459771048,1.0
30.560038662,0.0
30.660306276,0.0
30.760573889,4.0
30.860841503,0.0
30.961109117,2.0
31.061376731,2.0
31.161644345,1.0
31.261911959,0.0
31.362179573,1.0
31.462447186,2.0
31.562714800,2.0
31.662982414,0.0
31.763250028,0.0
31.863517642,1.0
31.963785256,2.0
32.064052870,0.0
32.164320483,2.0
32.264588097,1.0
32.364855711,1.0
32.465123325,2.0
32.565390939,4.0
32.665658553,1.0
32.765926167,2.0
32.866193780,8.0
32.966461394,89.0
33.066729008,18.0
33.166996622,1.0
33.267264236,4.0
33.367531850,2.0
33.467799464,2.0
33.568067078,0.0
33.668334691,0.0
33.768602305,4.0
33.868869919,1.0
33.969137533,0.0
34.069405147,0.0
34.169672761,4.0
34.269940375,1.0
34.370207988,1.0
34.470475602,4.0
34.570743216,1.0
34.671010830,0.0
34.771278444,1.0
34.871546058,6.0
34.971813672,2.0
35.072081285,1.0
35.172348899,0.0
35.272616513,1.0
35.372884127,0.0
35.473151741,2.0
35.573419355,0.0
35.673686969,0.0
35.773954582,0.0
35.874222196,2.0
35.974489810,0.0
36.074757424,1.0
36.175025038,1.0
36.275292652,0.0
36.375560266,2.0
36.475827880,1.0
36.576095493,1.0
36.676363107,2.0
36.776630721,2.0
36.876898335,2.0
36.977165949,4.0
37.077433563,1.0
37.177701177,0.0
37.277968790,2.0
37.378236404,1.0
37.478504018,1.0
37.578771632,1.0
37.679039246,4.0
37.779306860,5.0
37.879574474,4.0
37.979842087,4.0
38.080109701,1.0
38.180377315,4.0
38.280644929,4.0
38.380912543,1.0
38.481180157,0.0
38.581447771,1.0
38.681715384,1.0
38.781982998,2.0
38.882250612,0.0
38.982518226,0.0
39.082785840,1.0
39.183053454,0.0
39.283321068,0.0
39.383588681,5.0
39.483856295,2.0
39.584123909,0.0
39.684391523,1.0
39.784659137,0.0
39.884926751,1.0
39.985194365,0.0
40.085461979,1.0
40.185729592,0.0
40.285997206,1.0
40.386264820,1.0
40.486532434,1.0
40.586800048,0.0
40.687067662,1.0
40.787335276,2.0
40.887602889,1.0
40.987870503,0.0
41.088138117,0.0
41.188405731,1.0
41.288673345,0.0
41.388940959,0.0
41.489208573,0.0
41.589476186,0.0
41.689743800,0.0
41.790011414,1.0
41.890279028,0.0
41.990546642,1.0
42.090814256,1.0
42.191081870,2.0
42.291349483,8.0
42.391617097,2.0
42.491884711,1.0
42.592152325,0.0
42.692419939,1.0
42.792687553,4.0
42.892955167,1.0
42.993222781,0.0
43.093490394,0.0
43.193758008,0.0
43.294025622,1.0
43.394293236,1.0
43.494560850,0.0
43.594828464,2.0
43.695096078,1.0
43.795363691,0.0
43.895631305,0.0
43.995898919,0.0
44.096166533,1.0
44.196434147,0.0
44.296701761,0.0
44.396969375,0.0
44.497236988,0.0
44.597504602,1.0
44.697772216,0.0
44.798039830,0.0
44.898307444,0.0
44.998575058,2.0
45.098842672,2.0
45.199110285,2.0
45.299377899,1.0
45.399645513,0.0
45.499913127,1.0
45.600180741,2.0
45.700448355,0.0
45.800715969,0.0
45.900983583,0.0
46.001251196,0.0
46.101518810,2.0
46.201786424,2.0
46.302054038,1.0
46.402321652,0.0
46.502589266,0.0
46.602856880,0.0
46.703124493,2.0
46.803392107,0.0
46.903659721,1.0
47.003927335,1.0
47.104194949,0.0
47.204462563,4.0
47.304730177,5.0
47.404997790,0.0
47.505265404,4.0
47.605533018,0.0
47.705800632,1.0
47.806068246,0.0
47.906335860,1.0
48.006603474,0.0
48.106871087,2.0
48.207138701,2.0
48.307406315,1.0
48.407673929,1.0
48.507941543,0.0
48.608209157,0.0
48.708476771,0.0
48.808744385,2.0
48.909011998,0.0
49.009279612,1.0
49.109547226,2.0
49.209814840,1.0
49.310082454,1.0
49.410350068,0.0
49.510617682,1.0
49.610885295,1.0
49.711152909,0.0
49.811420523,0.0
49.911688137,0.0
50.011955751,0.0
50.112223365,0.0
50.212490979,2.0
50.312758592,0.0
50.413026206,1.0
50.513293820,1.0
50.613561434,2.0
50.713829048,1.0
50.814096662,2.0
50.914364276,0.0
51.014631889,0.0
51.114899503,1.0
51.215167117,5.0
51.315434731,0.0
51.415702345,1.0
51.515969959,1.0
51.616237573,0.0
51.716505186,0.0
51.816772800,1.0
51.917040414,2.0
52.017308028,0.0
52.117575642,1.0
52.217843256,1.0
52.318110870,0.0
52.418378484,1.0
52.518646097,4.0
52.618913711,2.0
52.719181325,0.0
52.819448939,1.0
52.919716553,0.0
53.019984167,1.0
53.120251781,0.0
53.220519394,4.0
53.320787008,1.0
53.421054622,1.0
53.521322236,0.0
53.621589850,1.0
53.721857464,0.0
53.822125078,5.0
53.922392691,1.0
54.022660305,0.0
54.122927919,4.0
54.223195533,5.0
54.323463147,1.0
54.423730761,0.0
54.523998375,1.0
54.624265988,2.0
54.724533602,0.0
54.824801216,2.0
54.925068830,1.0
55.025336444,4.0
55.125604058,1.0
55.225871672,1.0
55.326139286,1.0
55.426406899,0.0
55.526674513,0.0
55.626942127,0.0
55.727209741,0.0
55.827477355,1.0
55.927744969,1.0
56.028012583,1.0
56.128280196,0.0
56.228547810,1.0
56.328815424,4.0
56.429083038,4.0
56.529350652,0.0
56.629618266,1.0
56.729885880,1.0
56.830153493,1.0
56.930421107,1.0
57.030688721,1.0
57.130956335,0.0
57.231223949,1.0
57.331491563,0.0
57.431759177,0.0
57.532026790,1.0
57.632294404,1.0
57.732562018,1.0
57.832829632,1.0
57.933097246,2.0
58.033364860,2.0
58.133632474,0.0
58.233900088,0.0
58.334167701,2.0
58.434435315,0.0
58.534702929,5.0
58.634970543,2.0
58.735238157,0.0
58.835505771,4.0
58.935773385,1.0
59.036040998,6.0
59.136308612,0.0
59.236576226,1.0
59.336843840,0.0
59.437111454,1.0
59.537379068,1.0
59.637646682,0.0
59.737914295,1.0
59.838181909,2.0
59.938449523,4.0
60.038717137,0.0
60.138984751,1.0
60.239252365,4.0
60.339519979,1.0
60.439787592,1.0
60.540055206,1.0
60.640322820,4.0
60.740590434,1.0
60.840858048,0.0
60.941125662,1.0
61.041393276,1.0
61.141660889,1.0
61.241928503,2.0
61.342196117,2.0
61.442463731,8.0
61.542731345,5.0
61.642998959,25.0
61.743266573,10.0
61.843534187,6.0
61.943801800,1.0
62.044069414,8.0
62.144337028,5.0
62.244604642,4.0
62.344872256,1.0
62.445139870,2.0
62.545407484,5.0
62.645675097,2.0
62.745942711,1.0
62.846210325,2.0
62.946477939,2.0
63.046745553,5.0
63.147013167,2.0
63.247280781,1.0
63.347548394,4.0
63.447816008,5.0
63.548083622,2.0
63.648351236,4.0
63.748618850,2.0
63.848886464,9.0
63.949154078,5.0
64.049421691,0.0
64.149689305,13.0
64.249956919,2.0
64.350224533,4.0
64.450492147,2.0
64.550759761,9.0
64.651027375,6.0
64.751294989,5.0
64.851562602,8.0
64.951830216,1.0
65.052097830,4.0
65.152365444,8.0
65.252633058,6.0
65.352900672,8.0
65.453168286,9.0
65.553435899,4.0
65.653703513,12.0
65.753971127,14.0
65.854238741,49.0
65.954506355,13.0
66.054773969,12.0
66.155041583,8.0
66.255309196,9.0
66.355576810,24.0
66.455844424,34.0
66.556112038,37.0
66.656379652,37.0
66.756647266,40.0
66.856914880,44.0
66.957182493,44.0
67.057450107,53.0
67.157717721,58.0
67.257985335,70.0
67.358252949,62.0
67.458520563,61.0
67.558788177,72.0
67.659055791,88.0
67.759323404,98.0
67.859591018,106.0
67.959858632,85.0
68.060126246,125.0
68.160393860,185.0
68.260661474,209.0
68.360929088,316.0
68.461196701,352.0
68.561464315,348.0
68.661731929,522.0
68.761999543,906.0
68.862267157,934.0
68.962534771,1696.0
69.062802385,25708.0
69.163069998,28423.0
69.263337612,15195.0
69.363605226,14904.0
69.463872840,1333.0
69.564140454,652.0
69.664408068,402.0
69.764675682,304.0
69.864943295,233.0
69.965210909,172.0
70.065478523,167.0
70.165746137,159.0
70.266013751,135.0
70.366281365,128.0
70.466548979,112.0
70.566816593,105.0
70.667084206,82.0
70.767351820,82.0
70.867619434,66.0
70.967887048,72.0
71.068154662,72.0
71.168422276,58.0
71.268689890,54.0
71.368957503,52.0
71.469225117,48.0
71.569492731,60.0
71.669760345,34.0
71.770027959,30.0
71.870295573,44.0
71.970563187,30.0
72.070830800,18.0
72.171098414,40.0
72.271366028,33.0
72.371633642,25.0
72.471901256,14.0
72.572168870,32.0
72.672436484,21.0
72.772704097,20.0
72.872971711,16.0
72.973239325,12.0
73.073506939,10.0
73.173774553,14.0
73.274042167,13.0
73.374309781,10.0
73.474577394,8.0
73.574845008,12.0
73.675112622,9.0
73.775380236,8.0
73.875647850,4.0
73.975915464,6.0
74.076183078,10.0
74.176450692,6.0
74.276718305,8.0
74.376985919,4.0
74.477253533,10.0
74.577521147,8.0
74.677788761,5.0
74.778056375,6.0
74.878323989,5.0
74.978591602,10.0
75.078859216,5.0
75.179126830,8.0
75.279394444,4.0
75.379662058,5.0
75.479929672,8.0
75.580197286,4.0
75.680464899,4.0
75.780732513,5.0
75.881000127,4.0
75.981267741,2.0
76.081535355,0.0
76.181802969,5.0
76.282070583,9.0
76.382338196,2.0
76.482605810,8.0
76.582873424,4.0
76.683141038,1.0
76.783408652,2.0
76.883676266,4.0
76.983943880,5.0
77.084211494,1.0
77.184479107,1.0
77.284746721,1.0
77.385014335,0.0
77.485281949,4.0
77.585549563,4.0
77.685817177,1.0
77.786084791,5.0
77.886352404,4.0
77.986620018,5.0
78.086887632,5.0
78.187155246,4.0
78.287422860,5.0
78.387690474,2.0
78.487958088,2.0
78.588225701,1.0
78.688493315,6.0
78.788760929,2.0
78.889028543,4.0
78.989296157,2.0
79.089563771,4.0
79.189831385,1.0
79.290098998,5.0
79.390366612,1.0
79.490634226,2.0
79.590901840,4.0
79.691169454,0.0
79.791437068,1.0
79.891704682,1.0
79.991972296,2.0
80.092239909,1.0
80.192507523,2.0
80.292775137,1.0
80.393042751,4.0
80.493310365,0.0
80.593577979,1.0
80.693845593,2.0
80.794113206,1.0
80.894380820,1.0
80.994648434,0.0
81.094916048,1.0
81.195183662,2.0
81.295451276,1.0
81.395718890,0.0
81.495986503,2.0
81.596254117,1.0
81.696521731,1.0
81.796789345,2.0
81.897056959,1.0
81.997324573,1.0
82.097592187,1.0
82.197859800,1.0
82.298127414,4.0
82.398395028,5.0
82.498662642,0.0
82.598930256,1.0
82.699197870,2.0
82.799465484,2.0
82.899733098,1.0
83.000000711,4.0
83.100268325,4.0
83.200535939,2.0
83.300803553,2.0
83.401071167,2.0
83.501338781,2.0
83.601606395,2.0
83.701874008,4.0
83.802141622,0.0
83.902409236,1.0
84.002676850,1.0
84.102944464,4.0
84.203212078,0.0
84.303479692,6.0
84.403747305,2.0
84.504014919,2.0
84.604282533,0.0
84.704550147,1.0
84.804817761,0.0
84.905085375,2.0
85.005352989,1.0
85.105620602,2.0
85.205888216,0.0
85.306155830,2.0
85.406423444,1.0
85.506691058,0.0
85.606958672,2.0
85.707226286,0.0
85.807493899,2.0
85.907761513,8.0
86.008029127,1.0
86.108296741,1.0
86.208564355,0.0
86.308831969,2.0
86.409099583,2.0
86.509367197,0.0
86.609634810,1.0
86.709902424,0.0
86.810170038,0.0
86.910437652,4.0
87.010705266,0.0
87.110972880,2.0
87.211240494,0.0
87.311508107,2.0
87.411775721,0.0
87.512043335,1.0
87.612310949,1.0
87.712578563,2.0
87.812846177,1.0
87.913113791,2.0
88.013381404,2.0
88.113649018,1.0
88.213916632,4.0
88.314184246,0.0
88.414451860,0.0
88.514719474,0.0
88.614987088,1.0
88.715254701,1.0
88.815522315,1.0
88.915789929,1.0
89.016057543,1.0
89.116325157,1.0
89.216592771,0.0
89.316860385,1.0
89.417127999,0.0
89.517395612,1.0
89.617663226,5.0
89.717930840,0.0
89.818198454,6.0
89.918466068,1.0
90.018733682,0.0
90.119001296,4.0
90.219268909,0.0
90.319536523,2.0
90.419804137,2.0
90.520071751,2.0
90.620339365,0.0
90.720606979,4.0
90.820874593,2.0
90.921142206,1.0
91.021409820,2.0
91.121677434,0.0
91.221945048,0.0
91.322212662,0.0
91.422480276,1.0
91.522747890,0.0
91.623015503,1.0
91.723283117,1.0
91.823550731,1.0
91.923818345,1.0
92.024085959,2.0
92.124353573,2.0
92.224621187,0.0
92.324888801,0.0
92.425156414,1.0
92.525424028,4.0
92.625691642,1.0
92.725959256,2.0
92.826226870,4.0
92.926494484,2.0
93.026762098,0.0
93.127029711,0.0
93.227297325,1.0
93.327564939,1.0
93.427832553,0.0
93.528100167,1.0
93.628367781,5.0
93.728635395,0.0
93.828903008,1.0
93.929170622,0.0
94.029438236,1.0
94.129705850,0.0
94.229973464,1.0
94.330241078,2.0
94.430508692,1.0
94.530776305,0.0
94.631043919,1.0
94.731311533,0.0
94.831579147,2.0
94.931846761,0.0
95.032114375,0.0
95.132381989,0.0
95.232649602,1.0
95.332917216,2.0
95.433184830,5.0
95.533452444,1.0
95.633720058,0.0
95.733987672,0.0
95.834255286,0.0
95.934522900,1.0
96.034790513,4.0
96.135058127,1.0
96.235325741,1.0
96.335593355,1.0
96.435860969,1.0
96.536128583,5.0
96.636396197,0.0
96.736663810,0.0
96.836931424,1.0
96.937199038,0.0
97.037466652,2.0
97.137734266,0.0
97.238001880,0.0
97.338269494,0.0
97.438537107,1.0
97.538804721,0.0
97.639072335,2.0
97.739339949,1.0
97.839607563,0.0
97.939875177,1.0
98.040142791,2.0
98.140410404,2.0
98.240678018,0.0
98.340945632,2.0
98.441213246,0.0
98.541480860,1.0
98.641748474,1.0
98.742016088,2.0
98.842283702,0.0
98.942551315,2.0
99.042818929,1.0
99.143086543,2.0
99.243354157,4.0
99.343621771,0.0
99.443889385,1.0
99.544156999,1.0
99.644424612,0.0
99.744692226,0.0
99.844959840,4.0
99.945227454,4.0
100.045495068,2.0
100.145762682,0.0
100.246030296,1.0
100.346297909,1.0
100.446565523,1.0
100.546833137,1.0
100.647100751,0.0
100.747368365,1.0
100.847635979,0.0
100.947903593,1.0
101.048171206,0.0
101.148438820,2.0
101.248706434,2.0
101.348974048,0.0
101.449241662,1.0
101.549509276,2.0
101.649776890,1.0
101.750044504,1.0
101.850312117,2.0
101.950579731,0.0
102.050847345,0.0
102.151114959,0.0
102.251382573,0.0
102.351650187,0.0
102.451917801,1.0
102.552185414,1.0
102.652453028,1.0
102.752720642,1.0
102.852988256,1.0
102.953255870,0.0
103.053523484,1.0
103.153791098,1.0
103.254058711,2.0
103.354326325,1.0
103.454593939,1.0
103.554861553,1.0
103.655129167,0.0
103.755396781,0.0
103.855664395,0.0
103.955932008,1.0
104.056199622,2.0
104.156467236,0.0
104.256734850,1.0
104.357002464,2.0
104.457270078,0.0
104.557537692,1.0
104.657805306,0.0
104.758072919,0.0
104.858340533,1.0
104.958608147,0.0
105.058875761,1.0
105.159143375,0.0
105.259410989,0.0
105.359678603,1.0
105.459946216,2.0
105.560213830,2.0
105.660481444,0.0
105.760749058,1.0
105.861016672,1.0
105.961284286,2.0
106.061551900,1.0
106.161819513,2.0
106.262087127,4.0
106.362354741,0.0
106.462622355,2.0
106.562889969,1.0
106.663157583,0.0
106.763425197,6.0
106.863692810,1.0
106.963960424,1.0
107.064228038,1.0
107.164495652,1.0
107.264763266,2.0
107.365030880,2.0
107.465298494,1.0
107.565566107,5.0
107.665833721,1.0
107.766101335,0.0
107.866368949,1.0
107.966636563,1.0
108.066904177,0.0
108.167171791,1.0
108.267439405,0.0
108.367707018,2.0
108.467974632,2.0
108.568242246,1.0
108.668509860,1.0
108.768777474,0.0
108.869045088,0.0
108.969312702,2.0
109.069580315,2.0
109.169847929,1.0
109.270115543,0.0
109.370383157,0.0
109.470650771,2.0
109.570918385,0.0
109.671185999,0.0
109.771453612,2.0
109.871721226,1.0
109.971988840,0.0
110.072256454,0.0
110.172524068,0.0
110.272791682,2.0
110.373059296,1.0
110.473326909,2.0
110.573594523,4.0
110.673862137,2.0
110.774129751,2.0
110.874397365,2.0
110.974664979,2.0
111.074932593,1.0
111.175200207,1.0
111.275467820,0.0
111.375735434,5.0
111.476003048,1.0
111.576270662,0.0
111.676538276,0.0
111.776805890,4.0
111.877073504,1.0
111.977341117,1.0
112.077608731,0.0
112.177876345,0.0
112.278143959,4.0
112.378411573,1.0
112.478679187,1.0
112.578946801,1.0
112.679214414,1.0
112.779482028,1.0
112.879749642,0.0
112.980017256,0.0
113.080284870,1.0
113.180552484,0.0
113.280820098,2.0
113.381087711,1.0
113.481355325,2.0
113.581622939,0.0
113.681890553,2.0
113.782158167,1.0
113.882425781,2.0
113.982693395,0.0
114.082961009,4.0
114.183228622,1.0
114.283496236,2.0
114.383763850,0.0
114.484031464,2.0
114.584299078,0.0
114.684566692,1.0
114.784834306,1.0
114.885101919,0.0
114.985369533,1.0
115.085637147,2.0
115.185904761,0.0
115.286172375,2.0
115.386439989,2.0
115.486707603,0.0
115.586975216,1.0
115.687242830,8.0
115.787510444,2.0
115.887778058,4.0
115.988045672,1.0
116.088313286,0.0
116.188580900,0.0
116.288848513,2.0
116.389116127,1.0
116.489383741,2.0
116.589651355,16.0
116.689918969,10.0
116.790186583,4.0
116.890454197,0.0
116.990721811,4.0
117.090989424,17.0
117.191257038,5.0
117.291524652,4.0
117.391792266,2.0
117.492059880,0.0
117.592327494,5.0
117.692595108,4.0
117.792862721,0.0
117.893130335,1.0
117.993397949,2.0
118.093665563,4.0
118.193933177,0.0
118.294200791,4.0
118.394468405,1.0
118.494736018,1.0
118.595003632,1.0
118.695271246,1.0
118.795538860,1.0
118.895806474,0.0
118.996074088,1.0
119.096341702,0.0
119.196609315,1.0
119.296876929,1.0
119.397144543,0.0
119.497412157,2.0
119.597679771,1.0
119.697947385,4.0
119.798214999,1.0
119.898482612,2.0
119.998750226,5.0
120.099017840,1.0
120.199285454,6.0
120.299553068,2.0
120.399820682,2.0
120.500088296,1.0
120.600355910,2.0
120.700623523,0.0
120.800891137,2.0
120.901158751,1.0
121.001426365,4.0
121.101693979,0.0
121.201961593,1.0
121.302229207,2.0
121.402496820,4.0
121.502764434,0.0
121.603032048,2.0
121.703299662,1.0
121.803567276,4.0
121.903834890,0.0
122.004102504,1.0
122.104370117,2.0
122.204637731,0.0
122.304905345,1.0
122.405172959,1.0
122.505440573,4.0
122.605708187,2.0
122.705975801,1.0
122.806243414,0.0
122.906511028,1.0
123.006778642,2.0
123.107046256,1.0
123.207313870,5.0
123.307581484,2.0
123.407849098,1.0
123.508116712,1.0
123.608384325,1.0
123.708651939,1.0
123.808919553,0.0
123.909187167,4.0
124.009454781,1.0
124.109722395,1.0
124.209990009,2.0
124.310257622,2.0
124.410525236,1.0
124.510792850,0.0
124.611060464,0.0
124.711328078,2.0
124.811595692,1.0
124.911863306,0.0
125.012130919,1.0
125.112398533,1.0
125.212666147,0.0
125.312933761,1.0
125.413201375,0.0
125.513468989,4.0
125.613736603,0.0
125.714004216,4.0
125.814271830,0.0
125.914539444,0.0
126.014807058,4.0
126.115074672,1.0
126.215342286,1.0
126.315609900,1.0
126.415877514,0.0
126.516145127,0.0
126.616412741,0.0
126.716680355,0.0
126.816947969,1.0
126.917215583,0.0
127.017483197,0.0
127.117750811,6.0
127.218018424,2.0
127.318286038,1.0
127.418553652,1.0
127.518821266,1.0
127.619088880,4.0
127.719356494,2.0
127.819624108,1.0
127.919891721,1.0
128.020159335,2.0
128.120426949,0.0
128.220694563,0.0
128.320962177,1.0
128.421229791,1.0
128.521497405,5.0
128.621765018,0.0
128.722032632,4.0
128.822300246,1.0
128.922567860,0.0
129.022835474,1.0
129.123103088,1.0
129.223370702,1.0
129.323638315,0.0
129.423905929,2.0
129.524173543,1.0
129.624441157,0.0
129.724708771,2.0
129.824976385,2.0
129.925243999,1.0
130.025511613,4.0
130.125779226,0.0
130.226046840,1.0
130.326314454,4.0
130.426582068,1.0
130.526849682,0.0
130.627117296,1.0
130.727384910,4.0
130.827652523,0.0
130.927920137,1.0
131.028187751,2.0
131.128455365,4.0
131.228722979,2.0
131.328990593,2.0
131.429258207,1.0
131.529525820,1.0
131.629793434,1.0
131.730061048,0.0
131.830328662,0.0
131.930596276,1.0
132.030863890,2.0
132.131131504,2.0
132.231399117,1.0
132.331666731,1.0
132.431934345,0.0
132.532201959,0.0
132.632469573,6.0
132.732737187,0.0
132.833004801,4.0
132.933272415,1.0
133.033540028,4.0
133.133807642,1.0
133.234075256,2.0
133.334342870,1.0
133.434610484,2.0
133.534878098,1.0
133.635145712,2.0
133.735413325,2.0
133.835680939,2.0
133.935948553,1.0
134.036216167,0.0
134.136483781,1.0
134.236751395,0.0
134.337019009,1.0
134.437286622,2.0
134.537554236,4.0
134.637821850,6.0
134.738089464,1.0
134.838357078,2.0
134.938624692,4.0
135.038892306,1.0
135.139159919,0.0
135.239427533,0.0
135.339695147,4.0
135.439962761,2.0
135.540230375,0.0
135.640497989,1.0
135.740765603,1.0
135.841033217,0.0
135.941300830,0.0
136.041568444,1.0
136.141836058,0.0
136.242103672,1.0
136.342371286,4.0
136.442638900,1.0
136.542906514,1.0
136.643174127,4.0
136.743441741,4.0
136.843709355,2.0
136.943976969,0.0
137.044244583,4.0
137.144512197,0.0
137.244779811,2.0
137.345047424,2.0
137.445315038,1.0
137.545582652,2.0
137.645850266,0.0
137.746117880,1.0
137.846385494,0.0
137.946653108,0.0
138.046920721,1.0
138.147188335,4.0
138.247455949,1.0
138.347723563,4.0
138.447991177,0.0
138.548258791,1.0
138.648526405,0.0
138.748794019,1.0
138.849061632,6.0
138.949329246,2.0
139.049596860,1.0
139.149864474,1.0
139.250132088,4.0
139.350399702,0.0
139.450667316,4.0
139.550934929,0.0
139.651202543,1.0
139.751470157,1.0
139.851737771,0.0
139.952005385,4.0
140.052272999,0.0
140.152540613,1.0
140.252808226,2.0
140.353075840,1.0
140.453343454,4.0
140.553611068,1.0
140.653878682,0.0
140.754146296,2.0
140.854413910,4.0
140.954681523,2.0
141.054949137,1.0
141.155216751,1.0
141.255484365,1.0
141.355751979,2.0
141.456019593,4.0
141.556287207,2.0
141.656554820,2.0
141.756822434,1.0
141.857090048,0.0
141.957357662,1.0
142.057625276,2.0
142.157892890,1.0
142.258160504,1.0
142.358428118,2.0
142.458695731,1.0
142.558963345,1.0
142.659230959,2.0
142.759498573,1.0
142.859766187,1.0
142.960033801,0.0
143.060301415,2.0
143.160569028,1.0
143.260836642,0.0
143.361104256,0.0
143.461371870,2.0
143.561639484,0.0
143.661907098,0.0
143.762174712,2.0
143.862442325,1.0
143.962709939,2.0
144.062977553,6.0
144.163245167,1.0
144.263512781,4.0
144.363780395,4.0
144.464048009,0.0
144.564315622,2.0
144.664583236,0.0
144.764850850,0.0
144.865118464,4.0
144.965386078,4.0
145.065653692,0.0
145.165921306,1.0
145.266188920,5.0
145.366456533,1.0
145.466724147,2.0
145.566991761,0.0
145.667259375,6.0
145.767526989,2.0
145.867794603,0.0
145.968062217,1.0
146.068329830,1.0
146.168597444,1.0
146.268865058,1.0
146.369132672,5.0
146.469400286,1.0
146.569667900,4.0
146.669935514,1.0
146.770203127,1.0
146.870470741,1.0
146.970738355,2.0
147.071005969,1.0
147.171273583,2.0
147.271541197,0.0
147.371808811,2.0
147.472076424,0.0
147.572344038,2.0
147.672611652,2.0
147.772879266,2.0
147.873146880,5.0
147.973414494,1.0
148.073682108,0.0
148.173949722,4.0
148.274217335,2.0
148.374484949,0.0
148.474752563,5.0
148.575020177,4.0
148.675287791,0.0
148.775555405,0.0
148.875823019,0.0
148.976090632,8.0
149.076358246,0.0
149.176625860,2.0
149.276893474,5.0
149.377161088,1.0
149.477428702,1.0
149.577696316,0.0
149.677963929,2.0
149.778231543,0.0
149.878499157,4.0
149.978766771,4.0
149.995478040,1.0